Workbook

Sheet Company Prepared Model>>>

Sheet Sources and Uses
B2: NOTE: Model assumes transaction closes on August 1, 2026
B4: Entry Valuation
B6: EBITDA Multiple | C6: 5.5
B7: LTM May 2026 Studio Level EBITDA | C7: =SUM(Summary!BF24:BF35)
B8: Pre Money TEV | C8: =C7*C6
B10: Sources and Uses
B11: Uses
B12: Pre Money TEV | C12: =C8
B13: Existing Debt Paydown (at August 2026) | C13: ='Cash, Debt & Equity'!W26
B14: New Studio Build (in Jan 2027) | C14: =-'Cash Flow Forecast (w prototype'!AB26
B15: Cash on balance sheet for working capital | C15: =C18-SUM(C12,C17,C16,C13,C14)
B16: Legal Fees | C16: 50000
B17: Financing Fees (2% of raise) | C17: =D17*C21 | D17: 0.02 | E17: <<< Fee
B18: Total Uses | C18: =C23
B20: Sources
B21: New Debt (leasehold, certain amount covers losses) | C21: 1650000 | D21: 0.1 | E21: <<< Cash Interest, paid monthly
B22: Management Rollover | C22: =C12
B23: Total Uses | C23: =SUM(C21:C22)
B25: Debt Service Coverage Metrics
C26: LTM May 2026 | D26: 2026 | E26: =D26+1 | F26: =E26+1
B27: ='Cash Flow Forecast (w prototype'!B55 | C27: ='Cash Flow Forecast (w prototype'!BF55 | D27: ='Cash Flow Forecast (w prototype'!BB55 | E27: ='Cash Flow Forecast (w prototype'!BC55 | F27: ='Cash Flow Forecast (w prototype'!BD55
B28: ='Cash Flow Forecast (w prototype'!B56 | C28: ='Cash Flow Forecast (w prototype'!BF56 | D28: ='Cash Flow Forecast (w prototype'!BB56 | E28: ='Cash Flow Forecast (w prototype'!BC56 | F28: ='Cash Flow Forecast (w prototype'!BD56
B29: ='Cash Flow Forecast (w prototype'!B57 | C29: ='Cash Flow Forecast (w prototype'!BF57 | D29: ='Cash Flow Forecast (w prototype'!BB57 | E29: ='Cash Flow Forecast (w prototype'!BC57 | F29: ='Cash Flow Forecast (w prototype'!BD57
B30: ='Cash Flow Forecast (w prototype'!B58 | C30: ='Cash Flow Forecast (w prototype'!BF58 | D30: =IFERROR('Cash Flow Forecast (w prototype'!BB58,"NA") | E30: ='Cash Flow Forecast (w prototype'!BC58 | F30: ='Cash Flow Forecast (w prototype'!BD58

Sheet Charts
B2: Consolidated Revenue
C3: 2025 | D3: =C3+1 | E3: =D3+1 | F3: =E3+1
C4: =Summary!BA6 | D4: =Summary!BB6 | E4: =Summary!BC6 | F4: =Summary!BD6
B6: Consolidated Studio Level EBITDA
C7: 2025 | D7: =C7+1 | E7: =D7+1 | F7: =E7+1
C8: =Summary!BA39 | D8: =Summary!BB39 | E8: =Summary!BC39 | F8: =Summary!BD39
B11: Consolidated Adjusted EBITDA, Post Corp Overhead
C12: 2025 | D12: =C12+1 | E12: =D12+1 | F12: =E12+1
C13: =Summary!BA59 | D13: =Summary!BB59 | E13: =Summary!BC59 | F13: =Summary!BD59
B16: Consolidated EBITDA, Post Corp Overhead
C17: 2025 | D17: =C17+1 | E17: =D17+1 | F17: =E17+1
C18: =Summary!BA41 | D18: =Summary!BB41 | E18: =Summary!BC41 | F18: =Summary!BD41
B33: Studio By Studio Revenue, Monthly Roll Up
B35: Jan 2025 | C35: Feb 2025 | D35: March 2025 | E35: April 2025 | F35: May 2025 | G35: Jun 2025 | H35: Jul 2025 | I35: Aug 2025 | J35: Sep 2025 | K35: Oct 2025 | L35: Nov 2025 | M35: Dec 2025 | N35: Jan 2026 | O35: Feb 2026 | P35: Mar 2026 | Q35: Apr 2026 | R35: May 2026
A36: =Summary!C7 | B36: =Summary!D7 | C36: =Summary!E7 | D36: =Summary!F7 | E36: =Summary!G7 | F36: =Summary!H7 | G36: =Summary!I7 | H36: =Summary!J7 | ... R36: =Summary!T7
A37: =Summary!C8 | B37: =Summary!D8 | C37: =Summary!E8 | D37: =Summary!F8 | E37: =Summary!G8 | F37: =Summary!H8 | G37: =Summary!I8 | H37: =Summary!J8 | ... R37: =Summary!T8
A38: =Summary!C9 | B38: =Summary!D9 | C38: =Summary!E9 | D38: =Summary!F9 | E38: =Summary!G9 | F38: =Summary!H9 | G38: =Summary!I9 | H38: =Summary!J9 | ... R38: =Summary!T9
A39: =Summary!C10 | B39: =Summary!D10 | C39: =Summary!E10 | D39: =Summary!F10 | E39: =Summary!G10 | F39: =Summary!H10 | G39: =Summary!I10 | H39: =Summary!J10 | ... R39: =Summary!T10
A40: =Summary!C11 | B40: =Summary!D11 | C40: =Summary!E11 | D40: =Summary!F11 | E40: =Summary!G11 | F40: =Summary!H11 | G40: =Summary!I11 | H40: =Summary!J11 | ... R40: =Summary!T11
A41: =Summary!C12 | B41: =Summary!D12 | C41: =Summary!E12 | D41: =Summary!F12 | E41: =Summary!G12 | F41: =Summary!H12 | G41: =Summary!I12 | H41: =Summary!J12 | ... R41: =Summary!T12
A42: =Summary!C13 | B42: =Summary!D13 | C42: =Summary!E13 | D42: =Summary!F13 | E42: =Summary!G13 | F42: =Summary!H13 | G42: =Summary!I13 | H42: =Summary!J13 | ... R42: =Summary!T13
A43: =Summary!C14 | B43: =Summary!D14 | C43: =Summary!E14 | D43: =Summary!F14 | E43: =Summary!G14 | F43: =Summary!H14 | G43: =Summary!I14 | H43: =Summary!J14 | ... R43: =Summary!T14
A44: =Summary!C15 | B44: =Summary!D15 | C44: =Summary!E15 | D44: =Summary!F15 | E44: =Summary!G15 | F44: =Summary!H15 | G44: =Summary!I15 | H44: =Summary!J15 | ... R44: =Summary!T15
A45: =Summary!C16 | B45: =Summary!D16 | C45: =Summary!E16 | D45: =Summary!F16 | E45: =Summary!G16 | F45: =Summary!H16 | G45: =Summary!I16 | H45: =Summary!J16 | ... R45: =Summary!T16
A46: =Summary!C17 | B46: =Summary!D17 | C46: =Summary!E17 | D46: =Summary!F17 | E46: =Summary!G17 | F46: =Summary!H17 | G46: =Summary!I17 | H46: =Summary!J17 | ... R46: =Summary!T17
A47: =Summary!C18 | B47: =Summary!D18 | C47: =Summary!E18 | D47: =Summary!F18 | E47: =Summary!G18 | F47: =Summary!H18 | G47: =Summary!I18 | H47: =Summary!J18 | ... R47: =Summary!T18
B50: Revenue Segement Breakdown
A51: Berkeley
A52: Culver City
A53: Danville
A54: Lafayette
A55: Marin
A56: Ocean Park
A57: Presidio Heights
A58: Russian Hill
A59: Santa Barbara
A60: Santa Monica
A61: West Portal
A62: Westwood

Sheet Financials Commentary
C3: Cash Sales vs. Accrual (Earned) Revenue — how to read the two revenue lines in the model
C4: Sales Forecast & Summary tabs show CASH SALES — the total dollar value of packs, memberships, and workshops purchased at the MindBody / ClassPass / GymPass point-of-sale in the period. This is the operating KPI.
C5: Studio P&L, All Studios, and Consolidated P&L show ACCRUAL (GAAP) REVENUE — Sessions recognized over the package usage window + Breakage on expired unused packages − Refunds − Discounts. This is what shows up on the P&L / EBITDA line.
C6: They diverge in any given month by design. A pack sold in June is booked as cash sales in June but recognized as P&L revenue across the months a member actually uses it (or when it expires).
C9: Presidio Heights and Marina historical results
C10: Presidio Heights and Marina historical results are not directly comparable due to a system migration in April 2025. Prior to April 2025, both physical locations were tracked as a single studio (Presidio Heights) in MindBody. Beginning in April 2025, the locations were separated into two distinct studios, creating a reporting discontinuity in the historical results.

Sheet Cover
B2: Mighty Pilates
B3: Financial Model
B5: Last refreshed: June 23, 2026 | C5: 2026-08-24
B7: Tab Guide
B9: Summary & Controls | C9: Top-level KPIs, studio sales & EBITDA tables, charts
B10: Assumptions | C10: All model inputs: OpEx, sales forecast, rev rec curves, loan terms
B11: Cash Flow Forecast | C11: Monthly cash flow from operations + investing + financing
B12: P&L Summary | C12: Consolidated monthly P&L (Revenue → EBITDA)
B13: P&L Detail | C13: Account-level P&L matching accountant chart of accounts
B14: All Studios Summary | C14: Side-by-side studio comparison
B15: [Studio] FCST (×12) | C15: Per-studio P&L forecast (BK, CC, DN, LF, MR, OP, PH, RH, SB, SM, WP, WW)
B16: Cash, Debt & Equity | C16: Balance sheet, loan amortization schedules, equity tracking
B17: Sales Forecast | C17: Studio × month editable sales grid
B18: CapEx | C18: Capital expenditure project schedule
B19: QBO Actuals | C19: Historical accountant-booked P&L, BS, SCF (read-only)
B22: Conventions
B24: Yellow cells = inputs (edit these)
B25: Light green cells = actuals (closed months, do not edit)

Sheet Read Me
B2: Read Me — Model Architecture
B3: Last refreshed: June 23, 2026
B5: Tab Roles
B6: Summary & Controls | C6: Top-level dashboard. Sales + EBITDA by studio. Total EBITDA references P&L NOI directly.
B7: Assumptions | C7: Editable global parameters: rev rec curves, refund/discount/COGS rates, escalations, loan terms.
B8: Sales Forecast | C8: Per-studio × month sales grid. EDITABLE for forecast months (yellow). Drives revenue formulas. Hidden rows 101-113 hold 2025 history for lag formulas — do not delete.
B9: Cash, Debt & Equity | C9: Loan amortization schedule + debt service forecast.
B10: Cash Flow Forecast | C10: Monthly CF with operating/investing/financing.
B11: P&L (Consolidated) | C11: Consolidated monthly P&L. Revenue/COGS use direct lag formulas (with 2025 history). OpEx rows = SUM(per-studio) + HO + HO Other.
B12: All Studios Summary | C12: Side-by-side studio comparison.
B13: [Code] P&L (×12) | C13: Per-studio P&L: BK, CC, DN, LF, MR, OP, PH, RH, SB, SM, WP, WW. OpEx leaves are HARDCODED values (editable) summing to per-studio override. Revenue formulas use per-studio lag (2026+ from Sales Forecast, 2025 from hidden helper rows 102-113).
B14: HO P&L | C14: Head Office overhead (no revenue). Same leaf-summing structure. NOI is negative (= -Total OpEx).
B15: CapEx | C15: Project schedule (empty — add projects to populate Investing rows on CF).
B16: QBO Actuals | C16: Raw accountant-booked P&L/BS/SCF data. Read-only reference.
B18: Cell Conventions
B19: Yellow fill (FFFF99) | C19: EDITABLE input cell. Cat can change these.
B20: Light green fill | C20: Hardcoded actual from QBO/accountant. Do not edit (would diverge from source data).
B21: White/no fill | C21: Formula cell. Computed from other cells.
B22: Light blue fill | C22: Subtotal or total row.
B23: Bold green fill | C23: Key KPI (EBITDA, ending cash).
B25: Value Flow
B26: Sales edit | C26: Edit Sales Forecast cell → flows to: Studio P&L Sessions/Breakage (via lag formula) → Studio NOI → Summary & Controls studio row → Sales Forecast TOTAL row → Consolidated P&L revenue → Consolidated NOI → Summary & Controls Total EBITDA.
B27: OpEx leaf edit | C27: Edit per-studio OpEx leaf (e.g., BK Paid Ads) → Studio Marketing subtotal (=SUM leaves) → Studio Total OpEx → Studio NOI → Summary & Controls studio row → Consolidated P&L Marketing (=SUM studios + HO) → Consolidated Total OpEx → Consolidated NOI → Summary & Controls Total EBITDA. Full propagation works.
B28: Assumption edit | C28: Edit rate on Assumptions tab (refund %, discount %, escalation, etc.) → flows through all formulas referencing that cell.
B30: Hidden Helpers — DO NOT DELETE
B31: Sales Forecast rows 100-113 | C31: Hidden helper rows holding 2025 monthly sales (consolidated row 101 and per-studio rows 102-113). Required for 7-month lag formulas on Session/Breakage Revenue forecasts for May 2026 and Jun 2026.
B32: Sales Forecast row ~50+ | C32: Helper for chart data references on Summary & Controls. Removing breaks charts.
B34: Monthly Update Procedure (when QBO closes new month)
B35: Step 1 | C35: Upload new QBO export to Streamlit dashboard. Streamlit's committed_actuals.json gets updated.
B36: Step 2 | C36: Run refresh_from_streamlit.py (in /Users/chandlerclemons/financial-modeling/models/mighty/).
B37: Step 3 | C37: Refresh script will: (a) extend actuals columns by 1 month, (b) shift forecast forward, (c) refresh trailing-3-month avg lines (Taxes Paid, Property Taxes, Retail, Depreciation), (d) update 2025 helper row values if Streamlit data changed historicals.
B38: Step 4 | C38: Open the Excel and spot-check the new actuals column vs Streamlit. Save & share with stakeholders.
B41: Cash Sales vs Accrual Revenue
B42: Sales Forecast / Summary | C42: These tabs show CASH SALES: Total Sales captured at the MindBody/ClassPass/GymPass point-of-sale when a member buys a class pack, membership, or workshop.
B43: Studio P&L / All Studios | C43: These tabs show ACCRUAL P&L REVENUE: Sessions recognized over the package usage window + Breakage when unused packages expire − Refunds − Discounts.
B44: Reconciliation horizon | C44: These metrics diverge in any individual month by design. They reconcile only over the full lifecycle of a cohort of packages (typically 6-12 months from purchase).
B45: Both are correct | C45: Cash Sales is the operating KPI (Total cash value of sales in period). Accrual Revenue is the GAAP P&L line (what's earned).
B47: Why hardcoded | C47: Property Tax on consolidated P&L row 26 is kept as a hardcoded forecast value rather than linked to individual P&L tabs because the QBO source booked property tax at corporate (Norbrook) level, not per-studio. Studio P&L row 68 ('903000 Property taxes') is $0 in actuals.
B48: Forecast basis | C48: Forecast value $4178.19/mo = 2025 actual annual Property Taxes ($50,138.23) / 12. Conservative assumption that 2026 onwards will run at the same rate.
B50: Categories tracked | C50: The consolidated P&L tracks 7 OpEx categories: Marketing (r14), Payroll (r15), Software & Admin (r16), Professional Fees (r17), Utilities (r18), Property Costs (r19), Travel & Meals (r20).
...

Sheet Summary
B2: Summary & Controls
B3: Top-level dashboard. Studio sales, EBITDA, YoY summary, charts.
B4: Monthly Total Session Sales by Studio
B5: Metric | C5: Studio | D5: Jan 2025 (A) | E5: Feb 2025 (A) | F5: Mar 2025 (A) | G5: Apr 2025 (A) | H5: May 2025 (A) | I5: Jun 2025 (A) | J5: Jul 2025 (A) | K5: Aug 2025 (A) | L5: Sep 2025 (A) | M5: Oct 2025 (A) | N5: Nov 2025 (A) | O5: Dec 2025 (A) | P5: Jan 2026 (A) | Q5: Feb 2026 (A) | R5: Mar 2026 (A) | S5: Apr 2026 (A) | T5: May 2026 (A) | U5: June 2026 (A) | V5: Jul 2026 | W5: Aug 2026 | X5: Sep 2026 | Y5: Oct 2026 | Z5: Nov 2026 | AA5: Dec 2026 | AB5: Jan 2027 | AC5: Feb 2027 | AD5: Mar 2027 | AE5: Apr 2027 | AF5: May 2027 | AG5: Jun 2027 | AH5: Jul 2027 | AI5: Aug 2027 | AJ5: Sep 2027 | AK5: Oct 2027 | AL5: Nov 2027 | AM5: Dec 2027 | AN5: Jan 2028 | AO5: Feb 2028 | AP5: Mar 2028 | AQ5: Apr 2028 | AR5: May 2028 | AS5: Jun 2028 | AT5: Jul 2028 | AU5: Aug 2028 | AV5: Sep 2028 | AW5: Oct 2028 | AX5: Nov 2028 | AY5: Dec 2028 | BA5: 2025 | BB5: =BA5+1 | BC5: =BB5+1 | BD5: =BC5+1 | BF5: LTM May 2026
B6: Total Sales | D6: =SUM(D7:D20) | E6: =SUM(E7:E20) | F6: =SUM(F7:F20) | G6: =SUM(G7:G20) | H6: =SUM(H7:H20) | I6: =SUM(I7:I20) | J6: =SUM(J7:J20) | K6: =SUM(K7:K20) | ... AY6: =SUM(AY7:AY20) | BA6: =SUM(D6:O6) | BB6: =SUM(P6:AA6) | BC6: =SUM(AB6:AM6) | BD6: =SUM(AN6:AY6) | BF6: =SUM(I6:T6) | BH6: =SUM(BA6:BD6)-SUM(D6:AY6)
C7: Berkeley | D7: ='Sales Forecast'!D6 | E7: ='Sales Forecast'!E6 | F7: ='Sales Forecast'!F6 | G7: ='Sales Forecast'!G6 | H7: ='Sales Forecast'!H6 | I7: ='Sales Forecast'!I6 | J7: ='Sales Forecast'!J6 | K7: ='Sales Forecast'!K6 | ... AY7: ='Sales Forecast'!AY6 | BA7: =SUM(D7:O7) | BB7: =SUM(P7:AA7) | BC7: =SUM(AB7:AM7) | BD7: =SUM(AN7:AY7) | BF7: =SUM(I7:T7) | BH7: =SUM(BA7:BD7)-SUM(D7:AY7)
C8: Culver City | D8: ='Sales Forecast'!D7 | E8: ='Sales Forecast'!E7 | F8: ='Sales Forecast'!F7 | G8: ='Sales Forecast'!G7 | H8: ='Sales Forecast'!H7 | I8: ='Sales Forecast'!I7 | J8: ='Sales Forecast'!J7 | K8: ='Sales Forecast'!K7 | ... AY8: ='Sales Forecast'!AY7 | BA8: =SUM(D8:O8) | BB8: =SUM(P8:AA8) | BC8: =SUM(AB8:AM8) | BD8: =SUM(AN8:AY8) | BF8: =SUM(I8:T8) | BH8: =SUM(BA8:BD8)-SUM(D8:AY8)
C9: Danville | D9: ='Sales Forecast'!D8 | E9: ='Sales Forecast'!E8 | F9: ='Sales Forecast'!F8 | G9: ='Sales Forecast'!G8 | H9: ='Sales Forecast'!H8 | I9: ='Sales Forecast'!I8 | J9: ='Sales Forecast'!J8 | K9: ='Sales Forecast'!K8 | ... AY9: ='Sales Forecast'!AY8 | BA9: =SUM(D9:O9) | BB9: =SUM(P9:AA9) | BC9: =SUM(AB9:AM9) | BD9: =SUM(AN9:AY9) | BF9: =SUM(I9:T9) | BH9: =SUM(BA9:BD9)-SUM(D9:AY9)
C10: Lafayette | D10: ='Sales Forecast'!D9 | E10: ='Sales Forecast'!E9 | F10: ='Sales Forecast'!F9 | G10: ='Sales Forecast'!G9 | H10: ='Sales Forecast'!H9 | I10: ='Sales Forecast'!I9 | J10: ='Sales Forecast'!J9 | K10: ='Sales Forecast'!K9 | ... AY10: ='Sales Forecast'!AY9 | BA10: =SUM(D10:O10) | BB10: =SUM(P10:AA10) | BC10: =SUM(AB10:AM10) | BD10: =SUM(AN10:AY10) | BF10: =SUM(I10:T10) | BH10: =SUM(BA10:BD10)-SUM(D10:AY10)
C11: Marin | D11: ='Sales Forecast'!D10 | E11: ='Sales Forecast'!E10 | F11: ='Sales Forecast'!F10 | G11: ='Sales Forecast'!G10 | H11: ='Sales Forecast'!H10 | I11: ='Sales Forecast'!I10 | J11: ='Sales Forecast'!J10 | K11: ='Sales Forecast'!K10 | ... AY11: ='Sales Forecast'!AY10 | BA11: =SUM(D11:O11) | BB11: =SUM(P11:AA11) | BC11: =SUM(AB11:AM11) | BD11: =SUM(AN11:AY11) | BF11: =SUM(I11:T11) | BH11: =SUM(BA11:BD11)-SUM(D11:AY11)
C12: Ocean Park | D12: ='Sales Forecast'!D11 | E12: ='Sales Forecast'!E11 | F12: ='Sales Forecast'!F11 | G12: ='Sales Forecast'!G11 | H12: ='Sales Forecast'!H11 | I12: ='Sales Forecast'!I11 | J12: ='Sales Forecast'!J11 | K12: ='Sales Forecast'!K11 | ... AY12: ='Sales Forecast'!AY11 | BA12: =SUM(D12:O12) | BB12: =SUM(P12:AA12) | BC12: =SUM(AB12:AM12) | BD12: =SUM(AN12:AY12) | BF12: =SUM(I12:T12) | BH12: =SUM(BA12:BD12)-SUM(D12:AY12)
C13: Presidio Heights | D13: ='Sales Forecast'!D12 | E13: ='Sales Forecast'!E12 | F13: ='Sales Forecast'!F12 | G13: ='Sales Forecast'!G12 | H13: ='Sales Forecast'!H12 | I13: ='Sales Forecast'!I12 | J13: ='Sales Forecast'!J12 | K13: ='Sales Forecast'!K12 | ... AY13: ='Sales Forecast'!AY12 | BA13: =SUM(D13:O13) | BB13: =SUM(P13:AA13) | BC13: =SUM(AB13:AM13) | BD13: =SUM(AN13:AY13) | BF13: =SUM(I13:T13) | BH13: =SUM(BA13:BD13)-SUM(D13:AY13)
C14: Russian Hill | D14: ='Sales Forecast'!D13 | E14: ='Sales Forecast'!E13 | F14: ='Sales Forecast'!F13 | G14: ='Sales Forecast'!G13 | H14: ='Sales Forecast'!H13 | I14: ='Sales Forecast'!I13 | J14: ='Sales Forecast'!J13 | K14: ='Sales Forecast'!K13 | ... AY14: ='Sales Forecast'!AY13 | BA14: =SUM(D14:O14) | BB14: =SUM(P14:AA14) | BC14: =SUM(AB14:AM14) | BD14: =SUM(AN14:AY14) | BF14: =SUM(I14:T14) | BH14: =SUM(BA14:BD14)-SUM(D14:AY14)
C15: Santa Barbara | D15: ='Sales Forecast'!D14 | E15: ='Sales Forecast'!E14 | F15: ='Sales Forecast'!F14 | G15: ='Sales Forecast'!G14 | H15: ='Sales Forecast'!H14 | I15: ='Sales Forecast'!I14 | J15: ='Sales Forecast'!J14 | K15: ='Sales Forecast'!K14 | ... AY15: ='Sales Forecast'!AY14 | BA15: =SUM(D15:O15) | BB15: =SUM(P15:AA15) | BC15: =SUM(AB15:AM15) | BD15: =SUM(AN15:AY15) | BF15: =SUM(I15:T15) | BH15: =SUM(BA15:BD15)-SUM(D15:AY15)
C16: Santa Monica | D16: ='Sales Forecast'!D15 | E16: ='Sales Forecast'!E15 | F16: ='Sales Forecast'!F15 | G16: ='Sales Forecast'!G15 | H16: ='Sales Forecast'!H15 | I16: ='Sales Forecast'!I15 | J16: ='Sales Forecast'!J15 | K16: ='Sales Forecast'!K15 | ... AY16: ='Sales Forecast'!AY15 | BA16: =SUM(D16:O16) | BB16: =SUM(P16:AA16) | BC16: =SUM(AB16:AM16) | BD16: =SUM(AN16:AY16) | BF16: =SUM(I16:T16) | BH16: =SUM(BA16:BD16)-SUM(D16:AY16)
C17: West Portal | D17: ='Sales Forecast'!D16 | E17: ='Sales Forecast'!E16 | F17: ='Sales Forecast'!F16 | G17: ='Sales Forecast'!G16 | H17: ='Sales Forecast'!H16 | I17: ='Sales Forecast'!I16 | J17: ='Sales Forecast'!J16 | K17: ='Sales Forecast'!K16 | ... AY17: ='Sales Forecast'!AY16 | BA17: =SUM(D17:O17) | BB17: =SUM(P17:AA17) | BC17: =SUM(AB17:AM17) | BD17: =SUM(AN17:AY17) | BF17: =SUM(I17:T17) | BH17: =SUM(BA17:BD17)-SUM(D17:AY17)
C18: Westwood | D18: ='Sales Forecast'!D17 | E18: ='Sales Forecast'!E17 | F18: ='Sales Forecast'!F17 | G18: ='Sales Forecast'!G17 | H18: ='Sales Forecast'!H17 | I18: ='Sales Forecast'!I17 | J18: ='Sales Forecast'!J17 | K18: ='Sales Forecast'!K17 | ... AY18: ='Sales Forecast'!AY17 | BA18: =SUM(D18:O18) | BB18: =SUM(P18:AA18) | BC18: =SUM(AB18:AM18) | BD18: =SUM(AN18:AY18) | BF18: =SUM(I18:T18) | BH18: =SUM(BA18:BD18)-SUM(D18:AY18)
C19: New Location (Prototype Build) | AB19: =Prototype!B35 | AC19: =Prototype!C35 | AD19: =Prototype!D35 | AE19: =Prototype!E35 | AF19: =Prototype!F35 | AG19: =Prototype!G35 | AH19: =Prototype!H35 | AI19: =Prototype!I35 | ... AY19: =Prototype!Y35 | BA19: =SUM(D19:O19) | BB19: =SUM(P19:AA19) | BC19: =SUM(AB19:AM19) | BD19: =SUM(AN19:AY19) | BF19: =SUM(I19:T19)
C20: Head Office | D20: 0 | E20: 0 | F20: 0 | G20: 0 | H20: 0 | I20: 0 | J20: 0 | K20: 0 | L20: 0 | M20: 0 | N20: 0 | O20: 0 | P20: 0 | Q20: 0 | R20: 0 | S20: 0 | T20: 0 | U20: 0 | V20: 0 | W20: 0 | X20: 0 | Y20: 0 | Z20: 0 | AA20: 0 | AB20: 0 | AC20: 0 | AD20: 0 | AE20: 0 | AF20: 0 | AG20: 0 | AH20: 0 | AI20: 0 | AJ20: 0 | AK20: 0 | AL20: 0 | AM20: 0 | AN20: 0 | AO20: 0 | AP20: 0 | AQ20: 0 | AR20: 0 | AS20: 0 | AT20: 0 | AU20: 0 | AV20: 0 | AW20: 0 | AX20: 0 | AY20: 0 | BA20: =SUM(D20:O20) | BB20: =SUM(P20:AA20) | BC20: =SUM(AB20:AM20) | BD20: =SUM(AN20:AY20) | BF20: =SUM(I20:T20) | BH20: =SUM(BA20:BD20)-SUM(D20:AY20)
B22: Monthly EBITDA by Studio
B23: Total EBITDA | D23: =SUM(D24:D37) | E23: =SUM(E24:E37) | F23: =SUM(F24:F37) | G23: =SUM(G24:G37) | H23: =SUM(H24:H37) | I23: =SUM(I24:I37) | J23: =SUM(J24:J37) | K23: =SUM(K24:K37) | ... AY23: =SUM(AY24:AY37) | BA23: =SUM(D23:O23) | BB23: =SUM(P23:AA23) | BC23: =SUM(AB23:AM23) | BD23: =SUM(AN23:AY23) | BF23: =SUM(I23:T23) | BH23: =SUM(BA23:BD23)-SUM(D23:AY23)
C24: Berkeley | D24: ='BK P&L'!D64 | E24: ='BK P&L'!E64 | F24: ='BK P&L'!F64 | G24: ='BK P&L'!G64 | H24: ='BK P&L'!H64 | I24: ='BK P&L'!I64 | J24: ='BK P&L'!J64 | K24: ='BK P&L'!K64 | ... AY24: ='BK P&L'!AY64 | BA24: =SUM(D24:O24) | BB24: =SUM(P24:AA24) | BC24: =SUM(AB24:AM24) | BD24: =SUM(AN24:AY24) | BF24: =SUM(I24:T24) | BH24: =SUM(BA24:BD24)-SUM(D24:AY24)
C25: Culver City | D25: ='CC P&L'!D63 | E25: ='CC P&L'!E63 | F25: ='CC P&L'!F63 | G25: ='CC P&L'!G63 | H25: ='CC P&L'!H63 | I25: ='CC P&L'!I63 | J25: ='CC P&L'!J63 | K25: ='CC P&L'!K63 | ... AY25: ='CC P&L'!AY63 | BA25: =SUM(D25:O25) | BB25: =SUM(P25:AA25) | BC25: =SUM(AB25:AM25) | BD25: =SUM(AN25:AY25) | BF25: =SUM(I25:T25) | BH25: =SUM(BA25:BD25)-SUM(D25:AY25)
C26: Danville | D26: ='DN P&L'!D63 | E26: ='DN P&L'!E63 | F26: ='DN P&L'!F63 | G26: ='DN P&L'!G63 | H26: ='DN P&L'!H63 | I26: ='DN P&L'!I63 | J26: ='DN P&L'!J63 | K26: ='DN P&L'!K63 | ... AY26: ='DN P&L'!AY63 | BA26: =SUM(D26:O26) | BB26: =SUM(P26:AA26) | BC26: =SUM(AB26:AM26) | BD26: =SUM(AN26:AY26) | BF26: =SUM(I26:T26) | BH26: =SUM(BA26:BD26)-SUM(D26:AY26)
C27: Lafayette | D27: ='LF P&L'!D64 | E27: ='LF P&L'!E64 | F27: ='LF P&L'!F64 | G27: ='LF P&L'!G64 | H27: ='LF P&L'!H64 | I27: ='LF P&L'!I64 | J27: ='LF P&L'!J64 | K27: ='LF P&L'!K64 | ... AY27: ='LF P&L'!AY64 | BA27: =SUM(D27:O27) | BB27: =SUM(P27:AA27) | BC27: =SUM(AB27:AM27) | BD27: =SUM(AN27:AY27) | BF27: =SUM(I27:T27) | BH27: =SUM(BA27:BD27)-SUM(D27:AY27)
C28: Marin | D28: ='MR P&L'!D63 | E28: ='MR P&L'!E63 | F28: ='MR P&L'!F63 | G28: ='MR P&L'!G63 | H28: ='MR P&L'!H63 | I28: ='MR P&L'!I63 | J28: ='MR P&L'!J63 | K28: ='MR P&L'!K63 | ... AY28: ='MR P&L'!AY63 | BA28: =SUM(D28:O28) | BB28: =SUM(P28:AA28) | BC28: =SUM(AB28:AM28) | BD28: =SUM(AN28:AY28) | BF28: =SUM(I28:T28) | BH28: =SUM(BA28:BD28)-SUM(D28:AY28)
C29: Ocean Park | D29: ='OP P&L'!D63 | E29: ='OP P&L'!E63 | F29: ='OP P&L'!F63 | G29: ='OP P&L'!G63 | H29: ='OP P&L'!H63 | I29: ='OP P&L'!I63 | J29: ='OP P&L'!J63 | K29: ='OP P&L'!K63 | ... AY29: ='OP P&L'!AY63 | BA29: =SUM(D29:O29) | BB29: =SUM(P29:AA29) | BC29: =SUM(AB29:AM29) | BD29: =SUM(AN29:AY29) | BF29: =SUM(I29:T29) | BH29: =SUM(BA29:BD29)-SUM(D29:AY29)
C30: Presidio Heights | D30: ='PH P&L'!D64 | E30: ='PH P&L'!E64 | F30: ='PH P&L'!F64 | G30: ='PH P&L'!G64 | H30: ='PH P&L'!H64 | I30: ='PH P&L'!I64 | J30: ='PH P&L'!J64 | K30: ='PH P&L'!K64 | ... AY30: ='PH P&L'!AY64 | BA30: =SUM(D30:O30) | BB30: =SUM(P30:AA30) | BC30: =SUM(AB30:AM30) | BD30: =SUM(AN30:AY30) | BF30: =SUM(I30:T30) | BH30: =SUM(BA30:BD30)-SUM(D30:AY30)
C31: Russian Hill | D31: ='RH P&L'!D63 | E31: ='RH P&L'!E63 | F31: ='RH P&L'!F63 | G31: ='RH P&L'!G63 | H31: ='RH P&L'!H63 | I31: ='RH P&L'!I63 | J31: ='RH P&L'!J63 | K31: ='RH P&L'!K63 | ... AY31: ='RH P&L'!AY63 | BA31: =SUM(D31:O31) | BB31: =SUM(P31:AA31) | BC31: =SUM(AB31:AM31) | BD31: =SUM(AN31:AY31) | BF31: =SUM(I31:T31) | BH31: =SUM(BA31:BD31)-SUM(D31:AY31)
C32: Santa Barbara | D32: ='SB P&L'!D63 | E32: ='SB P&L'!E63 | F32: ='SB P&L'!F63 | G32: ='SB P&L'!G63 | H32: ='SB P&L'!H63 | I32: ='SB P&L'!I63 | J32: ='SB P&L'!J63 | K32: ='SB P&L'!K63 | ... AY32: ='SB P&L'!AY63 | BA32: =SUM(D32:O32) | BB32: =SUM(P32:AA32) | BC32: =SUM(AB32:AM32) | BD32: =SUM(AN32:AY32) | BF32: =SUM(I32:T32) | BH32: =SUM(BA32:BD32)-SUM(D32:AY32)
C33: Santa Monica | D33: ='SM P&L'!D64 | E33: ='SM P&L'!E64 | F33: ='SM P&L'!F64 | G33: ='SM P&L'!G64 | H33: ='SM P&L'!H64 | I33: ='SM P&L'!I64 | J33: ='SM P&L'!J64 | K33: ='SM P&L'!K64 | ... AY33: ='SM P&L'!AY64 | BA33: =SUM(D33:O33) | BB33: =SUM(P33:AA33) | BC33: =SUM(AB33:AM33) | BD33: =SUM(AN33:AY33) | BF33: =SUM(I33:T33) | BH33: =SUM(BA33:BD33)-SUM(D33:AY33)
C34: West Portal | D34: ='WP P&L'!D63 | E34: ='WP P&L'!E63 | F34: ='WP P&L'!F63 | G34: ='WP P&L'!G63 | H34: ='WP P&L'!H63 | I34: ='WP P&L'!I63 | J34: ='WP P&L'!J63 | K34: ='WP P&L'!K63 | ... AY34: ='WP P&L'!AY63 | BA34: =SUM(D34:O34) | BB34: =SUM(P34:AA34) | BC34: =SUM(AB34:AM34) | BD34: =SUM(AN34:AY34) | BF34: =SUM(I34:T34) | BH34: =SUM(BA34:BD34)-SUM(D34:AY34)
C35: Westwood | D35: ='WW P&L'!D64 | E35: ='WW P&L'!E64 | F35: ='WW P&L'!F64 | G35: ='WW P&L'!G64 | H35: ='WW P&L'!H64 | I35: ='WW P&L'!I64 | J35: ='WW P&L'!J64 | K35: ='WW P&L'!K64 | ... AY35: ='WW P&L'!AY64 | BA35: =SUM(D35:O35) | BB35: =SUM(P35:AA35) | BC35: =SUM(AB35:AM35) | BD35: =SUM(AN35:AY35) | BF35: =SUM(I35:T35) | BH35: =SUM(BA35:BD35)-SUM(D35:AY35)
C36: New Location (Prototype Build) | AB36: =Prototype!B48 | AC36: =Prototype!C48 | AD36: =Prototype!D48 | AE36: =Prototype!E48 | AF36: =Prototype!F48 | AG36: =Prototype!G48 | AH36: =Prototype!H48 | AI36: =Prototype!I48 | ... AY36: =Prototype!Y48 | BA36: =SUM(D36:O36) | BB36: =SUM(P36:AA36) | BC36: =SUM(AB36:AM36) | BD36: =SUM(AN36:AY36) | BF36: =SUM(I36:T36)
C37: Head Office | D37: ='HO P&L'!D36 | E37: ='HO P&L'!E36 | F37: ='HO P&L'!F36 | G37: ='HO P&L'!G36 | H37: ='HO P&L'!H36 | I37: ='HO P&L'!I36 | J37: ='HO P&L'!J36 | K37: ='HO P&L'!K36 | ... AY37: ='HO P&L'!AY36 | BA37: =SUM(D37:O37) | BB37: =SUM(P37:AA37) | BC37: =SUM(AB37:AM37) | BD37: =SUM(AN37:AY37) | BF37: =SUM(I37:T37) | BH37: =SUM(BA37:BD37)-SUM(D37:AY37)
B39: Studio Level EBITDA | D39: =SUM(D24:D36) | E39: =SUM(E24:E36) | F39: =SUM(F24:F36) | G39: =SUM(G24:G36) | H39: =SUM(H24:H36) | I39: =SUM(I24:I36) | J39: =SUM(J24:J36) | K39: =SUM(K24:K36) | ... AY39: =SUM(AY24:AY36) | BA39: =SUM(D39:O39) | BB39: =SUM(P39:AA39) | BC39: =SUM(AB39:AM39) | BD39: =SUM(AN39:AY39) | BF39: =SUM(I39:T39)
B40: Head Office | D40: =D37 | E40: =E37 | F40: =F37 | G40: =G37 | H40: =H37 | I40: =I37 | J40: =J37 | K40: =K37 | ... AY40: =AY37 | BA40: =SUM(D40:O40) | BB40: =SUM(P40:AA40) | BC40: =SUM(AB40:AM40) | BD40: =SUM(AN40:AY40) | BF40: =SUM(I40:T40)
B41: EBITDA, Post Corp Overhead | D41: =SUM(D39:D40) | E41: =SUM(E39:E40) | F41: =SUM(F39:F40) | G41: =SUM(G39:G40) | H41: =SUM(H39:H40) | I41: =SUM(I39:I40) | J41: =SUM(J39:J40) | K41: =SUM(K39:K40) | ... AY41: =SUM(AY39:AY40) | BA41: =SUM(BA39:BA40) | BB41: =SUM(BB39:BB40) | BC41: =SUM(BC39:BC40) | BD41: =SUM(BD39:BD40) | BF41: =SUM(I41:T41)
B42: Russian Hill Start-Up Costs | D42: 27678.97 | E42: 46607.8 | F42: 2621.08 | G42: 3676.99 | H42: 3252 | I42: 0 | J42: 0 | K42: 1306.25 | L42: 0 | M42: 0 | N42: 0 | O42: 0 | BA42: =SUM(D42:O42) | BB42: =SUM(P42:AA42) | BC42: =SUM(AB42:AM42) | BD42: =SUM(AN42:AY42) | BF42: =SUM(I42:T42)
B43: Ocean Park Start-Up Costs | D43: 719.87 | E43: 5189.83 | F43: 27247.86 | G43: 9987.27 | H43: 543.23 | I43: 777.13 | J43: 0 | K43: 0 | L43: 387.59 | M43: 0 | N43: 0 | O43: 0 | BA43: =SUM(D43:O43) | BB43: =SUM(P43:AA43) | BC43: =SUM(AB43:AM43) | BD43: =SUM(AN43:AY43) | BF43: =SUM(I43:T43)
...

Sheet Sales Forecast
B2: Sales Forecast (Gross)
B3: Jan-Jun 2026 actuals (locked, Cat-authoritative). Jul 2026 onwards forecast (editable).
B4: Per-Studio Monthly Sales
B5: Code | C5: Studio | D5: Jan 2025 | E5: Feb 2025 | F5: Mar 2025 | G5: Apr 2025 | H5: May 2025 | I5: Jun 2025 | J5: Jul 2025 | K5: Aug 2025 | L5: Sep 2025 | M5: Oct 2025 | N5: Nov 2025 | O5: Dec 2025 | P5: Jan 2026 | Q5: Feb 2026 | R5: Mar 2026 | S5: Apr 2026 | T5: 46143 | U5: Jun 2026 | V5: Jul 2026 | W5: Aug 2026 | X5: Sep 2026 | Y5: Oct 2026 | Z5: Nov 2026 | AA5: Dec 2026 | AB5: Jan 2027 | AC5: Feb 2027 | AD5: Mar 2027 | AE5: Apr 2027 | AF5: May 2027 | AG5: Jun 2027 | AH5: Jul 2027 | AI5: Aug 2027 | AJ5: Sep 2027 | AK5: Oct 2027 | AL5: Nov 2027 | AM5: Dec 2027 | AN5: Jan 2028 | AO5: Feb 2028 | AP5: Mar 2028 | AQ5: Apr 2028 | AR5: May 2028 | AS5: Jun 2028 | AT5: Jul 2028 | AU5: Aug 2028 | AV5: Sep 2028 | AW5: Oct 2028 | AX5: Nov 2028 | AY5: Dec 2028
B6: BK | C6: Berkeley | D6: 122672 | E6: 124750 | F6: 112908 | G6: 140814 | H6: 111061 | I6: 107458 | J6: 101618 | K6: 142373 | L6: 101097 | M6: 115965 | N6: 101860 | O6: 99707 | P6: 124393 | Q6: 129377 | R6: 103159 | S6: 136117 | T6: 83273 | U6: 100821 | V6: 99551 | W6: 120000 | X6: 120000 | Y6: 130000 | Z6: 130000 | AA6: 149000 | AB6: 130612.65 | AC6: 135845.85 | AD6: 108316.95 | AE6: 142922.85 | AF6: 87649.8 | AG6: 115500 | AH6: 110250 | AI6: 126000 | AJ6: 126000 | AK6: 136500 | AL6: 136500 | AM6: 156450 | AN6: 137143.28 | AO6: 142638.14 | AP6: 113732.8 | AQ6: 150068.99 | AR6: 92032.29 | AS6: 121275 | AT6: 115762.5 | AU6: 132300 | AV6: 132300 | AW6: 143325 | AX6: 143325 | AY6: 164272.5
B7: CC | C7: Culver City | D7: 0 | E7: 0 | F7: 0 | G7: 0 | H7: 0 | I7: 0 | J7: 0 | K7: 0 | L7: 16118 | M7: 31030 | N7: 31622 | O7: 31310 | P7: 43840 | Q7: 38704 | R7: 42619 | S7: 39690 | T7: 43327 | U7: 32522 | V7: 42903 | W7: 50000 | X7: 53000 | Y7: 60000 | Z7: 64000 | AA7: 60000 | AB7: 61000 | AC7: 73307 | AD7: 69238 | AE7: 75096 | AF7: 70949 | AG7: 64231 | AH7: 95489 | AI7: 107456 | AJ7: 102425 | AK7: 95000 | AL7: 95000 | AM7: 95000 | AN7: 64050 | AO7: 76972.35 | AP7: 72699.9 | AQ7: 78850.8 | AR7: 74496.45 | AS7: 67442.55 | AT7: 100263.45 | AU7: 112828.8 | AV7: 107546.25 | AW7: 99750 | AX7: 99750 | AY7: 99750
B8: DN | C8: Danville | D8: 0 | E8: 0 | F8: 0 | G8: 0 | H8: 0 | I8: 8385 | J8: 14789 | K8: 16531 | L8: 16660 | M8: 14843 | N8: 15819 | O8: 17950 | P8: 24286 | Q8: 23358 | R8: 20289 | S8: 20363 | T8: 15337 | U8: 20327 | V8: 16795 | W8: 25000 | X8: 25000 | Y8: 30000 | Z8: 25000 | AA8: 32000 | AB8: 32000 | AC8: 40000 | AD8: 40000 | AE8: 45000 | AF8: 45000 | AG8: 50000 | AH8: 50000 | AI8: 50000 | AJ8: 55000 | AK8: 55000 | AL8: 55000 | AM8: 55000 | AN8: 33600 | AO8: 42000 | AP8: 42000 | AQ8: 47250 | AR8: 47250 | AS8: 52500 | AT8: 52500 | AU8: 52500 | AV8: 57750 | AW8: 57750 | AX8: 57750 | AY8: 57750
B9: LF | C9: Lafayette | D9: 90025 | E9: 86822 | F9: 85300 | G9: 127703 | H9: 79380 | I9: 76768 | J9: 70767 | K9: 102739 | L9: 68837 | M9: 83777 | N9: 79979 | O9: 79880 | P9: 92365 | Q9: 126186 | R9: 78385 | S9: 106542 | T9: 71444 | U9: 81024 | V9: 86878 | W9: 80000 | X9: 80250 | Y9: 85000 | Z9: 95000 | AA9: 110000 | AB9: 96983.25 | AC9: 132495.3 | AD9: 82304.25 | AE9: 111869.1 | AF9: 75832.05 | AG9: 84000 | AH9: 84262.5 | AI9: 84000 | AJ9: 84262.5 | AK9: 89250 | AL9: 99750 | AM9: 115500 | AN9: 101832.41 | AO9: 139120.07 | AP9: 86419.46 | AQ9: 117462.56 | AR9: 79623.65 | AS9: 88200 | AT9: 88475.62 | AU9: 88200 | AV9: 88475.62 | AW9: 93712.5 | AX9: 104737.5 | AY9: 121275
B10: MR | C10: Marin | D10: 16838.6 | E10: 13867.046 | F10: 14508.233 | G10: 36538 | H10: 90956 | I10: 87668 | J10: 91349 | K10: 113973 | L10: 81190 | M10: 98516 | N10: 90001 | O10: 104919 | P10: 100589 | Q10: 114193 | R10: 90196 | S10: 140256 | T10: 74382 | U10: 98742 | V10: 109856 | W10: 120000 | X10: 98000 | Y10: 110000 | Z10: 120000 | AA10: 115000 | AB10: 105618.45 | AC10: 119902.65 | AD10: 94705.8 | AE10: 147268.8 | AF10: 78685.95 | AG10: 101115 | AH10: 99750 | AI10: 126000 | AJ10: 102900 | AK10: 115500 | AL10: 126000 | AM10: 120750 | AN10: 110899.37 | AO10: 125897.78 | AP10: 99441.09 | AQ10: 154632.24 | AR10: 82620.25 | AS10: 106170.75 | AT10: 104737.5 | AU10: 132300 | AV10: 108045 | AW10: 121275 | AX10: 132300 | AY10: 126787.5
B11: OP | C11: Ocean Park | D11: 0 | E11: 0 | F11: 0 | G11: 30025 | H11: 45379 | I11: 50782 | J11: 59231 | K11: 60132 | L11: 52754 | M11: 51670 | N11: 60236 | O11: 51621 | P11: 60583 | Q11: 59614 | R11: 62052 | S11: 73815 | T11: 63770 | U11: 50286 | V11: 58162 | W11: 60000 | X11: 63000 | Y11: 70000 | Z11: 75000 | AA11: 60000 | AB11: 63612.15 | AC11: 62594.7 | AD11: 65154.6 | AE11: 77505.75 | AF11: 67045.65 | AG11: 67410 | AH11: 78750 | AI11: 63000 | AJ11: 66150 | AK11: 73500 | AL11: 78750 | AM11: 63000 | AN11: 66792.76 | AO11: 65724.43 | AP11: 68412.33 | AQ11: 81381.04 | AR11: 70397.93 | AS11: 70780.5 | AT11: 82687.5 | AU11: 66150 | AV11: 69457.5 | AW11: 77175 | AX11: 82687.5 | AY11: 66150
B12: PH | C12: Presidio Heights | D12: 233958.4 | E12: 218217.95 | F12: 206588.77 | G12: 189694 | H12: 117239 | I12: 109486 | J12: 91214 | K12: 179728 | L12: 107500 | M12: 134780 | N12: 113334 | O12: 128126 | P12: 124927 | Q12: 180839 | R12: 115051 | S12: 179323 | T12: 93511 | U12: 113383 | V12: 117515 | W12: 155000 | X12: 120000 | Y12: 125000 | Z12: 140000 | AA12: 150000 | AB12: 131173.35 | AC12: 189880.95 | AD12: 120803.55 | AE12: 188289.15 | AF12: 100401 | AG12: 120750 | AH12: 115500 | AI12: 162750 | AJ12: 126000 | AK12: 131250 | AL12: 147000 | AM12: 157500 | AN12: 137732.02 | AO12: 199375 | AP12: 126843.73 | AQ12: 197703.61 | AR12: 105421.05 | AS12: 126787.5 | AT12: 121275 | AU12: 170887.5 | AV12: 132300 | AW12: 137812.5 | AX12: 154350 | AY12: 165375
B13: RH | C13: Russian Hill | D13: 0 | E13: 31933 | F13: 55412 | G13: 81989 | H13: 70953 | I13: 67470 | J13: 72141 | K13: 93312 | L13: 69913 | M13: 80685 | N13: 76340 | O13: 72252 | P13: 96145 | Q13: 94253 | R13: 85589 | S13: 108129 | T13: 66857 | U13: 71619 | V13: 75936 | W13: 95000 | X13: 80000 | Y13: 82000 | Z13: 80000 | AA13: 88000 | AB13: 100952.25 | AC13: 98965.65 | AD13: 89868.45 | AE13: 113535.45 | AF13: 71700.3 | AG13: 80850 | AH13: 78750 | AI13: 99750 | AJ13: 84000 | AK13: 86100 | AL13: 84000 | AM13: 92400 | AN13: 105999.86 | AO13: 103913.93 | AP13: 94361.87 | AQ13: 119212.22 | AR13: 75285.32 | AS13: 84892.5 | AT13: 82687.5 | AU13: 104737.5 | AV13: 88200 | AW13: 90405 | AX13: 88200 | AY13: 97020
B14: SB | C14: Santa Barbara | D14: 0 | E14: 0 | F14: 0 | G14: 0 | H14: 0 | I14: 0 | J14: 0 | K14: 0 | L14: 0 | M14: 0 | N14: 8231 | O14: 17514 | P14: 32747 | Q14: 27799 | R14: 25898 | S14: 23393 | T14: 20133 | U14: 17783 | V14: 18714 | W14: 30000 | X14: 30000 | Y14: 33000 | Z14: 35000 | AA14: 35000 | AB14: 59231 | AC14: 60132 | AD14: 52754 | AE14: 51670 | AF14: 60236 | AG14: 51621 | AH14: 62000 | AI14: 63000 | AJ14: 73000 | AK14: 65000 | AL14: 64200 | AM14: 64200 | AN14: 62192.55 | AO14: 63138.6 | AP14: 55391.7 | AQ14: 54253.5 | AR14: 63247.8 | AS14: 54202.05 | AT14: 65100 | AU14: 66150 | AV14: 76650 | AW14: 68250 | AX14: 67410 | AY14: 67410
B15: SM | C15: Santa Monica | D15: 143755 | E15: 203570 | F15: 268747 | G15: 164726 | H15: 193168 | I15: 169753 | J15: 231840 | K15: 162408 | L15: 176867 | M15: 154064 | N15: 188610 | O15: 178478 | P15: 184491 | Q15: 161597 | R15: 192258 | S15: 157521 | T15: 206632 | U15: 130716 | V15: 163688 | W15: 200000 | X15: 190000 | Y15: 220000 | Z15: 251450 | AA15: 190000 | AB15: 215000 | AC15: 190000 | AD15: 215000 | AE15: 200000 | AF15: 235000 | AG15: 210000 | AH15: 200000 | AI15: 210000 | AJ15: 215000 | AK15: 231000 | AL15: 264022.5 | AM15: 199500 | AN15: =1.05*AB15 | AO15: =1.05*AC15 | AP15: =1.05*AD15 | AQ15: =1.05*AE15 | AR15: =1.05*AF15 | AS15: =1.05*AG15 | AT15: =1.05*AH15 | AU15: =1.05*AI15 | ... AY15: =1.05*AM15
B16: WP | C16: West Portal | D16: 0 | E16: 0 | F16: 0 | G16: 0 | H16: 0 | I16: 0 | J16: 0 | K16: 0 | L16: 0 | M16: 0 | N16: 470 | O16: 4114 | P16: 1573 | Q16: 1513 | R16: 784 | S16: 370 | T16: 26 | U16: 225 | V16: 99 | W16: 0 | X16: 0 | Y16: 40000 | Z16: 70000 | AA16: 78000 | AB16: 75000 | AC16: 86822 | AD16: 85300 | AE16: 127703 | AF16: 79689 | AG16: 76768 | AH16: 70767 | AI16: 102739 | AJ16: 68837 | AK16: 83777 | AL16: 79979 | AM16: 79880 | AN16: 94526.25 | AO16: 91163.1 | AP16: 89565 | AQ16: 134088.15 | AR16: 83673.45 | AS16: 80606.4 | AT16: 74305.35 | AU16: 107875.95 | AV16: 72278.85 | AW16: 87965.85 | AX16: 83977.95 | AY16: 83874
B17: WW | C17: Westwood | D17: 71187 | E17: 96307 | F17: 93607 | G17: 77241 | H17: 90103 | I17: 75890 | J17: 75128 | K17: 59513 | L17: 67496 | M17: 64714 | N17: 67128 | O17: 61457 | P17: 71360 | Q17: 69405 | R17: 62992 | S17: 49441 | T17: 60750 | U17: 41757 | V17: 47537 | W17: 64000 | X17: 72000 | Y17: 80000 | Z17: 85600 | AA17: 74900 | AB17: 74928 | AC17: 75000 | AD17: 66141.6 | AE17: 61000 | AF17: 75000 | AG17: 75000 | AH17: 65100 | AI17: 67200 | AJ17: 75600 | AK17: 84000 | AL17: 89880 | AM17: 78645 | AN17: 78674.4 | AO17: 76519.01 | AP17: 69448.68 | AQ17: 61000 | AR17: 71000 | AS17: 71662.5 | AT17: 68355 | AU17: 70560 | AV17: 79380 | AW17: 88200 | AX17: 94374 | AY17: 82577.25
B18: TOTAL | C18: All Studios | D18: =SUM(D6:D17) | E18: =SUM(E6:E17) | F18: =SUM(F6:F17) | G18: =SUM(G6:G17) | H18: =SUM(H6:H17) | I18: =SUM(I6:I17) | J18: =SUM(J6:J17) | K18: =SUM(K6:K17) | ... AY18: =SUM(AY6:AY17)
B20: Annual Summary
B21: Code | C21: Studio | D21: 2025 | E21: 2026 | F21: 2027 | G21: 2028
B22: BK | C22: Berkeley | D22: =SUM(D6:O6) | E22: =SUM(P6:AA6) | F22: =SUM(AB6:AM6) | G22: =SUM(AN6:AY6)
B23: CC | C23: Culver City | D23: =SUM(D7:O7) | E23: =SUM(P7:AA7) | F23: =SUM(AB7:AM7) | G23: =SUM(AN7:AY7)
B24: DN | C24: Danville | D24: =SUM(D8:O8) | E24: =SUM(P8:AA8) | F24: =SUM(AB8:AM8) | G24: =SUM(AN8:AY8)
B25: LF | C25: Lafayette | D25: =SUM(D9:O9) | E25: =SUM(P9:AA9) | F25: =SUM(AB9:AM9) | G25: =SUM(AN9:AY9)
B26: MR | C26: Marin | D26: =SUM(D10:O10) | E26: =SUM(P10:AA10) | F26: =SUM(AB10:AM10) | G26: =SUM(AN10:AY10)
B27: OP | C27: Ocean Park | D27: =SUM(D11:O11) | E27: =SUM(P11:AA11) | F27: =SUM(AB11:AM11) | G27: =SUM(AN11:AY11)
B28: PH | C28: Presidio Heights | D28: =SUM(D12:O12) | E28: =SUM(P12:AA12) | F28: =SUM(AB12:AM12) | G28: =SUM(AN12:AY12)
B29: RH | C29: Russian Hill | D29: =SUM(D13:O13) | E29: =SUM(P13:AA13) | F29: =SUM(AB13:AM13) | G29: =SUM(AN13:AY13)
B30: SB | C30: Santa Barbara | D30: =SUM(D14:O14) | E30: =SUM(P14:AA14) | F30: =SUM(AB14:AM14) | G30: =SUM(AN14:AY14)
B31: SM | C31: Santa Monica | D31: =SUM(D15:O15) | E31: =SUM(P15:AA15) | F31: =SUM(AB15:AM15) | G31: =SUM(AN15:AY15)
B32: WP | C32: West Portal | D32: =SUM(D16:O16) | E32: =SUM(P16:AA16) | F32: =SUM(AB16:AM16) | G32: =SUM(AN16:AY16)
B33: WW | C33: Westwood | D33: =SUM(D17:O17) | E33: =SUM(P17:AA17) | F33: =SUM(AB17:AM17) | G33: =SUM(AN17:AY17)
B34: TOTAL | C34: All Studios | D34: =SUM(D22:D33) | E34: =SUM(E22:E33) | F34: =SUM(F22:F33) | G34: =SUM(G22:G33)
B100: 2025 SALES HISTORY (hidden helper for lag formulas) | P100: 2025-07 | Q100: 2025-08 | R100: 2025-09 | S100: 2025-10 | T100: 2025-11 | U100: 2025-12
P101: 808077 | Q101: 930709 | R101: 758432 | S101: 830044 | T101: 833160 | U101: 847328
B102: 2025 helper: BK (Berkeley) | T102: 102111.01 | U102: 103847.42
B103: 2025 helper: CC (Culver City) | T103: 36886.61 | U103: 37513.88
B104: 2025 helper: DN (Danville) | T104: 18359.97 | U104: 18672.19
B105: 2025 helper: LF (Lafayette) | T105: 84253.69 | U105: 85686.43
B106: 2025 helper: MR (Marin) | T106: 92130.72 | U106: 93697.42
B107: 2025 helper: OP (Ocean Park) | T107: 56662.27 | U107: 57625.82
...

Sheet Assumptions
B2: Assumptions
B3: Yellow cells are editable inputs. All other tabs reference these values.
B5: 1. Model Control
B6: Last Actuals Month | C6: Jul 2026
B7: Forecast Horizon (months) | C7: 32
B8: Forecast End Month | C8: Dec 2028
B10: 2. Revenue Recognition Curves
B11: Lag Month (0 = sale month) | C11: 0 | D11: 1 | E11: 2 | F11: 3 | G11: 4 | H11: 5 | I11: 6 | J11: Sum
B12: Earned % | C12: 0.3868 | D12: 0.2997 | E12: 0.0855 | F12: 0.0482 | G12: 0.0261 | H12: 0.0193 | I12: 0.0144 | J12: =SUM(C12:I12)
B13: Breakage % | C13: 0.0017 | D13: 0.0602 | E13: 0.0053 | F13: 0.0003 | G13: 0.0001 | H13: 0.0008 | I13: 0.0516 | J13: =SUM(C13:I13)
B14: Total (Earned + Breakage) | C14: =C12+C13 | D14: =D12+D13 | E14: =E12+E13 | F14: =F12+F13 | G14: =G12+G13 | H14: =H12+H13 | I14: =I12+I13 | J14: =SUM(C14:I14)
B16: 3. Rates (% of Gross Revenue)
B17: Refund Rate | C17: -0.0158 | D17: Refunds as % of gross revenue. Negative reduces net revenue.
B18: Discount Rate | C18: -0.0531 | D18: Discounts as % of gross revenue. Negative reduces net revenue.
B19: Merchant Fee % | C19: 0.0286 | D19: Payment processor fees as % of revenue.
B20: COGS % | C20: 0.0096 | D20: Cost of goods sold as % of revenue (retail).
B22: 4. Annual Escalation Rates
B23: Rent / Property Escalation | C23: 0.03 | D23: 3% annual rent step-up applied to forecast months
B24: Other OpEx Escalation | C24: 0.04 | D24: 4% annual escalation for all non-rent OpEx categories
B25: Sales YoY Growth | C25: 0.05 | D25: 5% YoY assumed for 2028 (applied to 2027 seasonal pattern)
B27: 5. Loan Terms (as of Apr 2026)
B28: Loan | C28: Original Amt | D28: Current Balance | E28: Rate (Annual) | F28: Avg Monthly Pmt | G28: Start Date | H28: Type
B29: MindBody Loan - SM | C29: 193706.66 | D29: 99348.21 | E29: 0 | F29: 18871.69 | G29: 2025-09 | H29: Amortizing
B30: MindBody Loan - PH | C30: 130000 | D30: 46989.79 | E30: 0 | F30: 16602.04 | G30: 2025-09 | H30: Amortizing
B31: MindBody Loan - LF | C31: 69249.28 | D31: 20599.85 | E31: 0 | F31: 12162.36 | G31: 2025-10 | H31: Amortizing
B32: MindBody Loan - MR | C32: 67443.81 | D32: 14815.18 | E32: 0 | F32: 13157.16 | G32: 2025-10 | H32: Amortizing
B33: Samson Loan | C33: 265414.78 | D33: 189034.12 | E33: 0 | F33: 25460.22 | G33: 2025-11 | H33: Amortizing
B34: Specialty Capital Loan | C34: 217184.21 | D34: 165407.89 | E34: 0 | F34: 25888.16 | G34: 2025-12 | H34: Amortizing
B35: Norbrook Inc Loan | C35: 162318 | D35: 162318 | E35: 0.08 | F35: 0 | G35: 2025-10 | H35: Interest-Only
B36: TOTAL DEBT | D36: =SUM(D29:D35) | F36: =SUM(F29:F35)
B38: 6. Active Studios
B39: Code | C39: Name
B40: BK | C40: Berkeley
B41: CC | C41: Culver City
B42: DN | C42: Danville
B43: LF | C43: Lafayette
B44: MR | C44: Marin
B45: OP | C45: Ocean Park
B46: PH | C46: Presidio Heights
B47: RH | C47: Russian Hill
...

Sheet Cash, Debt & Equity
B2: Cash, Debt & Equity
B4: Item | P4: Jan 2026 | Q4: Feb 2026 | R4: Mar 2026 | S4: Apr 2026 | T4: May 2026 | U4: Jun 2026 | V4: Jul 2026 | W4: Aug 2026 | X4: Sep 2026 | Y4: Oct 2026 | Z4: Nov 2026 | AA4: Dec 2026 | AB4: Jan 2027 | AC4: Feb 2027 | AD4: Mar 2027 | AE4: Apr 2027 | AF4: May 2027 | AG4: Jun 2027 | AH4: Jul 2027 | AI4: Aug 2027 | AJ4: Sep 2027 | AK4: Oct 2027 | AL4: Nov 2027 | AM4: Dec 2027 | AN4: Jan 2028 | AO4: Feb 2028 | AP4: Mar 2028 | AQ4: Apr 2028 | AR4: May 2028 | AS4: Jun 2028 | AT4: Jul 2028 | AU4: Aug 2028 | AV4: Sep 2028 | AW4: Oct 2028 | AX4: Nov 2028 | AY4: Dec 2028
B5: CASH POSITION | D5: Jan 2025 | E5: Feb 2025 | F5: Mar 2025 | G5: Apr 2025 | H5: May 2025 | I5: Jun 2025 | J5: Jul 2025 | K5: Aug 2025 | L5: Sep 2025 | M5: Oct 2025 | N5: Nov 2025 | O5: Dec 2025
B6: Ending Cash Balance (from CF) | P6: ='Cash Flow Forecast (w prototype'!P40 | Q6: ='Cash Flow Forecast (w prototype'!Q40 | R6: ='Cash Flow Forecast (w prototype'!R40 | S6: ='Cash Flow Forecast (w prototype'!S40 | T6: ='Cash Flow Forecast (w prototype'!T40 | U6: ='Cash Flow Forecast (w prototype'!U40 | V6: ='Cash Flow Forecast (w prototype'!V40 | W6: ='Cash Flow Forecast (w prototype'!W40 | ... AY6: ='Cash Flow Forecast (w prototype'!AY40
B8: DEBT SCHEDULE — Loan Balances by Month
B9: MindBody Loan - SM | P9: ='QBO Actuals'!C195 | Q9: ='QBO Actuals'!D195 | R9: ='QBO Actuals'!E195 | S9: ='QBO Actuals'!F195 | T9: ='QBO Actuals'!G195 | U9: ='QBO Actuals'!H195 | V9: =MAX(U9-18871.69,0) | W9: =MAX(V9-18871.69,0) | X9: =MAX(W9-18871.69,0) | Y9: =MAX(X9-18871.69,0) | Z9: =MAX(Y9-18871.69,0) | AA9: =MAX(Z9-18871.69,0) | AB9: =MAX(AA9-18871.69,0) | AC9: =MAX(AB9-18871.69,0) | ... AY9: =MAX(AX9-18871.69,0)
B10: MindBody Loan - PH | P10: ='QBO Actuals'!C198 | Q10: ='QBO Actuals'!D198 | R10: ='QBO Actuals'!E198 | S10: ='QBO Actuals'!F198 | T10: ='QBO Actuals'!G198 | U10: ='QBO Actuals'!H198 | V10: =MAX(U10-16602.04,0) | W10: =MAX(V10-16602.04,0) | X10: =MAX(W10-16602.04,0) | Y10: =MAX(X10-16602.04,0) | Z10: =MAX(Y10-16602.04,0) | AA10: =MAX(Z10-16602.04,0) | AB10: =MAX(AA10-16602.04,0) | AC10: =MAX(AB10-16602.04,0) | ... AY10: =MAX(AX10-16602.04,0)
B11: MindBody Loan - LF | P11: ='QBO Actuals'!C201 | Q11: ='QBO Actuals'!D201 | R11: ='QBO Actuals'!E201 | S11: ='QBO Actuals'!F201 | T11: ='QBO Actuals'!G201 | U11: ='QBO Actuals'!H201 | V11: =MAX(U11-12162.36,0) | W11: =MAX(V11-12162.36,0) | X11: =MAX(W11-12162.36,0) | Y11: =MAX(X11-12162.36,0) | Z11: =MAX(Y11-12162.36,0) | AA11: =MAX(Z11-12162.36,0) | AB11: =MAX(AA11-12162.36,0) | AC11: =MAX(AB11-12162.36,0) | ... AY11: =MAX(AX11-12162.36,0)
B12: MindBody Loan - MR | P12: ='QBO Actuals'!C204 | Q12: ='QBO Actuals'!D204 | R12: ='QBO Actuals'!E204 | S12: ='QBO Actuals'!F204 | T12: ='QBO Actuals'!G204 | U12: ='QBO Actuals'!H204 | V12: =MAX(U12-13157.16,0) | W12: =MAX(V12-13157.16,0) | X12: =MAX(W12-13157.16,0) | Y12: =MAX(X12-13157.16,0) | Z12: =MAX(Y12-13157.16,0) | AA12: =MAX(Z12-13157.16,0) | AB12: =MAX(AA12-13157.16,0) | AC12: =MAX(AB12-13157.16,0) | ... AY12: =MAX(AX12-13157.16,0)
B13: Samson Loan | P13: ='QBO Actuals'!C206 | Q13: ='QBO Actuals'!D206 | R13: ='QBO Actuals'!E206 | S13: ='QBO Actuals'!F206 | T13: ='QBO Actuals'!G206 | U13: ='QBO Actuals'!H206 | V13: =MAX(U13-25460.22,0) | W13: =MAX(V13-25460.22,0) | X13: =MAX(W13-25460.22,0) | Y13: =MAX(X13-25460.22,0) | Z13: =MAX(Y13-25460.22,0) | AA13: =MAX(Z13-25460.22,0) | AB13: =MAX(AA13-25460.22,0) | AC13: =MAX(AB13-25460.22,0) | ... AY13: =MAX(AX13-25460.22,0)
B14: Specialty Capital Loan | P14: ='QBO Actuals'!C207 | Q14: ='QBO Actuals'!D207 | R14: ='QBO Actuals'!E207 | S14: ='QBO Actuals'!F207 | T14: ='QBO Actuals'!G207 | U14: ='QBO Actuals'!H207 | V14: =MAX(U14-25888.16,0) | W14: =MAX(V14-25888.16,0) | X14: =MAX(W14-25888.16,0) | Y14: =MAX(X14-25888.16,0) | Z14: =MAX(Y14-25888.16,0) | AA14: =MAX(Z14-25888.16,0) | AB14: =MAX(AA14-25888.16,0) | AC14: =MAX(AB14-25888.16,0) | ... AY14: =MAX(AX14-25888.16,0)
B15: Norbrook Inc Loan | P15: 0 | Q15: 0 | R15: 0 | S15: 162318 | T15: 162318 | U15: =T15 | V15: =U15 | W15: =V15 | X15: =W15 | Y15: =X15 | Z15: =Y15 | AA15: =Z15 | AB15: =AA15 | ... AY15: =AX15
B16: TOTAL DEBT | P16: =SUM(P9:P15) | Q16: =SUM(Q9:Q15) | R16: =SUM(R9:R15) | S16: =SUM(S9:S15) | T16: =SUM(T9:T15) | U16: =SUM(U9:U15) | V16: =SUM(V9:V15) | W16: =SUM(W9:W15) | ... AY16: =SUM(AY9:AY15)
B18: MONTHLY DEBT SERVICE
B19: MindBody Loan - SM | P19: 0 | Q19: 0 | R19: 0 | S19: 0 | T19: 0 | U19: =IF(U9>0,18871.69,0) | V19: =IF(V9>0,18871.69,0) | W19: =IF(W9>0,18871.69,0) | X19: =IF(X9>0,18871.69,0) | Y19: =IF(Y9>0,18871.69,0) | Z19: =IF(Z9>0,18871.69,0) | AA19: =IF(AA9>0,18871.69,0) | AB19: =IF(AB9>0,18871.69,0) | ... AY19: =IF(AY9>0,18871.69,0)
B20: MindBody Loan - PH | P20: 0 | Q20: 0 | R20: 0 | S20: 0 | T20: 0 | U20: =IF(U10>0,16602.04,0) | V20: =IF(V10>0,16602.04,0) | W20: =IF(W10>0,16602.04,0) | X20: =IF(X10>0,16602.04,0) | Y20: =IF(Y10>0,16602.04,0) | Z20: =IF(Z10>0,16602.04,0) | AA20: =IF(AA10>0,16602.04,0) | AB20: =IF(AB10>0,16602.04,0) | ... AY20: =IF(AY10>0,16602.04,0)
B21: MindBody Loan - LF | P21: 0 | Q21: 0 | R21: 0 | S21: 0 | T21: 0 | U21: =IF(U11>0,12162.36,0) | V21: =IF(V11>0,12162.36,0) | W21: =IF(W11>0,12162.36,0) | X21: =IF(X11>0,12162.36,0) | Y21: =IF(Y11>0,12162.36,0) | Z21: =IF(Z11>0,12162.36,0) | AA21: =IF(AA11>0,12162.36,0) | AB21: =IF(AB11>0,12162.36,0) | ... AY21: =IF(AY11>0,12162.36,0)
B22: MindBody Loan - MR | P22: 0 | Q22: 0 | R22: 0 | S22: 0 | T22: 0 | U22: =IF(U12>0,13157.16,0) | V22: =IF(V12>0,13157.16,0) | W22: =IF(W12>0,13157.16,0) | X22: =IF(X12>0,13157.16,0) | Y22: =IF(Y12>0,13157.16,0) | Z22: =IF(Z12>0,13157.16,0) | AA22: =IF(AA12>0,13157.16,0) | AB22: =IF(AB12>0,13157.16,0) | ... AY22: =IF(AY12>0,13157.16,0)
B23: Samson Loan | P23: 0 | Q23: 0 | R23: 0 | S23: 0 | T23: 94517.1 | U23: =IF(U13>0,25460.22,0) | V23: =IF(V13>0,25460.22,0) | W23: =IF(W13>0,25460.22,0) | X23: =IF(X13>0,25460.22,0) | Y23: =IF(Y13>0,25460.22,0) | Z23: =IF(Z13>0,25460.22,0) | AA23: =IF(AA13>0,25460.22,0) | AB23: =IF(AB13>0,25460.22,0) | ... AY23: =IF(AY13>0,25460.22,0)
B24: Specialty Capital Loan | P24: 0 | Q24: 0 | R24: 0 | S24: 0 | T24: 90052.62 | U24: =IF(U14>0,25888.16,0) | V24: =IF(V14>0,25888.16,0) | W24: =IF(W14>0,25888.16,0) | X24: =IF(X14>0,25888.16,0) | Y24: =IF(Y14>0,25888.16,0) | Z24: =IF(Z14>0,25888.16,0) | AA24: =IF(AA14>0,25888.16,0) | AB24: =IF(AB14>0,25888.16,0) | ... AY24: =IF(AY14>0,25888.16,0)
B25: Norbrook Inc Loan | P25: 0 | Q25: 0 | R25: 0 | S25: 0 | T25: 0 | U25: =U15*0.08/12 | V25: =V15*0.08/12 | W25: =W15*0.08/12 | X25: =X15*0.08/12 | Y25: =Y15*0.08/12 | Z25: =Z15*0.08/12 | AA25: =AA15*0.08/12 | AB25: =AB15*0.08/12 | ... AY25: =AY15*0.08/12
B26: TOTAL DEBT SERVICE | P26: =SUM(P19:P25) | Q26: =SUM(Q19:Q25) | R26: =SUM(R19:R25) | S26: =SUM(S19:S25) | T26: =SUM(T19:T25) | U26: =SUM(U19:U25) | V26: =SUM(V19:V25) | W26: =SUM(W19:W25) | ... AY26: =SUM(AY19:AY25)
B28: OWNER EQUITY / INTERCOMPANY
B29: Intercompany Net Position | P29: 224773.04 | Q29: 224773.04 | R29: 358106.37 | S29: 436439.7 | T29: 0 | U29: 0 | V29: 0 | W29: 0 | X29: 0 | Y29: 0 | Z29: 0 | AA29: 0 | AB29: 0 | AC29: 0 | AD29: 0 | AE29: 0 | AF29: 0 | AG29: 0 | AH29: 0 | AI29: 0 | AJ29: 0 | AK29: 0 | AL29: 0 | AM29: 0 | AN29: 0 | AO29: 0 | AP29: 0 | AQ29: 0 | AR29: 0 | AS29: 0 | AT29: 0 | AU29: 0 | AV29: 0 | AW29: 0 | AX29: 0 | AY29: 0

Sheet Cash Flow Forecast (w prototype
B2: Cash Flow Forecast with 1 Prototype (Cash Basis Cash Flow Statement - as such, no deffereds / no D&A add back / etc.)
B4: Monthly Cash Flow
B5: Line Item | C5: Annual Total | D5: Jan 2025 | E5: Feb 2025 | F5: Mar 2025 | G5: Apr 2025 | H5: May 2025 | I5: Jun 2025 | J5: Jul 2025 | K5: Aug 2025 | L5: Sep 2025 | M5: Oct 2025 | N5: Nov 2025 | O5: Dec 2025 | P5: Jan 2026 | Q5: Feb 2026 | R5: Mar 2026 | S5: Apr 2026 | T5: May 2026 | U5: Jun 2026 | V5: Jul 2026 | W5: Aug 2026 | X5: Sep 2026 | Y5: Oct 2026 | Z5: Nov 2026 | AA5: Dec 2026 | AB5: Jan 2027 | AC5: Feb 2027 | AD5: Mar 2027 | AE5: Apr 2027 | AF5: May 2027 | AG5: Jun 2027 | AH5: Jul 2027 | AI5: Aug 2027 | AJ5: Sep 2027 | AK5: Oct 2027 | AL5: Nov 2027 | AM5: Dec 2027 | AN5: Jan 2028 | AO5: Feb 2028 | AP5: Mar 2028 | AQ5: Apr 2028 | AR5: May 2028 | AS5: Jun 2028 | AT5: Jul 2028 | AU5: Aug 2028 | AV5: Sep 2028 | AW5: Oct 2028 | AX5: Nov 2028 | AY5: Dec 2028 | BA5: 2025 | BB5: =BA5+1 | BC5: =BB5+1 | BD5: =BC5+1 | BF5: LTM May 2026
B6: CASH INFLOWS
B7: Total Cash Sales | P7: =Summary!P6 | Q7: =Summary!Q6 | R7: =Summary!R6 | S7: =Summary!S6 | T7: =Summary!T6 | U7: =Summary!U6 | V7: =Summary!V6 | W7: =Summary!W6 | ... AY7: =Summary!AY6
B9: OPERATING OUTFLOWS
A10: =Prototype!A37 | B10: Property Costs | P10: ='P&L (Existing Locations)'!P19 | Q10: ='P&L (Existing Locations)'!Q19 | R10: ='P&L (Existing Locations)'!R19 | S10: ='P&L (Existing Locations)'!S19 | T10: ='P&L (Existing Locations)'!T19 | U10: ='P&L (Existing Locations)'!U19 | V10: ='P&L (Existing Locations)'!V19 | W10: ='P&L (Existing Locations)'!W19 | ... AA10: ='P&L (Existing Locations)'!AA19 | AB10: ='P&L (Existing Locations)'!AB19+Prototype!B37 | AC10: ='P&L (Existing Locations)'!AC19+Prototype!C37 | AD10: ='P&L (Existing Locations)'!AD19+Prototype!D37 | AE10: ='P&L (Existing Locations)'!AE19+Prototype!E37 | AF10: ='P&L (Existing Locations)'!AF19+Prototype!F37 | AG10: ='P&L (Existing Locations)'!AG19+Prototype!G37 | AH10: ='P&L (Existing Locations)'!AH19+Prototype!H37 | AI10: ='P&L (Existing Locations)'!AI19+Prototype!I37 | ... AY10: ='P&L (Existing Locations)'!AY19+Prototype!Y37
A11: =Prototype!A38 | B11: Staff Costs | P11: ='P&L (Existing Locations)'!P15 | Q11: ='P&L (Existing Locations)'!Q15 | R11: ='P&L (Existing Locations)'!R15 | S11: ='P&L (Existing Locations)'!S15 | T11: ='P&L (Existing Locations)'!T15 | U11: ='P&L (Existing Locations)'!U15 | V11: ='P&L (Existing Locations)'!V15 | W11: ='P&L (Existing Locations)'!W15 | ... AA11: ='P&L (Existing Locations)'!AA15 | AB11: ='P&L (Existing Locations)'!AB15+Prototype!B38 | AC11: ='P&L (Existing Locations)'!AC15+Prototype!C38 | AD11: ='P&L (Existing Locations)'!AD15+Prototype!D38 | AE11: ='P&L (Existing Locations)'!AE15+Prototype!E38 | AF11: ='P&L (Existing Locations)'!AF15+Prototype!F38 | AG11: ='P&L (Existing Locations)'!AG15+Prototype!G38 | AH11: ='P&L (Existing Locations)'!AH15+Prototype!H38 | AI11: ='P&L (Existing Locations)'!AI15+Prototype!I38 | ... AY11: ='P&L (Existing Locations)'!AY15+Prototype!Y38
A12: Utilities and Equipment, Maintineince, Moter Vehicles even through ZERO | B12: Utilities | P12: ='P&L (Existing Locations)'!P18 | Q12: ='P&L (Existing Locations)'!Q18 | R12: ='P&L (Existing Locations)'!R18 | S12: ='P&L (Existing Locations)'!S18 | T12: ='P&L (Existing Locations)'!T18 | U12: ='P&L (Existing Locations)'!U18 | V12: ='P&L (Existing Locations)'!V18 | W12: ='P&L (Existing Locations)'!W18 | ... AA12: ='P&L (Existing Locations)'!AA18 | AB12: ='P&L (Existing Locations)'!AB18+Prototype!B39+Prototype!B40+Prototype!B44 | AC12: ='P&L (Existing Locations)'!AC18+Prototype!C39+Prototype!C40+Prototype!C44 | AD12: ='P&L (Existing Locations)'!AD18+Prototype!D39+Prototype!D40+Prototype!D44 | AE12: ='P&L (Existing Locations)'!AE18+Prototype!E39+Prototype!E40+Prototype!E44 | AF12: ='P&L (Existing Locations)'!AF18+Prototype!F39+Prototype!F40+Prototype!F44 | AG12: ='P&L (Existing Locations)'!AG18+Prototype!G39+Prototype!G40+Prototype!G44 | AH12: ='P&L (Existing Locations)'!AH18+Prototype!H39+Prototype!H40+Prototype!H44 | AI12: ='P&L (Existing Locations)'!AI18+Prototype!I39+Prototype!I40+Prototype!I44 | ... AY12: ='P&L (Existing Locations)'!AY18+Prototype!Y39+Prototype!Y40+Prototype!Y44
A13: =Prototype!A41 | B13: Marketing & Promotion | P13: ='P&L (Existing Locations)'!P14 | Q13: ='P&L (Existing Locations)'!Q14 | R13: ='P&L (Existing Locations)'!R14 | S13: ='P&L (Existing Locations)'!S14 | T13: ='P&L (Existing Locations)'!T14 | U13: ='P&L (Existing Locations)'!U14 | V13: ='P&L (Existing Locations)'!V14 | W13: ='P&L (Existing Locations)'!W14 | ... AA13: ='P&L (Existing Locations)'!AA14 | AB13: ='P&L (Existing Locations)'!AB14+Prototype!B41 | AC13: ='P&L (Existing Locations)'!AC14+Prototype!C41 | AD13: ='P&L (Existing Locations)'!AD14+Prototype!D41 | AE13: ='P&L (Existing Locations)'!AE14+Prototype!E41 | AF13: ='P&L (Existing Locations)'!AF14+Prototype!F41 | AG13: ='P&L (Existing Locations)'!AG14+Prototype!G41 | AH13: ='P&L (Existing Locations)'!AH14+Prototype!H41 | AI13: ='P&L (Existing Locations)'!AI14+Prototype!I41 | ... AY13: ='P&L (Existing Locations)'!AY14+Prototype!Y41
A14: Admin and Finaince and Policy | B14: Administrative & G&A | P14: ='P&L (Existing Locations)'!P16 | Q14: ='P&L (Existing Locations)'!Q16 | R14: ='P&L (Existing Locations)'!R16 | S14: ='P&L (Existing Locations)'!S16 | T14: ='P&L (Existing Locations)'!T16 | U14: ='P&L (Existing Locations)'!U16 | V14: ='P&L (Existing Locations)'!V16 | W14: ='P&L (Existing Locations)'!W16 | ... AA14: ='P&L (Existing Locations)'!AA16 | AB14: ='P&L (Existing Locations)'!AB16+Prototype!B42+Prototype!B46 | AC14: ='P&L (Existing Locations)'!AC16+Prototype!C42+Prototype!C46 | AD14: ='P&L (Existing Locations)'!AD16+Prototype!D42+Prototype!D46 | AE14: ='P&L (Existing Locations)'!AE16+Prototype!E42+Prototype!E46 | AF14: ='P&L (Existing Locations)'!AF16+Prototype!F42+Prototype!F46 | AG14: ='P&L (Existing Locations)'!AG16+Prototype!G42+Prototype!G46 | AH14: ='P&L (Existing Locations)'!AH16+Prototype!H42+Prototype!H46 | AI14: ='P&L (Existing Locations)'!AI16+Prototype!I42+Prototype!I46 | ... AY14: ='P&L (Existing Locations)'!AY16+Prototype!Y42+Prototype!Y46
A15: =Prototype!A45 | B15: Professional Fees | P15: ='P&L (Existing Locations)'!P17 | Q15: ='P&L (Existing Locations)'!Q17 | R15: ='P&L (Existing Locations)'!R17 | S15: ='P&L (Existing Locations)'!S17 | T15: ='P&L (Existing Locations)'!T17 | U15: ='P&L (Existing Locations)'!U17 | V15: ='P&L (Existing Locations)'!V17 | W15: ='P&L (Existing Locations)'!W17 | ... AA15: ='P&L (Existing Locations)'!AA17 | AB15: ='P&L (Existing Locations)'!AB17+Prototype!B45 | AC15: ='P&L (Existing Locations)'!AC17+Prototype!C45 | AD15: ='P&L (Existing Locations)'!AD17+Prototype!D45 | AE15: ='P&L (Existing Locations)'!AE17+Prototype!E45 | AF15: ='P&L (Existing Locations)'!AF17+Prototype!F45 | AG15: ='P&L (Existing Locations)'!AG17+Prototype!G45 | AH15: ='P&L (Existing Locations)'!AH17+Prototype!H45 | AI15: ='P&L (Existing Locations)'!AI17+Prototype!I45 | ... AY15: ='P&L (Existing Locations)'!AY17+Prototype!Y45
A16: =Prototype!A43 | B16: Travel & Meals | P16: ='BK P&L'!P51+'CC P&L'!P50+'DN P&L'!P50+'LF P&L'!P51+'MR P&L'!P50+'OP P&L'!P50+'PH P&L'!P51+'RH P&L'!P50+'SB P&L'!P50+'SM P&L'!P51+'WP P&L'!P50+'WW P&L'!P51+'HO P&L'!P30 | Q16: ='BK P&L'!Q51+'CC P&L'!Q50+'DN P&L'!Q50+'LF P&L'!Q51+'MR P&L'!Q50+'OP P&L'!Q50+'PH P&L'!Q51+'RH P&L'!Q50+'SB P&L'!Q50+'SM P&L'!Q51+'WP P&L'!Q50+'WW P&L'!Q51+'HO P&L'!Q30 | R16: ='BK P&L'!R51+'CC P&L'!R50+'DN P&L'!R50+'LF P&L'!R51+'MR P&L'!R50+'OP P&L'!R50+'PH P&L'!R51+'RH P&L'!R50+'SB P&L'!R50+'SM P&L'!R51+'WP P&L'!R50+'WW P&L'!R51+'HO P&L'!R30 | S16: ='BK P&L'!S51+'CC P&L'!S50+'DN P&L'!S50+'LF P&L'!S51+'MR P&L'!S50+'OP P&L'!S50+'PH P&L'!S51+'RH P&L'!S50+'SB P&L'!S50+'SM P&L'!S51+'WP P&L'!S50+'WW P&L'!S51+'HO P&L'!S30 | T16: ='BK P&L'!T51+'CC P&L'!T50+'DN P&L'!T50+'LF P&L'!T51+'MR P&L'!T50+'OP P&L'!T50+'PH P&L'!T51+'RH P&L'!T50+'SB P&L'!T50+'SM P&L'!T51+'WP P&L'!T50+'WW P&L'!T51+'HO P&L'!T30 | U16: ='BK P&L'!U51+'CC P&L'!U50+'DN P&L'!U50+'LF P&L'!U51+'MR P&L'!U50+'OP P&L'!U50+'PH P&L'!U51+'RH P&L'!U50+'SB P&L'!U50+'SM P&L'!U51+'WP P&L'!U50+'WW P&L'!U51+'HO P&L'!U30 | V16: ='BK P&L'!V51+'CC P&L'!V50+'DN P&L'!V50+'LF P&L'!V51+'MR P&L'!V50+'OP P&L'!V50+'PH P&L'!V51+'RH P&L'!V50+'SB P&L'!V50+'SM P&L'!V51+'WP P&L'!V50+'WW P&L'!V51+'HO P&L'!V30 | W16: ='BK P&L'!W51+'CC P&L'!W50+'DN P&L'!W50+'LF P&L'!W51+'MR P&L'!W50+'OP P&L'!W50+'PH P&L'!W51+'RH P&L'!W50+'SB P&L'!W50+'SM P&L'!W51+'WP P&L'!W50+'WW P&L'!W51+'HO P&L'!W30 | ... AA16: ='BK P&L'!AA51+'CC P&L'!AA50+'DN P&L'!AA50+'LF P&L'!AA51+'MR P&L'!AA50+'OP P&L'!AA50+'PH P&L'!AA51+'RH P&L'!AA50+'SB P&L'!AA50+'SM P&L'!AA51+'WP P&L'!AA50+'WW P&L'!AA51+'HO P&L'!AA30 | AB16: ='BK P&L'!AB51+'CC P&L'!AB50+'DN P&L'!AB50+'LF P&L'!AB51+'MR P&L'!AB50+'OP P&L'!AB50+'PH P&L'!AB51+'RH P&L'!AB50+'SB P&L'!AB50+'SM P&L'!AB51+'WP P&L'!AB50+'WW P&L'!AB51+'HO P&L'!AB30+Prototype!B43 | AC16: ='BK P&L'!AC51+'CC P&L'!AC50+'DN P&L'!AC50+'LF P&L'!AC51+'MR P&L'!AC50+'OP P&L'!AC50+'PH P&L'!AC51+'RH P&L'!AC50+'SB P&L'!AC50+'SM P&L'!AC51+'WP P&L'!AC50+'WW P&L'!AC51+'HO P&L'!AC30+Prototype!C43 | AD16: ='BK P&L'!AD51+'CC P&L'!AD50+'DN P&L'!AD50+'LF P&L'!AD51+'MR P&L'!AD50+'OP P&L'!AD50+'PH P&L'!AD51+'RH P&L'!AD50+'SB P&L'!AD50+'SM P&L'!AD51+'WP P&L'!AD50+'WW P&L'!AD51+'HO P&L'!AD30+Prototype!D43 | AE16: ='BK P&L'!AE51+'CC P&L'!AE50+'DN P&L'!AE50+'LF P&L'!AE51+'MR P&L'!AE50+'OP P&L'!AE50+'PH P&L'!AE51+'RH P&L'!AE50+'SB P&L'!AE50+'SM P&L'!AE51+'WP P&L'!AE50+'WW P&L'!AE51+'HO P&L'!AE30+Prototype!E43 | AF16: ='BK P&L'!AF51+'CC P&L'!AF50+'DN P&L'!AF50+'LF P&L'!AF51+'MR P&L'!AF50+'OP P&L'!AF50+'PH P&L'!AF51+'RH P&L'!AF50+'SB P&L'!AF50+'SM P&L'!AF51+'WP P&L'!AF50+'WW P&L'!AF51+'HO P&L'!AF30+Prototype!F43 | AG16: ='BK P&L'!AG51+'CC P&L'!AG50+'DN P&L'!AG50+'LF P&L'!AG51+'MR P&L'!AG50+'OP P&L'!AG50+'PH P&L'!AG51+'RH P&L'!AG50+'SB P&L'!AG50+'SM P&L'!AG51+'WP P&L'!AG50+'WW P&L'!AG51+'HO P&L'!AG30+Prototype!G43 | AH16: ='BK P&L'!AH51+'CC P&L'!AH50+'DN P&L'!AH50+'LF P&L'!AH51+'MR P&L'!AH50+'OP P&L'!AH50+'PH P&L'!AH51+'RH P&L'!AH50+'SB P&L'!AH50+'SM P&L'!AH51+'WP P&L'!AH50+'WW P&L'!AH51+'HO P&L'!AH30+Prototype!H43 | AI16: ='BK P&L'!AI51+'CC P&L'!AI50+'DN P&L'!AI50+'LF P&L'!AI51+'MR P&L'!AI50+'OP P&L'!AI50+'PH P&L'!AI51+'RH P&L'!AI50+'SB P&L'!AI50+'SM P&L'!AI51+'WP P&L'!AI50+'WW P&L'!AI51+'HO P&L'!AI30+Prototype!I43 | ... AY16: ='BK P&L'!AY51+'CC P&L'!AY50+'DN P&L'!AY50+'LF P&L'!AY51+'MR P&L'!AY50+'OP P&L'!AY50+'PH P&L'!AY51+'RH P&L'!AY50+'SB P&L'!AY50+'SM P&L'!AY51+'WP P&L'!AY50+'WW P&L'!AY51+'HO P&L'!AY30+Prototype!Y43
