Workbook

Sheet Cover
B2: Mighty Pilates
B3: Financial Model
B5: Last refreshed: June 23, 2026
B7: Tab Guide
B9: Summary & Controls | C9: Top-level KPIs, studio sales & EBITDA tables, charts
B10: Assumptions | C10: All model inputs: OpEx, sales forecast, rev rec curves, loan terms
B11: Cash Flow Forecast | C11: Monthly cash flow from operations + investing + financing
B12: P&L Summary | C12: Consolidated monthly P&L (Revenue → EBITDA)
B13: P&L Detail | C13: Account-level P&L matching accountant chart of accounts
B14: All Studios Summary | C14: Side-by-side studio comparison
B15: [Studio] FCST (×12) | C15: Per-studio P&L forecast (BK, CC, DN, LF, MR, OP, PH, RH, SB, SM, WP, WW)
B16: Cash, Debt & Equity | C16: Balance sheet, loan amortization schedules, equity tracking
B17: Sales Forecast | C17: Studio × month editable sales grid
B18: CapEx | C18: Capital expenditure project schedule
B19: QBO Actuals | C19: Historical accountant-booked P&L, BS, SCF (read-only)
B22: Conventions
B24: Yellow cells = inputs (edit these)
B25: Light green cells = actuals (closed months, do not edit)

Sheet Read Me
B2: Read Me — Model Architecture
B3: Last refreshed: June 23, 2026
B5: Tab Roles
B6: Summary & Controls | C6: Top-level dashboard. Sales + EBITDA by studio. Total EBITDA references P&L NOI directly.
B7: Assumptions | C7: Editable global parameters: rev rec curves, refund/discount/COGS rates, escalations, loan terms.
B8: Sales Forecast | C8: Per-studio × month sales grid. EDITABLE for forecast months (yellow). Drives revenue formulas. Hidden rows 101-113 hold 2025 history for lag formulas — do not delete.
B9: Cash, Debt & Equity | C9: Loan amortization schedule + debt service forecast.
B10: Cash Flow Forecast | C10: Monthly CF with operating/investing/financing.
B11: P&L (Consolidated) | C11: Consolidated monthly P&L. Revenue/COGS use direct lag formulas (with 2025 history). OpEx rows = SUM(per-studio) + HO + HO Other.
B12: All Studios Summary | C12: Side-by-side studio comparison.
B13: [Code] P&L (×12) | C13: Per-studio P&L: BK, CC, DN, LF, MR, OP, PH, RH, SB, SM, WP, WW. OpEx leaves are HARDCODED values (editable) summing to per-studio override. Revenue formulas use per-studio lag (2026+ from Sales Forecast, 2025 from hidden helper rows 102-113).
B14: HO P&L | C14: Head Office overhead (no revenue). Same leaf-summing structure. NOI is negative (= -Total OpEx).
B15: CapEx | C15: Project schedule (empty — add projects to populate Investing rows on CF).
B16: QBO Actuals | C16: Raw accountant-booked P&L/BS/SCF data. Read-only reference.
B18: Cell Conventions
B19: Yellow fill (FFFF99) | C19: EDITABLE input cell. Cat can change these.
B20: Light green fill | C20: Hardcoded actual from QBO/accountant. Do not edit (would diverge from source data).
B21: White/no fill | C21: Formula cell. Computed from other cells.
B22: Light blue fill | C22: Subtotal or total row.
B23: Bold green fill | C23: Key KPI (EBITDA, ending cash).
B25: Value Flow
B26: Sales edit | C26: Edit Sales Forecast cell → flows to: Studio P&L Sessions/Breakage (via lag formula) → Studio NOI → Summary & Controls studio row → Sales Forecast TOTAL row → Consolidated P&L revenue → Consolidated NOI → Summary & Controls Total EBITDA.
B27: OpEx leaf edit | C27: Edit per-studio OpEx leaf (e.g., BK Paid Ads) → Studio Marketing subtotal (=SUM leaves) → Studio Total OpEx → Studio NOI → Summary & Controls studio row → Consolidated P&L Marketing (=SUM studios + HO) → Consolidated Total OpEx → Consolidated NOI → Summary & Controls Total EBITDA. Full propagation works.
B28: Assumption edit | C28: Edit rate on Assumptions tab (refund %, discount %, escalation, etc.) → flows through all formulas referencing that cell.
B30: Hidden Helpers — DO NOT DELETE
B31: Sales Forecast rows 100-113 | C31: Hidden helper rows holding 2025 monthly sales (consolidated row 101 and per-studio rows 102-113). Required for 7-month lag formulas on Session/Breakage Revenue forecasts for May 2026 and Jun 2026.
B32: Sales Forecast row ~50+ | C32: Helper for chart data references on Summary & Controls. Removing breaks charts.
B34: Monthly Update Procedure (when QBO closes new month)
B35: Step 1 | C35: Upload new QBO export to Streamlit dashboard. Streamlit's committed_actuals.json gets updated.
B36: Step 2 | C36: Run refresh_from_streamlit.py (in /Users/chandlerclemons/financial-modeling/models/mighty/).
B37: Step 3 | C37: Refresh script will: (a) extend actuals columns by 1 month, (b) shift forecast forward, (c) refresh trailing-3-month avg lines (Taxes Paid, Property Taxes, Retail, Depreciation), (d) update 2025 helper row values if Streamlit data changed historicals.
B38: Step 4 | C38: Open the Excel and spot-check the new actuals column vs Streamlit. Save & share with stakeholders.
B40: Streamlit Source Repo
B41: GitHub | C41: github.com/c-clemons/mighty-pilates (private)
B42: Live app | C42: mighty-pilates-financial-model.streamlit.app
B43: Local files | C43: /Users/chandlerclemons/mighty-pilates/dashboard/data/

Sheet Summary
B2: Summary & Controls
B3: Top-level dashboard. Studio sales, EBITDA, YoY summary, charts.
B4: Monthly Total Session Sales by Studio
B5: Metric | C5: Studio | D5: Jan 2026 (A) | E5: Feb 2026 (A) | F5: Mar 2026 (A) | G5: Apr 2026 (A) | H5: May 2026 | I5: Jun 2026 | J5: Jul 2026 | K5: Aug 2026 | L5: Sep 2026 | M5: Oct 2026 | N5: Nov 2026 | O5: Dec 2026 | P5: Jan 2027 | Q5: Feb 2027 | R5: Mar 2027 | S5: Apr 2027 | T5: May 2027 | U5: Jun 2027 | V5: Jul 2027 | W5: Aug 2027 | X5: Sep 2027 | Y5: Oct 2027 | Z5: Nov 2027 | AA5: Dec 2027 | AB5: Jan 2028 | AC5: Feb 2028 | AD5: Mar 2028 | AE5: Apr 2028 | AF5: May 2028 | AG5: Jun 2028 | AH5: Jul 2028 | AI5: Aug 2028 | AJ5: Sep 2028 | AK5: Oct 2028 | AL5: Nov 2028 | AM5: Dec 2028
B6: Total Sales | D6: =SUM(D7:D19) | E6: =SUM(E7:E19) | F6: =SUM(F7:F19) | G6: =SUM(G7:G19) | H6: =SUM(H7:H19) | I6: =SUM(I7:I19) | J6: =SUM(J7:J19) | K6: =SUM(K7:K19) | ... AM6: =SUM(AM7:AM19)
C7: Berkeley | D7: ='Sales Forecast'!D6 | E7: ='Sales Forecast'!E6 | F7: ='Sales Forecast'!F6 | G7: ='Sales Forecast'!G6 | H7: ='Sales Forecast'!H6 | I7: ='Sales Forecast'!I6 | J7: ='Sales Forecast'!J6 | K7: ='Sales Forecast'!K6 | ... AM7: ='Sales Forecast'!AM6
C8: Culver City | D8: ='Sales Forecast'!D7 | E8: ='Sales Forecast'!E7 | F8: ='Sales Forecast'!F7 | G8: ='Sales Forecast'!G7 | H8: ='Sales Forecast'!H7 | I8: ='Sales Forecast'!I7 | J8: ='Sales Forecast'!J7 | K8: ='Sales Forecast'!K7 | ... AM8: ='Sales Forecast'!AM7
C9: Danville | D9: ='Sales Forecast'!D8 | E9: ='Sales Forecast'!E8 | F9: ='Sales Forecast'!F8 | G9: ='Sales Forecast'!G8 | H9: ='Sales Forecast'!H8 | I9: ='Sales Forecast'!I8 | J9: ='Sales Forecast'!J8 | K9: ='Sales Forecast'!K8 | ... AM9: ='Sales Forecast'!AM8
C10: Lafayette | D10: ='Sales Forecast'!D9 | E10: ='Sales Forecast'!E9 | F10: ='Sales Forecast'!F9 | G10: ='Sales Forecast'!G9 | H10: ='Sales Forecast'!H9 | I10: ='Sales Forecast'!I9 | J10: ='Sales Forecast'!J9 | K10: ='Sales Forecast'!K9 | ... AM10: ='Sales Forecast'!AM9
C11: Marin | D11: ='Sales Forecast'!D10 | E11: ='Sales Forecast'!E10 | F11: ='Sales Forecast'!F10 | G11: ='Sales Forecast'!G10 | H11: ='Sales Forecast'!H10 | I11: ='Sales Forecast'!I10 | J11: ='Sales Forecast'!J10 | K11: ='Sales Forecast'!K10 | ... AM11: ='Sales Forecast'!AM10
C12: Ocean Park | D12: ='Sales Forecast'!D11 | E12: ='Sales Forecast'!E11 | F12: ='Sales Forecast'!F11 | G12: ='Sales Forecast'!G11 | H12: ='Sales Forecast'!H11 | I12: ='Sales Forecast'!I11 | J12: ='Sales Forecast'!J11 | K12: ='Sales Forecast'!K11 | ... AM12: ='Sales Forecast'!AM11
C13: Presidio Heights | D13: ='Sales Forecast'!D12 | E13: ='Sales Forecast'!E12 | F13: ='Sales Forecast'!F12 | G13: ='Sales Forecast'!G12 | H13: ='Sales Forecast'!H12 | I13: ='Sales Forecast'!I12 | J13: ='Sales Forecast'!J12 | K13: ='Sales Forecast'!K12 | ... AM13: ='Sales Forecast'!AM12
C14: Russian Hill | D14: ='Sales Forecast'!D13 | E14: ='Sales Forecast'!E13 | F14: ='Sales Forecast'!F13 | G14: ='Sales Forecast'!G13 | H14: ='Sales Forecast'!H13 | I14: ='Sales Forecast'!I13 | J14: ='Sales Forecast'!J13 | K14: ='Sales Forecast'!K13 | ... AM14: ='Sales Forecast'!AM13
C15: Santa Barbara | D15: ='Sales Forecast'!D14 | E15: ='Sales Forecast'!E14 | F15: ='Sales Forecast'!F14 | G15: ='Sales Forecast'!G14 | H15: ='Sales Forecast'!H14 | I15: ='Sales Forecast'!I14 | J15: ='Sales Forecast'!J14 | K15: ='Sales Forecast'!K14 | ... AM15: ='Sales Forecast'!AM14
C16: Santa Monica | D16: ='Sales Forecast'!D15 | E16: ='Sales Forecast'!E15 | F16: ='Sales Forecast'!F15 | G16: ='Sales Forecast'!G15 | H16: ='Sales Forecast'!H15 | I16: ='Sales Forecast'!I15 | J16: ='Sales Forecast'!J15 | K16: ='Sales Forecast'!K15 | ... AM16: ='Sales Forecast'!AM15
C17: West Portal | D17: ='Sales Forecast'!D16 | E17: ='Sales Forecast'!E16 | F17: ='Sales Forecast'!F16 | G17: ='Sales Forecast'!G16 | H17: ='Sales Forecast'!H16 | I17: ='Sales Forecast'!I16 | J17: ='Sales Forecast'!J16 | K17: ='Sales Forecast'!K16 | ... AM17: ='Sales Forecast'!AM16
C18: Westwood | D18: ='Sales Forecast'!D17 | E18: ='Sales Forecast'!E17 | F18: ='Sales Forecast'!F17 | G18: ='Sales Forecast'!G17 | H18: ='Sales Forecast'!H17 | I18: ='Sales Forecast'!I17 | J18: ='Sales Forecast'!J17 | K18: ='Sales Forecast'!K17 | ... AM18: ='Sales Forecast'!AM17
C19: Head Office | D19: 0 | E19: 0 | F19: 0 | G19: 0 | H19: 0 | I19: 0 | J19: 0 | K19: 0 | L19: 0 | M19: 0 | N19: 0 | O19: 0 | P19: 0 | Q19: 0 | R19: 0 | S19: 0 | T19: 0 | U19: 0 | V19: 0 | W19: 0 | X19: 0 | Y19: 0 | Z19: 0 | AA19: 0 | AB19: 0 | AC19: 0 | AD19: 0 | AE19: 0 | AF19: 0 | AG19: 0 | AH19: 0 | AI19: 0 | AJ19: 0 | AK19: 0 | AL19: 0 | AM19: 0
B21: Monthly EBITDA by Studio
B22: Total EBITDA | D22: =SUM(D23:D35) | E22: =SUM(E23:E35) | F22: =SUM(F23:F35) | G22: =SUM(G23:G35) | H22: =SUM(H23:H35) | I22: =SUM(I23:I35) | J22: =SUM(J23:J35) | K22: =SUM(K23:K35) | ... AM22: =SUM(AM23:AM35)
C23: Berkeley | D23: ='BK P&L'!D63 | E23: ='BK P&L'!E63 | F23: ='BK P&L'!F63 | G23: ='BK P&L'!G63 | H23: ='BK P&L'!H63 | I23: ='BK P&L'!I63 | J23: ='BK P&L'!J63 | K23: ='BK P&L'!K63 | ... AM23: ='BK P&L'!AM63
C24: Culver City | D24: ='CC P&L'!D63 | E24: ='CC P&L'!E63 | F24: ='CC P&L'!F63 | G24: ='CC P&L'!G63 | H24: ='CC P&L'!H63 | I24: ='CC P&L'!I63 | J24: ='CC P&L'!J63 | K24: ='CC P&L'!K63 | ... AM24: ='CC P&L'!AM63
C25: Danville | D25: ='DN P&L'!D63 | E25: ='DN P&L'!E63 | F25: ='DN P&L'!F63 | G25: ='DN P&L'!G63 | H25: ='DN P&L'!H63 | I25: ='DN P&L'!I63 | J25: ='DN P&L'!J63 | K25: ='DN P&L'!K63 | ... AM25: ='DN P&L'!AM63
C26: Lafayette | D26: ='LF P&L'!D63 | E26: ='LF P&L'!E63 | F26: ='LF P&L'!F63 | G26: ='LF P&L'!G63 | H26: ='LF P&L'!H63 | I26: ='LF P&L'!I63 | J26: ='LF P&L'!J63 | K26: ='LF P&L'!K63 | ... AM26: ='LF P&L'!AM63
C27: Marin | D27: ='MR P&L'!D63 | E27: ='MR P&L'!E63 | F27: ='MR P&L'!F63 | G27: ='MR P&L'!G63 | H27: ='MR P&L'!H63 | I27: ='MR P&L'!I63 | J27: ='MR P&L'!J63 | K27: ='MR P&L'!K63 | ... AM27: ='MR P&L'!AM63
C28: Ocean Park | D28: ='OP P&L'!D63 | E28: ='OP P&L'!E63 | F28: ='OP P&L'!F63 | G28: ='OP P&L'!G63 | H28: ='OP P&L'!H63 | I28: ='OP P&L'!I63 | J28: ='OP P&L'!J63 | K28: ='OP P&L'!K63 | ... AM28: ='OP P&L'!AM63
C29: Presidio Heights | D29: ='PH P&L'!D63 | E29: ='PH P&L'!E63 | F29: ='PH P&L'!F63 | G29: ='PH P&L'!G63 | H29: ='PH P&L'!H63 | I29: ='PH P&L'!I63 | J29: ='PH P&L'!J63 | K29: ='PH P&L'!K63 | ... AM29: ='PH P&L'!AM63
C30: Russian Hill | D30: ='RH P&L'!D63 | E30: ='RH P&L'!E63 | F30: ='RH P&L'!F63 | G30: ='RH P&L'!G63 | H30: ='RH P&L'!H63 | I30: ='RH P&L'!I63 | J30: ='RH P&L'!J63 | K30: ='RH P&L'!K63 | ... AM30: ='RH P&L'!AM63
C31: Santa Barbara | D31: ='SB P&L'!D63 | E31: ='SB P&L'!E63 | F31: ='SB P&L'!F63 | G31: ='SB P&L'!G63 | H31: ='SB P&L'!H63 | I31: ='SB P&L'!I63 | J31: ='SB P&L'!J63 | K31: ='SB P&L'!K63 | ... AM31: ='SB P&L'!AM63
C32: Santa Monica | D32: ='SM P&L'!D63 | E32: ='SM P&L'!E63 | F32: ='SM P&L'!F63 | G32: ='SM P&L'!G63 | H32: ='SM P&L'!H63 | I32: ='SM P&L'!I63 | J32: ='SM P&L'!J63 | K32: ='SM P&L'!K63 | ... AM32: ='SM P&L'!AM63
C33: West Portal | D33: ='WP P&L'!D63 | E33: ='WP P&L'!E63 | F33: ='WP P&L'!F63 | G33: ='WP P&L'!G63 | H33: ='WP P&L'!H63 | I33: ='WP P&L'!I63 | J33: ='WP P&L'!J63 | K33: ='WP P&L'!K63 | ... AM33: ='WP P&L'!AM63
C34: Westwood | D34: ='WW P&L'!D63 | E34: ='WW P&L'!E63 | F34: ='WW P&L'!F63 | G34: ='WW P&L'!G63 | H34: ='WW P&L'!H63 | I34: ='WW P&L'!I63 | J34: ='WW P&L'!J63 | K34: ='WW P&L'!K63 | ... AM34: ='WW P&L'!AM63
C35: Head Office | D35: ='HO P&L'!D36 | E35: ='HO P&L'!E36 | F35: ='HO P&L'!F36 | G35: ='HO P&L'!G36 | H35: ='HO P&L'!H36 | I35: ='HO P&L'!I36 | J35: ='HO P&L'!J36 | K35: ='HO P&L'!K36 | ... AM35: ='HO P&L'!AM36
B37: Total Add Backs | D37: ='P&L'!D38 | E37: ='P&L'!E38 | F37: ='P&L'!F38 | G37: ='P&L'!G38 | H37: ='P&L'!H38 | I37: ='P&L'!I38 | J37: ='P&L'!J38 | K37: ='P&L'!K38 | ... AM37: ='P&L'!AM38
B38: Total Adj-EBITDA | D38: ='P&L'!D39 | E38: ='P&L'!E39 | F38: ='P&L'!F39 | G38: ='P&L'!G39 | H38: ='P&L'!H39 | I38: ='P&L'!I39 | J38: ='P&L'!J39 | K38: ='P&L'!K39 | ... AM38: ='P&L'!AM39
B40: Annual Summary
B41: Metric | C41: Studio | D41: 2026 | E41: 2027 | F41: 2028 | G41: 2027 YoY | H41: 2028 YoY
B42: Total Sales | D42: =SUM(D43:D55) | E42: =SUM(E43:E55) | F42: =SUM(F43:F55) | G42: =IFERROR((E42-D42)/D42,0) | H42: =IFERROR((F42-E42)/E42,0)
C43: Berkeley | D43: =SUM('Sales Forecast'!D6:O6) | E43: =SUM('Sales Forecast'!P6:AA6) | F43: =SUM('Sales Forecast'!AB6:AM6) | G43: =IFERROR((E41-D41)/D41,0) | H43: =IFERROR((F41-E41)/E41,0)
C44: Culver City | D44: =SUM('Sales Forecast'!D7:O7) | E44: =SUM('Sales Forecast'!P7:AA7) | F44: =SUM('Sales Forecast'!AB7:AM7) | G44: =IFERROR((E42-D42)/D42,0) | H44: =IFERROR((F42-E42)/E42,0)
...

Sheet Assumptions
B2: Assumptions
B3: Yellow cells are editable inputs. All other tabs reference these values.
B5: 1. Model Control
B6: Last Actuals Month | C6: May 2026
B7: Forecast Horizon (months) | C7: 32
B8: Forecast End Month | C8: Dec 2028
B10: 2. Revenue Recognition Curves
B11: Lag Month (0 = sale month) | C11: 0 | D11: 1 | E11: 2 | F11: 3 | G11: 4 | H11: 5 | I11: 6 | J11: Sum
B12: Earned % | C12: 0.3868 | D12: 0.2997 | E12: 0.0855 | F12: 0.0482 | G12: 0.0261 | H12: 0.0193 | I12: 0.0144 | J12: =SUM(C12:I12)
B13: Breakage % | C13: 0.0017 | D13: 0.0602 | E13: 0.0053 | F13: 0.0003 | G13: 0.0001 | H13: 0.0008 | I13: 0.0516 | J13: =SUM(C13:I13)
B14: Total (Earned + Breakage) | C14: =C12+C13 | D14: =D12+D13 | E14: =E12+E13 | F14: =F12+F13 | G14: =G12+G13 | H14: =H12+H13 | I14: =I12+I13 | J14: =SUM(C14:I14)
B16: 3. Rates (% of Gross Revenue)
B17: Refund Rate | C17: -0.0158 | D17: Refunds as % of gross revenue. Negative reduces net revenue.
B18: Discount Rate | C18: -0.0531 | D18: Discounts as % of gross revenue. Negative reduces net revenue.
B19: Merchant Fee % | C19: 0.0286 | D19: Payment processor fees as % of revenue.
B20: COGS % | C20: 0.0096 | D20: Cost of goods sold as % of revenue (retail).
B22: 4. Annual Escalation Rates
B23: Rent / Property Escalation | C23: 0.03 | D23: 3% annual rent step-up applied to forecast months
B24: Other OpEx Escalation | C24: 0.04 | D24: 4% annual escalation for all non-rent OpEx categories
B25: Sales YoY Growth | C25: 0.05 | D25: 5% YoY assumed for 2028 (applied to 2027 seasonal pattern)
B27: 5. Loan Terms (as of Apr 2026)
B28: Loan | C28: Original Amt | D28: Current Balance | E28: Rate (Annual) | F28: Avg Monthly Pmt | G28: Start Date | H28: Type
B29: MindBody Loan - SM | C29: 193706.66 | D29: 99348.21 | E29: 0 | F29: 18871.69 | G29: 2025-09 | H29: Amortizing
B30: MindBody Loan - PH | C30: 130000 | D30: 46989.79 | E30: 0 | F30: 16602.04 | G30: 2025-09 | H30: Amortizing
B31: MindBody Loan - LF | C31: 69249.28 | D31: 20599.85 | E31: 0 | F31: 12162.36 | G31: 2025-10 | H31: Amortizing
B32: MindBody Loan - MR | C32: 67443.81 | D32: 14815.18 | E32: 0 | F32: 13157.16 | G32: 2025-10 | H32: Amortizing
B33: Samson Loan | C33: 265414.78 | D33: 189034.12 | E33: 0 | F33: 25460.22 | G33: 2025-11 | H33: Amortizing
B34: Specialty Capital Loan | C34: 217184.21 | D34: 165407.89 | E34: 0 | F34: 25888.16 | G34: 2025-12 | H34: Amortizing
B35: Norbrook Inc Loan | C35: 162318 | D35: 162318 | E35: 0.08 | F35: 0 | G35: 2025-10 | H35: Interest-Only
B36: TOTAL DEBT | D36: =SUM(D29:D35) | F36: =SUM(F29:F35)
B38: 6. Active Studios
B39: Code | C39: Name
B40: BK | C40: Berkeley
B41: CC | C41: Culver City
B42: DN | C42: Danville
B43: LF | C43: Lafayette
B44: MR | C44: Marin
B45: OP | C45: Ocean Park
B46: PH | C46: Presidio Heights
B47: RH | C47: Russian Hill
...

Sheet Sales Forecast
B2: Sales Forecast (Gross)
B3: Jan-Jul 2026 actuals (locked, Cat-authoritative). Aug 2026 onwards forecast (editable).
B4: Per-Studio Monthly Sales
B5: Code | C5: Studio | D5: Jan 2026 | E5: Feb 2026 | F5: Mar 2026 | G5: Apr 2026 | H5: May 2026 (A) | I5: Jun 2026 | J5: Jul 2026 (A) | K5: Aug 2026 | L5: Sep 2026 | M5: Oct 2026 | N5: Nov 2026 | O5: Dec 2026 | P5: Jan 2027 | Q5: Feb 2027 | R5: Mar 2027 | S5: Apr 2027 | T5: May 2027 | U5: Jun 2027 | V5: Jul 2027 | W5: Aug 2027 | X5: Sep 2027 | Y5: Oct 2027 | Z5: Nov 2027 | AA5: Dec 2027 | AB5: Jan 2028 | AC5: Feb 2028 | AD5: Mar 2028 | AE5: Apr 2028 | AF5: May 2028 | AG5: Jun 2028 | AH5: Jul 2028 | AI5: Aug 2028 | AJ5: Sep 2028 | AK5: Oct 2028 | AL5: Nov 2028 | AM5: Dec 2028
B6: BK | C6: Berkeley | D6: 124393 | E6: 129377 | F6: 103159 | G6: 136117 | H6: 83273 | I6: 100821 | J6: 99551 | K6: 120000 | L6: 120000 | M6: 130000 | N6: 130000 | O6: 149000 | P6: 130612.65 | Q6: 135845.85 | R6: 108316.95 | S6: 142922.85 | T6: 87649.8 | U6: 115500 | V6: 110250 | W6: 126000 | X6: 126000 | Y6: 136500 | Z6: 136500 | AA6: 156450 | AB6: 137143.28 | AC6: 142638.14 | AD6: 113732.8 | AE6: 150068.99 | AF6: 92032.29 | AG6: 121275 | AH6: 115762.5 | AI6: 132300 | AJ6: 132300 | AK6: 143325 | AL6: 143325 | AM6: 164272.5
B7: CC | C7: Culver City | D7: 43840 | E7: 38704 | F7: 42619 | G7: 39690 | H7: 43327 | I7: 32522 | J7: 42903 | K7: 50000 | L7: 53000 | M7: 60000 | N7: 64000 | O7: 60000 | P7: 61000 | Q7: 73307 | R7: 69238 | S7: 75096 | T7: 70949 | U7: 64231 | V7: 95489 | W7: 107456 | X7: 102425 | Y7: 95000 | Z7: 95000 | AA7: 95000 | AB7: 64050 | AC7: 76972.35 | AD7: 72699.9 | AE7: 78850.8 | AF7: 74496.45 | AG7: 67442.55 | AH7: 100263.45 | AI7: 112828.8 | AJ7: 107546.25 | AK7: 99750 | AL7: 99750 | AM7: 99750
B8: DN | C8: Danville | D8: 24286 | E8: 23358 | F8: 20289 | G8: 20363 | H8: 15337 | I8: 20327 | J8: 16795 | K8: 25000 | L8: 25000 | M8: 30000 | N8: 25000 | O8: 32000 | P8: 32000 | Q8: 40000 | R8: 40000 | S8: 45000 | T8: 45000 | U8: 50000 | V8: 50000 | W8: 50000 | X8: 55000 | Y8: 55000 | Z8: 55000 | AA8: 55000 | AB8: 33600 | AC8: 42000 | AD8: 42000 | AE8: 47250 | AF8: 47250 | AG8: 52500 | AH8: 52500 | AI8: 52500 | AJ8: 57750 | AK8: 57750 | AL8: 57750 | AM8: 57750
B9: LF | C9: Lafayette | D9: 92365 | E9: 126186 | F9: 78385 | G9: 106542 | H9: 71444 | I9: 81024 | J9: 86878 | K9: 80000 | L9: 80250 | M9: 85000 | N9: 95000 | O9: 110000 | P9: 96983.25 | Q9: 132495.3 | R9: 82304.25 | S9: 111869.1 | T9: 75832.05 | U9: 84000 | V9: 84262.5 | W9: 84000 | X9: 84262.5 | Y9: 89250 | Z9: 99750 | AA9: 115500 | AB9: 101832.41 | AC9: 139120.07 | AD9: 86419.46 | AE9: 117462.56 | AF9: 79623.65 | AG9: 88200 | AH9: 88475.62 | AI9: 88200 | AJ9: 88475.62 | AK9: 93712.5 | AL9: 104737.5 | AM9: 121275
B10: MR | C10: Marin | D10: 100589 | E10: 114193 | F10: 90196 | G10: 140256 | H10: 74382 | I10: 98742 | J10: 109856 | K10: 120000 | L10: 98000 | M10: 110000 | N10: 120000 | O10: 115000 | P10: 105618.45 | Q10: 119902.65 | R10: 94705.8 | S10: 147268.8 | T10: 78685.95 | U10: 101115 | V10: 99750 | W10: 126000 | X10: 102900 | Y10: 115500 | Z10: 126000 | AA10: 120750 | AB10: 110899.37 | AC10: 125897.78 | AD10: 99441.09 | AE10: 154632.24 | AF10: 82620.25 | AG10: 106170.75 | AH10: 104737.5 | AI10: 132300 | AJ10: 108045 | AK10: 121275 | AL10: 132300 | AM10: 126787.5
B11: OP | C11: Ocean Park | D11: 60583 | E11: 59614 | F11: 62052 | G11: 73815 | H11: 63770 | I11: 50286 | J11: 58162 | K11: 60000 | L11: 63000 | M11: 70000 | N11: 75000 | O11: 60000 | P11: 63612.15 | Q11: 62594.7 | R11: 65154.6 | S11: 77505.75 | T11: 67045.65 | U11: 67410 | V11: 78750 | W11: 63000 | X11: 66150 | Y11: 73500 | Z11: 78750 | AA11: 63000 | AB11: 66792.76 | AC11: 65724.43 | AD11: 68412.33 | AE11: 81381.04 | AF11: 70397.93 | AG11: 70780.5 | AH11: 82687.5 | AI11: 66150 | AJ11: 69457.5 | AK11: 77175 | AL11: 82687.5 | AM11: 66150
B12: PH | C12: Presidio Heights | D12: 124927 | E12: 180839 | F12: 115051 | G12: 179323 | H12: 93511 | I12: 113383 | J12: 117515 | K12: 155000 | L12: 120000 | M12: 125000 | N12: 140000 | O12: 150000 | P12: 131173.35 | Q12: 189880.95 | R12: 120803.55 | S12: 188289.15 | T12: 100401 | U12: 120750 | V12: 115500 | W12: 162750 | X12: 126000 | Y12: 131250 | Z12: 147000 | AA12: 157500 | AB12: 137732.02 | AC12: 199375 | AD12: 126843.73 | AE12: 197703.61 | AF12: 105421.05 | AG12: 126787.5 | AH12: 121275 | AI12: 170887.5 | AJ12: 132300 | AK12: 137812.5 | AL12: 154350 | AM12: 165375
B13: RH | C13: Russian Hill | D13: 96145 | E13: 94253 | F13: 85589 | G13: 108129 | H13: 66857 | I13: 71619 | J13: 75936 | K13: 95000 | L13: 80000 | M13: 82000 | N13: 80000 | O13: 88000 | P13: 100952.25 | Q13: 98965.65 | R13: 89868.45 | S13: 113535.45 | T13: 71700.3 | U13: 80850 | V13: 78750 | W13: 99750 | X13: 84000 | Y13: 86100 | Z13: 84000 | AA13: 92400 | AB13: 105999.86 | AC13: 103913.93 | AD13: 94361.87 | AE13: 119212.22 | AF13: 75285.32 | AG13: 84892.5 | AH13: 82687.5 | AI13: 104737.5 | AJ13: 88200 | AK13: 90405 | AL13: 88200 | AM13: 97020
B14: SB | C14: Santa Barbara | D14: 32747 | E14: 27799 | F14: 25898 | G14: 23393 | H14: 20133 | I14: 17783 | J14: 18714 | K14: 30000 | L14: 30000 | M14: 33000 | N14: 35000 | O14: 35000 | P14: 59231 | Q14: 60132 | R14: 52754 | S14: 51670 | T14: 60236 | U14: 51621 | V14: 62000 | W14: 63000 | X14: 73000 | Y14: 65000 | Z14: 64200 | AA14: 64200 | AB14: 62192.55 | AC14: 63138.6 | AD14: 55391.7 | AE14: 54253.5 | AF14: 63247.8 | AG14: 54202.05 | AH14: 65100 | AI14: 66150 | AJ14: 76650 | AK14: 68250 | AL14: 67410 | AM14: 67410
B15: SM | C15: Santa Monica | D15: 184491 | E15: 161597 | F15: 192258 | G15: 157521 | H15: 206632 | I15: 130716 | J15: 163688 | K15: 200000 | L15: 190000 | M15: 220000 | N15: 251450 | O15: 190000 | P15: 193715.55 | Q15: 169676.85 | R15: 201870.9 | S15: 165397.05 | T15: 217676.55 | U15: 210000 | V15: 210000 | W15: 210000 | X15: 199500 | Y15: 231000 | Z15: 264022.5 | AA15: 199500 | AB15: 203401.33 | AC15: 178160.69 | AD15: 211964.45 | AE15: 173666.9 | AF15: 228560.38 | AG15: 220500 | AH15: 220500 | AI15: 220500 | AJ15: 209475 | AK15: 242550 | AL15: 277223.62 | AM15: 209475
B16: WP | C16: West Portal | D16: 1573 | E16: 1513 | F16: 784 | G16: 370 | H16: 26 | I16: 225 | J16: 99 | K16: 78000 | L16: 75000 | M16: 80000 | N16: 80000 | O16: 80000 | P16: 90025 | Q16: 86822 | R16: 85300 | S16: 127703 | T16: 79689 | U16: 76768 | V16: 70767 | W16: 102739 | X16: 68837 | Y16: 83777 | Z16: 79979 | AA16: 79880 | AB16: 94526.25 | AC16: 91163.1 | AD16: 89565 | AE16: 134088.15 | AF16: 83673.45 | AG16: 80606.4 | AH16: 74305.35 | AI16: 107875.95 | AJ16: 72278.85 | AK16: 87965.85 | AL16: 83977.95 | AM16: 83874
B17: WW | C17: Westwood | D17: 71360 | E17: 69405 | F17: 62992 | G17: 49441 | H17: 60750 | I17: 41757 | J17: 47537 | K17: 64000 | L17: 72000 | M17: 80000 | N17: 85600 | O17: 74900 | P17: 74928 | Q17: 72875.25 | R17: 66141.6 | S17: 51913.05 | T17: 63897.75 | U17: 68250 | V17: 65100 | W17: 67200 | X17: 75600 | Y17: 84000 | Z17: 89880 | AA17: 78645 | AB17: 78674.4 | AC17: 76519.01 | AD17: 69448.68 | AE17: 54508.7 | AF17: 67092.64 | AG17: 71662.5 | AH17: 68355 | AI17: 70560 | AJ17: 79380 | AK17: 88200 | AL17: 94374 | AM17: 82577.25
B18: TOTAL | C18: All Studios | D18: =SUM(D6:D17) | E18: =SUM(E6:E17) | F18: =SUM(F6:F17) | G18: =SUM(G6:G17) | H18: =SUM(H6:H17) | I18: =SUM(I6:I17) | J18: =SUM(J6:J17) | K18: =SUM(K6:K17) | ... AM18: =SUM(AM6:AM17)
B20: Annual Summary
B21: Code | C21: Studio | D21: 2026 | E21: 2027 | F21: 2028 | G21: 2027 YoY | H21: 2028 YoY
B22: BK | C22: Berkeley | D22: =SUM(D6:O6) | E22: =SUM(P6:AA6) | F22: =SUM(AB6:AM6) | G22: =IFERROR((E22-D22)/D22,0) | H22: =IFERROR((F22-E22)/E22,0)
B23: CC | C23: Culver City | D23: =SUM(D7:O7) | E23: =SUM(P7:AA7) | F23: =SUM(AB7:AM7) | G23: =IFERROR((E23-D23)/D23,0) | H23: =IFERROR((F23-E23)/E23,0)
B24: DN | C24: Danville | D24: =SUM(D8:O8) | E24: =SUM(P8:AA8) | F24: =SUM(AB8:AM8) | G24: =IFERROR((E24-D24)/D24,0) | H24: =IFERROR((F24-E24)/E24,0)
B25: LF | C25: Lafayette | D25: =SUM(D9:O9) | E25: =SUM(P9:AA9) | F25: =SUM(AB9:AM9) | G25: =IFERROR((E25-D25)/D25,0) | H25: =IFERROR((F25-E25)/E25,0)
B26: MR | C26: Marin | D26: =SUM(D10:O10) | E26: =SUM(P10:AA10) | F26: =SUM(AB10:AM10) | G26: =IFERROR((E26-D26)/D26,0) | H26: =IFERROR((F26-E26)/E26,0)
B27: OP | C27: Ocean Park | D27: =SUM(D11:O11) | E27: =SUM(P11:AA11) | F27: =SUM(AB11:AM11) | G27: =IFERROR((E27-D27)/D27,0) | H27: =IFERROR((F27-E27)/E27,0)
B28: PH | C28: Presidio Heights | D28: =SUM(D12:O12) | E28: =SUM(P12:AA12) | F28: =SUM(AB12:AM12) | G28: =IFERROR((E28-D28)/D28,0) | H28: =IFERROR((F28-E28)/E28,0)
B29: RH | C29: Russian Hill | D29: =SUM(D13:O13) | E29: =SUM(P13:AA13) | F29: =SUM(AB13:AM13) | G29: =IFERROR((E29-D29)/D29,0) | H29: =IFERROR((F29-E29)/E29,0)
B30: SB | C30: Santa Barbara | D30: =SUM(D14:O14) | E30: =SUM(P14:AA14) | F30: =SUM(AB14:AM14) | G30: =IFERROR((E30-D30)/D30,0) | H30: =IFERROR((F30-E30)/E30,0)
B31: SM | C31: Santa Monica | D31: =SUM(D15:O15) | E31: =SUM(P15:AA15) | F31: =SUM(AB15:AM15) | G31: =IFERROR((E31-D31)/D31,0) | H31: =IFERROR((F31-E31)/E31,0)
B32: WP | C32: West Portal | D32: =SUM(D16:O16) | E32: =SUM(P16:AA16) | F32: =SUM(AB16:AM16) | G32: =IFERROR((E32-D32)/D32,0) | H32: =IFERROR((F32-E32)/E32,0)
B33: WW | C33: Westwood | D33: =SUM(D17:O17) | E33: =SUM(P17:AA17) | F33: =SUM(AB17:AM17) | G33: =IFERROR((E33-D33)/D33,0) | H33: =IFERROR((F33-E33)/E33,0)
B34: TOTAL | C34: All Studios | D34: =SUM(D22:D33) | E34: =SUM(E22:E33) | F34: =SUM(F22:F33) | G34: =IFERROR((E34-D34)/D34,0) | H34: =IFERROR((F34-E34)/E34,0)
B100: 2025 SALES HISTORY (hidden helper for lag formulas) | D100: 2025-07 | E100: 2025-08 | F100: 2025-09 | G100: 2025-10 | H100: 2025-11 | I100: 2025-12
D101: 808077 | E101: 930709 | F101: 758432 | G101: 830044 | H101: 833160 | I101: 847328
B102: 2025 helper: BK (Berkeley) | H102: 102111.01 | I102: 103847.42
B103: 2025 helper: CC (Culver City) | H103: 36886.61 | I103: 37513.88
B104: 2025 helper: DN (Danville) | H104: 18359.97 | I104: 18672.19
B105: 2025 helper: LF (Lafayette) | H105: 84253.69 | I105: 85686.43
B106: 2025 helper: MR (Marin) | H106: 92130.72 | I106: 93697.42
B107: 2025 helper: OP (Ocean Park) | H107: 56662.27 | I107: 57625.82
...

Sheet Cash, Debt & Equity
B2: Cash, Debt & Equity
B4: Item | D4: Jan 2026 | E4: Feb 2026 | F4: Mar 2026 | G4: Apr 2026 | H4: May 2026 | I4: Jun 2026 | J4: Jul 2026 | K4: Aug 2026 | L4: Sep 2026 | M4: Oct 2026 | N4: Nov 2026 | O4: Dec 2026 | P4: Jan 2027 | Q4: Feb 2027 | R4: Mar 2027 | S4: Apr 2027 | T4: May 2027 | U4: Jun 2027 | V4: Jul 2027 | W4: Aug 2027 | X4: Sep 2027 | Y4: Oct 2027 | Z4: Nov 2027 | AA4: Dec 2027 | AB4: Jan 2028 | AC4: Feb 2028 | AD4: Mar 2028 | AE4: Apr 2028 | AF4: May 2028 | AG4: Jun 2028 | AH4: Jul 2028 | AI4: Aug 2028 | AJ4: Sep 2028 | AK4: Oct 2028 | AL4: Nov 2028 | AM4: Dec 2028
B5: CASH POSITION
B6: Ending Cash Balance (from CF) | D6: ='Cash Flow Forecast'!D38 | E6: ='Cash Flow Forecast'!E38 | F6: ='Cash Flow Forecast'!F38 | G6: ='Cash Flow Forecast'!G38 | H6: ='Cash Flow Forecast'!H38 | I6: ='Cash Flow Forecast'!I38 | J6: ='Cash Flow Forecast'!J38 | K6: ='Cash Flow Forecast'!K38 | ... AM6: ='Cash Flow Forecast'!AM38
B8: DEBT SCHEDULE — Loan Balances by Month
B9: MindBody Loan - SM | D9: 0 | E9: 0 | F9: 0 | G9: 99348.21 | H9: 0 | I9: =MAX(H9-18871.69,0) | J9: =MAX(I9-18871.69,0) | K9: =MAX(J9-18871.69,0) | L9: =MAX(K9-18871.69,0) | M9: =MAX(L9-18871.69,0) | N9: =MAX(M9-18871.69,0) | O9: =MAX(N9-18871.69,0) | P9: =MAX(O9-18871.69,0) | ... AM9: =MAX(AL9-18871.69,0)
B10: MindBody Loan - PH | D10: 0 | E10: 0 | F10: 0 | G10: 46989.79 | H10: 0 | I10: =MAX(H10-16602.04,0) | J10: =MAX(I10-16602.04,0) | K10: =MAX(J10-16602.04,0) | L10: =MAX(K10-16602.04,0) | M10: =MAX(L10-16602.04,0) | N10: =MAX(M10-16602.04,0) | O10: =MAX(N10-16602.04,0) | P10: =MAX(O10-16602.04,0) | ... AM10: =MAX(AL10-16602.04,0)
B11: MindBody Loan - LF | D11: 0 | E11: 0 | F11: 0 | G11: 20599.85 | H11: 0 | I11: =MAX(H11-12162.36,0) | J11: =MAX(I11-12162.36,0) | K11: =MAX(J11-12162.36,0) | L11: =MAX(K11-12162.36,0) | M11: =MAX(L11-12162.36,0) | N11: =MAX(M11-12162.36,0) | O11: =MAX(N11-12162.36,0) | P11: =MAX(O11-12162.36,0) | ... AM11: =MAX(AL11-12162.36,0)
B12: MindBody Loan - MR | D12: 0 | E12: 0 | F12: 0 | G12: 14815.18 | H12: 0 | I12: =MAX(H12-13157.16,0) | J12: =MAX(I12-13157.16,0) | K12: =MAX(J12-13157.16,0) | L12: =MAX(K12-13157.16,0) | M12: =MAX(L12-13157.16,0) | N12: =MAX(M12-13157.16,0) | O12: =MAX(N12-13157.16,0) | P12: =MAX(O12-13157.16,0) | ... AM12: =MAX(AL12-13157.16,0)
B13: Samson Loan | D13: 205426.16 | E13: 189034.12 | F13: 154505.72 | G13: 129045.5 | H13: 94517.1 | I13: =MAX(H13-25460.22,0) | J13: =MAX(I13-25460.22,0) | K13: =MAX(J13-25460.22,0) | L13: =MAX(K13-25460.22,0) | M13: =MAX(L13-25460.22,0) | N13: =MAX(M13-25460.22,0) | O13: =MAX(N13-25460.22,0) | P13: =MAX(O13-25460.22,0) | ... AM13: =MAX(AL13-25460.22,0)
B14: Specialty Capital Loan | D14: 187921.05 | E14: 165407.89 | F14: 135078.94 | G14: 112565.78 | H14: 90052.62 | I14: =MAX(H14-25888.16,0) | J14: =MAX(I14-25888.16,0) | K14: =MAX(J14-25888.16,0) | L14: =MAX(K14-25888.16,0) | M14: =MAX(L14-25888.16,0) | N14: =MAX(M14-25888.16,0) | O14: =MAX(N14-25888.16,0) | P14: =MAX(O14-25888.16,0) | ... AM14: =MAX(AL14-25888.16,0)
B15: Norbrook Inc Loan | D15: 0 | E15: 0 | F15: 0 | G15: 162318 | H15: 0 | I15: =H15 | J15: =I15 | K15: =J15 | L15: =K15 | M15: =L15 | N15: =M15 | O15: =N15 | P15: =O15 | ... AM15: =AL15
B16: TOTAL DEBT | D16: =SUM(D9:D15) | E16: =SUM(E9:E15) | F16: =SUM(F9:F15) | G16: =SUM(G9:G15) | H16: =SUM(H9:H15) | I16: =SUM(I9:I15) | J16: =SUM(J9:J15) | K16: =SUM(K9:K15) | ... AM16: =SUM(AM9:AM15)
B18: MONTHLY DEBT SERVICE
B19: MindBody Loan - SM | D19: 0 | E19: 0 | F19: 0 | G19: 0 | H19: 0 | I19: =IF(I9>0,18871.69,0) | J19: =IF(J9>0,18871.69,0) | K19: =IF(K9>0,18871.69,0) | L19: =IF(L9>0,18871.69,0) | M19: =IF(M9>0,18871.69,0) | N19: =IF(N9>0,18871.69,0) | O19: =IF(O9>0,18871.69,0) | P19: =IF(P9>0,18871.69,0) | ... AM19: =IF(AM9>0,18871.69,0)
B20: MindBody Loan - PH | D20: 0 | E20: 0 | F20: 0 | G20: 0 | H20: 0 | I20: =IF(I10>0,16602.04,0) | J20: =IF(J10>0,16602.04,0) | K20: =IF(K10>0,16602.04,0) | L20: =IF(L10>0,16602.04,0) | M20: =IF(M10>0,16602.04,0) | N20: =IF(N10>0,16602.04,0) | O20: =IF(O10>0,16602.04,0) | P20: =IF(P10>0,16602.04,0) | ... AM20: =IF(AM10>0,16602.04,0)
B21: MindBody Loan - LF | D21: 0 | E21: 0 | F21: 0 | G21: 0 | H21: 0 | I21: =IF(I11>0,12162.36,0) | J21: =IF(J11>0,12162.36,0) | K21: =IF(K11>0,12162.36,0) | L21: =IF(L11>0,12162.36,0) | M21: =IF(M11>0,12162.36,0) | N21: =IF(N11>0,12162.36,0) | O21: =IF(O11>0,12162.36,0) | P21: =IF(P11>0,12162.36,0) | ... AM21: =IF(AM11>0,12162.36,0)
B22: MindBody Loan - MR | D22: 0 | E22: 0 | F22: 0 | G22: 0 | H22: 0 | I22: =IF(I12>0,13157.16,0) | J22: =IF(J12>0,13157.16,0) | K22: =IF(K12>0,13157.16,0) | L22: =IF(L12>0,13157.16,0) | M22: =IF(M12>0,13157.16,0) | N22: =IF(N12>0,13157.16,0) | O22: =IF(O12>0,13157.16,0) | P22: =IF(P12>0,13157.16,0) | ... AM22: =IF(AM12>0,13157.16,0)
B23: Samson Loan | D23: 0 | E23: 0 | F23: 0 | G23: 0 | H23: 94517.1 | I23: =IF(I13>0,25460.22,0) | J23: =IF(J13>0,25460.22,0) | K23: =IF(K13>0,25460.22,0) | L23: =IF(L13>0,25460.22,0) | M23: =IF(M13>0,25460.22,0) | N23: =IF(N13>0,25460.22,0) | O23: =IF(O13>0,25460.22,0) | P23: =IF(P13>0,25460.22,0) | ... AM23: =IF(AM13>0,25460.22,0)
B24: Specialty Capital Loan | D24: 0 | E24: 0 | F24: 0 | G24: 0 | H24: 90052.62 | I24: =IF(I14>0,25888.16,0) | J24: =IF(J14>0,25888.16,0) | K24: =IF(K14>0,25888.16,0) | L24: =IF(L14>0,25888.16,0) | M24: =IF(M14>0,25888.16,0) | N24: =IF(N14>0,25888.16,0) | O24: =IF(O14>0,25888.16,0) | P24: =IF(P14>0,25888.16,0) | ... AM24: =IF(AM14>0,25888.16,0)
B25: Norbrook Inc Loan | D25: 0 | E25: 0 | F25: 0 | G25: 0 | H25: 0 | I25: =I15*0.08/12 | J25: =J15*0.08/12 | K25: =K15*0.08/12 | L25: =L15*0.08/12 | M25: =M15*0.08/12 | N25: =N15*0.08/12 | O25: =O15*0.08/12 | P25: =P15*0.08/12 | ... AM25: =AM15*0.08/12
B26: TOTAL DEBT SERVICE | D26: =SUM(D19:D25) | E26: =SUM(E19:E25) | F26: =SUM(F19:F25) | G26: =SUM(G19:G25) | H26: =SUM(H19:H25) | I26: =SUM(I19:I25) | J26: =SUM(J19:J25) | K26: =SUM(K19:K25) | ... AM26: =SUM(AM19:AM25)
B28: OWNER EQUITY / INTERCOMPANY
B29: Intercompany Net Position | D29: 224773.04 | E29: 224773.04 | F29: 358106.37 | G29: 436439.7 | H29: 0 | I29: 0 | J29: 0 | K29: 0 | L29: 0 | M29: 0 | N29: 0 | O29: 0 | P29: 0 | Q29: 0 | R29: 0 | S29: 0 | T29: 0 | U29: 0 | V29: 0 | W29: 0 | X29: 0 | Y29: 0 | Z29: 0 | AA29: 0 | AB29: 0 | AC29: 0 | AD29: 0 | AE29: 0 | AF29: 0 | AG29: 0 | AH29: 0 | AI29: 0 | AJ29: 0 | AK29: 0 | AL29: 0 | AM29: 0

Sheet Cash Flow Forecast
B2: Cash Flow Forecast
B3: Actuals: Jan-Apr 2026 (light green). Forecast: May 2026 onwards. Net Change formulas sum operations + investing + financing.
B4: Monthly Cash Flow
B5: Line Item | C5: Annual Total | D5: Jan 2026 | E5: Feb 2026 | F5: Mar 2026 | G5: Apr 2026 | H5: May 2026 | I5: Jun 2026 | J5: Jul 2026 | K5: Aug 2026 | L5: Sep 2026 | M5: Oct 2026 | N5: Nov 2026 | O5: Dec 2026 | P5: Jan 2027 | Q5: Feb 2027 | R5: Mar 2027 | S5: Apr 2027 | T5: May 2027 | U5: Jun 2027 | V5: Jul 2027 | W5: Aug 2027 | X5: Sep 2027 | Y5: Oct 2027 | Z5: Nov 2027 | AA5: Dec 2027 | AB5: Jan 2028 | AC5: Feb 2028 | AD5: Mar 2028 | AE5: Apr 2028 | AF5: May 2028 | AG5: Jun 2028 | AH5: Jul 2028 | AI5: Aug 2028 | AJ5: Sep 2028 | AK5: Oct 2028 | AL5: Nov 2028 | AM5: Dec 2028
B6: CASH INFLOWS
B7: Total Cash Sales | D7: ='Sales Forecast'!D18 | E7: ='Sales Forecast'!E18 | F7: ='Sales Forecast'!F18 | G7: ='Sales Forecast'!G18 | H7: ='Sales Forecast'!H18 | I7: ='Sales Forecast'!I18 | J7: ='Sales Forecast'!J18 | K7: ='Sales Forecast'!K18 | ... AM7: ='Sales Forecast'!AM18
B9: OPERATING OUTFLOWS
B10: Property Costs | D10: 147113.46 | E10: 146344.65 | F10: 147382.66 | G10: 148059.43 | H10: 147112.25 | I10: 147112.25 | J10: 147112.25 | K10: 147112.25 | L10: 147112.25 | M10: 147112.25 | N10: 147112.25 | O10: 147112.25 | P10: 151525.62 | Q10: 151525.62 | R10: 151525.62 | S10: 151525.62 | T10: 151525.62 | U10: 151525.62 | V10: 151525.62 | W10: 151525.62 | X10: 151525.62 | Y10: 151525.62 | Z10: 151525.62 | AA10: 151525.62 | AB10: 156071.4 | AC10: 156071.4 | AD10: 156071.4 | AE10: 156071.4 | AF10: 156071.4 | AG10: 156071.4 | AH10: 156071.4 | AI10: 156071.4 | AJ10: 156071.4 | AK10: 156071.4 | AL10: 156071.4 | AM10: 156071.4
B11: Staff Costs | D11: 681232.98 | E11: 590412.06 | F11: 628953.81 | G11: 576480.98 | H11: 598615.61 | I11: 598615.61 | J11: 598615.61 | K11: 598615.61 | L11: 598615.61 | M11: 598615.61 | N11: 598615.61 | O11: 598615.61 | P11: 622560.23 | Q11: 622560.23 | R11: 622560.23 | S11: 622560.23 | T11: 622560.23 | U11: 622560.23 | V11: 622560.23 | W11: 622560.23 | X11: 622560.23 | Y11: 622560.23 | Z11: 622560.23 | AA11: 622560.23 | AB11: 647462.64 | AC11: 647462.64 | AD11: 647462.64 | AE11: 647462.64 | AF11: 647462.64 | AG11: 647462.64 | AH11: 647462.64 | AI11: 647462.64 | AJ11: 647462.64 | AK11: 647462.64 | AL11: 647462.64 | AM11: 647462.64
B12: Utilities | D12: 7087.42 | E12: 9973.09 | F12: 7034.72 | G12: 7270.22 | H12: 8720.11 | I12: 8720.11 | J12: 8720.11 | K12: 8720.11 | L12: 8720.11 | M12: 8720.11 | N12: 8720.11 | O12: 8720.11 | P12: 9043.82 | Q12: 9043.82 | R12: 9043.82 | S12: 9043.82 | T12: 9043.82 | U12: 9043.82 | V12: 9043.82 | W12: 9043.82 | X12: 9043.82 | Y12: 9043.82 | Z12: 9043.82 | AA12: 9043.82 | AB12: 9380.48 | AC12: 9380.48 | AD12: 8753.05 | AE12: 8753.05 | AF12: 8753.05 | AG12: 8753.05 | AH12: 8753.05 | AI12: 8753.05 | AJ12: 8753.05 | AK12: 8753.05 | AL12: 8753.05 | AM12: 8753.05
B13: Marketing & Promotion | D13: 27740.18 | E13: 27007.49 | F13: 16681.8 | G13: 5975.58 | H13: 16948.9 | I13: 16948.9 | J13: 16948.9 | K13: 16948.9 | L13: 16948.9 | M13: 16948.9 | N13: 16948.9 | O13: 16948.9 | P13: 17626.86 | Q13: 17626.86 | R13: 17626.86 | S13: 17626.86 | T13: 17626.86 | U13: 17626.86 | V13: 17626.86 | W13: 17626.86 | X13: 17626.86 | Y13: 17626.86 | Z13: 17626.86 | AA13: 17626.86 | AB13: 18331.93 | AC13: 18331.93 | AD13: 18331.93 | AE13: 18331.93 | AF13: 18331.93 | AG13: 18331.93 | AH13: 18331.93 | AI13: 18331.93 | AJ13: 18331.93 | AK13: 18331.93 | AL13: 18331.93 | AM13: 18331.93
B14: Administrative & G&A | D14: 32760.81 | E14: 38409.23 | F14: 33297.16 | G14: 28817.49 | H14: 37431.59 | I14: 37431.59 | J14: 37431.59 | K14: 37431.59 | L14: 37431.59 | M14: 37431.59 | N14: 37431.59 | O14: 37431.59 | P14: 38928.85 | Q14: 38928.85 | R14: 38928.85 | S14: 38928.85 | T14: 38928.85 | U14: 38928.85 | V14: 38928.85 | W14: 38928.85 | X14: 38928.85 | Y14: 38928.85 | Z14: 38928.85 | AA14: 38928.85 | AB14: 40486.01 | AC14: 40486.01 | AD14: 40486.01 | AE14: 40486.01 | AF14: 40486.01 | AG14: 40486.01 | AH14: 40486.01 | AI14: 40486.01 | AJ14: 40486.01 | AK14: 40486.01 | AL14: 40486.01 | AM14: 40486.01
B15: Professional Fees | D15: 42733.79 | E15: 24202.3 | F15: 22556.84 | G15: 25366 | H15: 24041.72 | I15: 24041.72 | J15: 24041.72 | K15: 24041.72 | L15: 24041.72 | M15: 24041.72 | N15: 24041.72 | O15: 24041.72 | P15: 25003.37 | Q15: 25003.37 | R15: 25003.37 | S15: 25003.37 | T15: 25003.37 | U15: 25003.37 | V15: 25003.37 | W15: 25003.37 | X15: 25003.37 | Y15: 25003.37 | Z15: 25003.37 | AA15: 25003.37 | AB15: 26003.5 | AC15: 26003.5 | AD15: 26003.5 | AE15: 26003.5 | AF15: 26003.5 | AG15: 26003.5 | AH15: 26003.5 | AI15: 26003.5 | AJ15: 26003.5 | AK15: 26003.5 | AL15: 26003.5 | AM15: 26003.5
B16: Travel & Meals | D16: 6819.03 | E16: 3543.33 | F16: 6002.36 | G16: 2789.61 | H16: 4111.78 | I16: 4111.78 | J16: 4111.78 | K16: 4111.78 | L16: 4111.78 | M16: 4111.78 | N16: 4111.78 | O16: 4111.78 | P16: 4276.25 | Q16: 4276.25 | R16: 4276.25 | S16: 4276.25 | T16: 4276.25 | U16: 4276.25 | V16: 4276.25 | W16: 4276.25 | X16: 4276.25 | Y16: 4276.25 | Z16: 4276.25 | AA16: 4276.25 | AB16: 4447.31 | AC16: 4447.31 | AD16: 4447.31 | AE16: 4447.31 | AF16: 4447.31 | AG16: 4447.31 | AH16: 4447.31 | AI16: 4447.31 | AJ16: 4447.31 | AK16: 4447.31 | AL16: 4447.31 | AM16: 4447.31
B17: Merchant Fees & COGS | D17: 65117.3 | E17: 67419.26 | F17: 61727.36 | G17: 65364.98 | H17: =H7*(Assumptions!$C$19+Assumptions!$C$20) | I17: =I7*(Assumptions!$C$19+Assumptions!$C$20) | J17: =J7*(Assumptions!$C$19+Assumptions!$C$20) | K17: =K7*(Assumptions!$C$19+Assumptions!$C$20) | L17: =L7*(Assumptions!$C$19+Assumptions!$C$20) | M17: =M7*(Assumptions!$C$19+Assumptions!$C$20) | N17: =N7*(Assumptions!$C$19+Assumptions!$C$20) | O17: =O7*(Assumptions!$C$19+Assumptions!$C$20) | ... AM17: =AM7*(Assumptions!$C$19+Assumptions!$C$20)
B18: Studio Start Up Costs | D18: 0 | E18: 0 | F18: 0 | G18: 0 | H18: 0 | I18: 0 | J18: 0 | K18: 0 | L18: 0 | M18: 0 | N18: 0 | O18: 0 | P18: 0 | Q18: 0 | R18: 0 | S18: 0 | T18: 0 | U18: 0 | V18: 0 | W18: 0 | X18: 0 | Y18: 0 | Z18: 0 | AA18: 0 | AB18: 0 | AC18: 0 | AD18: 0 | AE18: 0 | AF18: 0 | AG18: 0 | AH18: 0 | AI18: 0 | AJ18: 0 | AK18: 0 | AL18: 0 | AM18: 0
B19: Taxes | D19: 3673 | E19: 8816 | F19: 3673 | G19: 3673 | H19: 5387.33 | I19: 5387.33 | J19: 5387.33 | K19: 5387.33 | L19: 5387.33 | M19: 5387.33 | N19: 5387.33 | O19: 5387.33 | P19: 5602.82 | Q19: 5602.82 | R19: 5602.82 | S19: 5602.82 | T19: 5602.82 | U19: 5602.82 | V19: 5602.82 | W19: 5602.82 | X19: 5602.82 | Y19: 5602.82 | Z19: 5602.82 | AA19: 5602.82 | AB19: 5826.93 | AC19: 5826.93 | AD19: 5826.93 | AE19: 5826.93 | AF19: 5826.93 | AG19: 5826.93 | AH19: 5826.93 | AI19: 5826.93 | AJ19: 5826.93 | AK19: 5826.93 | AL19: 5826.93 | AM19: 5826.93
B20: Total Operating Expenses | D20: =SUM(D10:D19) | E20: =SUM(E10:E19) | F20: =SUM(F10:F19) | G20: =SUM(G10:G19) | H20: =SUM(H10:H19) | I20: =SUM(I10:I19) | J20: =SUM(J10:J19) | K20: =SUM(K10:K19) | ... AM20: =SUM(AM10:AM19)
B21: Net Cash from Operations | D21: =D7-D20 | E21: =E7-E20 | F21: =F7-F20 | G21: =G7-G20 | H21: =H7-H20 | I21: =I7-I20 | J21: =J7-J20 | K21: =K7-K20 | ... AM21: =AM7-AM20
B23: INVESTING ACTIVITIES
B24: Equipment & Furniture | D24: 0 | E24: 2497.4 | F24: 0 | G24: 0 | H24: 0 | I24: 0 | J24: 0 | K24: 0 | L24: 0 | M24: 0 | N24: 0 | O24: 0 | P24: 0 | Q24: 0 | R24: 0 | S24: 0 | T24: 0 | U24: 0 | V24: 0 | W24: 0 | X24: 0 | Y24: 0 | Z24: 0 | AA24: 0 | AB24: 0 | AC24: 0 | AD24: 0 | AE24: 0 | AF24: 0 | AG24: 0 | AH24: 0 | AI24: 0 | AJ24: 0 | AK24: 0 | AL24: 0 | AM24: 0
B25: Leasehold Improvements | D25: -17810.67 | E25: -7094.5 | F25: -24075 | G25: -1035.5 | H25: 0 | I25: 0 | J25: -275000 | K25: -160000 | L25: 0 | M25: 0 | N25: 0 | O25: 0 | P25: 0 | Q25: 0 | R25: 0 | S25: 0 | T25: 0 | U25: 0 | V25: 0 | W25: 0 | X25: 0 | Y25: 0 | Z25: 0 | AA25: 0 | AB25: 0 | AC25: 0 | AD25: 0 | AE25: 0 | AF25: 0 | AG25: 0 | AH25: 0 | AI25: 0 | AJ25: 0 | AK25: 0 | AL25: 0 | AM25: 0
B26: Deposits | D26: 0 | E26: 0 | F26: 0 | G26: 0 | H26: 0 | I26: 0 | J26: 0 | K26: 0 | L26: 0 | M26: 0 | N26: 0 | O26: 0 | P26: 0 | Q26: 0 | R26: 0 | S26: 0 | T26: 0 | U26: 0 | V26: 0 | W26: 0 | X26: 0 | Y26: 0 | Z26: 0 | AA26: 0 | AB26: 0 | AC26: 0 | AD26: 0 | AE26: 0 | AF26: 0 | AG26: 0 | AH26: 0 | AI26: 0 | AJ26: 0 | AK26: 0 | AL26: 0 | AM26: 0
B27: Net Investing | D27: =SUM(D24:D26) | E27: =SUM(E24:E26) | F27: =SUM(F24:F26) | G27: =SUM(G24:G26) | H27: =SUM(H24:H26) | I27: =SUM(I24:I26) | J27: =SUM(J24:J26) | K27: =SUM(K24:K26) | ... AM27: =SUM(AM24:AM26)
B29: FINANCING ACTIVITIES
B30: Loan Proceeds | D30: 9059.38 | E30: 9059.38 | F30: 9059.38 | G30: 12507.09 | H30: 0 | I30: 0 | J30: 0 | K30: 0 | L30: 0 | M30: 0 | N30: 0 | O30: 0 | P30: 0 | Q30: 0 | R30: 0 | S30: 0 | T30: 0 | U30: 0 | V30: 0 | W30: 0 | X30: 0 | Y30: 0 | Z30: 0 | AA30: 0 | AB30: 0 | AC30: 0 | AD30: 0 | AE30: 0 | AF30: 0 | AG30: 0 | AH30: 0 | AI30: 0 | AJ30: 0 | AK30: 0 | AL30: 0 | AM30: 0
B31: Loan Repayments | D31: -132128.24 | E31: -122128.76 | F31: -132834.5 | G31: -114793.66 | H31: =-'Cash, Debt & Equity'!H26 | I31: =-'Cash, Debt & Equity'!I26 | J31: =-'Cash, Debt & Equity'!J26 | K31: =-'Cash, Debt & Equity'!K26 | L31: =-'Cash, Debt & Equity'!L26 | M31: =-'Cash, Debt & Equity'!M26 | N31: =-'Cash, Debt & Equity'!N26 | O31: =-'Cash, Debt & Equity'!O26 | ... AM31: =-'Cash, Debt & Equity'!AM26
B32: Intercompany / Owner Contributions | D32: 0 | E32: 0 | F32: 133333.33 | G32: 78333.33 | H32: 0 | I32: 0 | J32: 0 | K32: 0 | L32: 0 | M32: 0 | N32: -100000 | O32: 0 | P32: 0 | Q32: 0 | R32: 0 | S32: 0 | T32: 0 | U32: 0 | V32: 0 | W32: 0 | X32: 0 | Y32: 0 | Z32: 0 | AA32: 0 | AB32: 0 | AC32: 0 | AD32: 0 | AE32: 0 | AF32: 0 | AG32: 0 | AH32: 0 | AI32: 0 | AJ32: 0 | AK32: 0 | AL32: 0 | AM32: 0
B33: Net Financing | D33: =SUM(D30:D32) | E33: =SUM(E30:E32) | F33: =SUM(F30:F32) | G33: =SUM(G30:G32) | H33: =SUM(H30:H32) | I33: =SUM(I30:I32) | J33: =SUM(J30:J32) | K33: =SUM(K30:K32) | ... AM33: =SUM(AM30:AM32)
B35: NET CHANGE IN CASH
B36: Net Change in Cash | D36: =D21+D27+D33 | E36: =E21+E27+E33 | F36: =F21+F27+F33 | G36: =G21+G27+G33 | H36: =H21+H27+H33 | I36: =I21+I27+I33 | J36: =J21+J27+J33 | K36: =K21+K27+K33 | ... AM36: =AM21+AM27+AM33
B37: Beginning Cash Balance | D37: =D38-D36 | E37: =D38 | F37: =E38 | G37: =F38 | H37: =G38 | I37: =H38 | J37: =I38 | K37: =J38 | L37: =K38 | ... AM37: =AL38
B38: Ending Cash Balance | D38: 187021.69 | E38: 261314.24 | F38: 237762.6 | G38: 473976.03 | H38: =H37+H36 | I38: =I37+I36 | J38: =J37+J36 | K38: =K37+K36 | L38: =L37+L36 | M38: =M37+M36 | N38: =N37+N36 | O38: =O37+O36 | ... AM38: =AM37+AM36

Sheet P&L
B2: Profit & Loss (Consolidated)
B3: Actuals Jan-Apr 2026. Forecast May 2026+ uses formulas from Sales Forecast and Assumptions.
B4: Monthly P&L
B5: Line Item | D5: Jan 2026 | E5: Feb 2026 | F5: Mar 2026 | G5: Apr 2026 | H5: May 2026 | I5: Jun 2026 | J5: Jul 2026 | K5: Aug 2026 | L5: Sep 2026 | M5: Oct 2026 | N5: Nov 2026 | O5: Dec 2026 | P5: Jan 2027 | Q5: Feb 2027 | R5: Mar 2027 | S5: Apr 2027 | T5: May 2027 | U5: Jun 2027 | V5: Jul 2027 | W5: Aug 2027 | X5: Sep 2027 | Y5: Oct 2027 | Z5: Nov 2027 | AA5: Dec 2027 | AB5: Jan 2028 | AC5: Feb 2028 | AD5: Mar 2028 | AE5: Apr 2028 | AF5: May 2028 | AG5: Jun 2028 | AH5: Jul 2028 | AI5: Aug 2028 | AJ5: Sep 2028 | AK5: Oct 2028 | AL5: Nov 2028 | AM5: Dec 2028
B6: Session Revenue | D6: 1000204 | E6: 866507.65 | F6: 867748.4 | G6: 790938.82 | H6: 807497.91 | I6: ='Sales Forecast'!I18*Assumptions!$C$12+'Sales Forecast'!H18*Assumptions!$D$12+'Sales Forecast'!G18*Assumptions!$E$12+'Sales Forecast'!F18*Assumptions!$F$12+'Sales Forecast'!E18*Assumptions!$G$12+'Sales Forecast'!D18*Assumptions!$H$12+'Sales Forecast'!I101*Assumptions!$I$12 | J6: ='Sales Forecast'!J18*Assumptions!$C$12+'Sales Forecast'!I18*Assumptions!$D$12+'Sales Forecast'!H18*Assumptions!$E$12+'Sales Forecast'!G18*Assumptions!$F$12+'Sales Forecast'!F18*Assumptions!$G$12+'Sales Forecast'!E18*Assumptions!$H$12+'Sales Forecast'!D18*Assumptions!$I$12 | K6: ='Sales Forecast'!K18*Assumptions!$C$12+'Sales Forecast'!J18*Assumptions!$D$12+'Sales Forecast'!I18*Assumptions!$E$12+'Sales Forecast'!H18*Assumptions!$F$12+'Sales Forecast'!G18*Assumptions!$G$12+'Sales Forecast'!F18*Assumptions!$H$12+'Sales Forecast'!E18*Assumptions!$I$12 | L6: ='Sales Forecast'!L18*Assumptions!$C$12+'Sales Forecast'!K18*Assumptions!$D$12+'Sales Forecast'!J18*Assumptions!$E$12+'Sales Forecast'!I18*Assumptions!$F$12+'Sales Forecast'!H18*Assumptions!$G$12+'Sales Forecast'!G18*Assumptions!$H$12+'Sales Forecast'!F18*Assumptions!$I$12 | M6: ='Sales Forecast'!M18*Assumptions!$C$12+'Sales Forecast'!L18*Assumptions!$D$12+'Sales Forecast'!K18*Assumptions!$E$12+'Sales Forecast'!J18*Assumptions!$F$12+'Sales Forecast'!I18*Assumptions!$G$12+'Sales Forecast'!H18*Assumptions!$H$12+'Sales Forecast'!G18*Assumptions!$I$12 | N6: ='Sales Forecast'!N18*Assumptions!$C$12+'Sales Forecast'!M18*Assumptions!$D$12+'Sales Forecast'!L18*Assumptions!$E$12+'Sales Forecast'!K18*Assumptions!$F$12+'Sales Forecast'!J18*Assumptions!$G$12+'Sales Forecast'!I18*Assumptions!$H$12+'Sales Forecast'!H18*Assumptions!$I$12 | O6: ='Sales Forecast'!O18*Assumptions!$C$12+'Sales Forecast'!N18*Assumptions!$D$12+'Sales Forecast'!M18*Assumptions!$E$12+'Sales Forecast'!L18*Assumptions!$F$12+'Sales Forecast'!K18*Assumptions!$G$12+'Sales Forecast'!J18*Assumptions!$H$12+'Sales Forecast'!I18*Assumptions!$I$12 | P6: ='Sales Forecast'!P18*Assumptions!$C$12+'Sales Forecast'!O18*Assumptions!$D$12+'Sales Forecast'!N18*Assumptions!$E$12+'Sales Forecast'!M18*Assumptions!$F$12+'Sales Forecast'!L18*Assumptions!$G$12+'Sales Forecast'!K18*Assumptions!$H$12+'Sales Forecast'!J18*Assumptions!$I$12 | Q6: ='Sales Forecast'!Q18*Assumptions!$C$12+'Sales Forecast'!P18*Assumptions!$D$12+'Sales Forecast'!O18*Assumptions!$E$12+'Sales Forecast'!N18*Assumptions!$F$12+'Sales Forecast'!M18*Assumptions!$G$12+'Sales Forecast'!L18*Assumptions!$H$12+'Sales Forecast'!K18*Assumptions!$I$12 | ... AM6: ='Sales Forecast'!AM18*Assumptions!$C$12+'Sales Forecast'!AL18*Assumptions!$D$12+'Sales Forecast'!AK18*Assumptions!$E$12+'Sales Forecast'!AJ18*Assumptions!$F$12+'Sales Forecast'!AI18*Assumptions!$G$12+'Sales Forecast'!AH18*Assumptions!$H$12+'Sales Forecast'!AG18*Assumptions!$I$12
B7: Breakage Revenue | D7: 139780.94 | E7: 155452.01 | F7: 132350.01 | G7: 142563.17 | H7: 141174.57 | I7: ='Sales Forecast'!I18*Assumptions!$C$13+'Sales Forecast'!H18*Assumptions!$D$13+'Sales Forecast'!G18*Assumptions!$E$13+'Sales Forecast'!F18*Assumptions!$F$13+'Sales Forecast'!E18*Assumptions!$G$13+'Sales Forecast'!D18*Assumptions!$H$13+'Sales Forecast'!I101*Assumptions!$I$13 | J7: ='Sales Forecast'!J18*Assumptions!$C$13+'Sales Forecast'!I18*Assumptions!$D$13+'Sales Forecast'!H18*Assumptions!$E$13+'Sales Forecast'!G18*Assumptions!$F$13+'Sales Forecast'!F18*Assumptions!$G$13+'Sales Forecast'!E18*Assumptions!$H$13+'Sales Forecast'!D18*Assumptions!$I$13 | K7: ='Sales Forecast'!K18*Assumptions!$C$13+'Sales Forecast'!J18*Assumptions!$D$13+'Sales Forecast'!I18*Assumptions!$E$13+'Sales Forecast'!H18*Assumptions!$F$13+'Sales Forecast'!G18*Assumptions!$G$13+'Sales Forecast'!F18*Assumptions!$H$13+'Sales Forecast'!E18*Assumptions!$I$13 | L7: ='Sales Forecast'!L18*Assumptions!$C$13+'Sales Forecast'!K18*Assumptions!$D$13+'Sales Forecast'!J18*Assumptions!$E$13+'Sales Forecast'!I18*Assumptions!$F$13+'Sales Forecast'!H18*Assumptions!$G$13+'Sales Forecast'!G18*Assumptions!$H$13+'Sales Forecast'!F18*Assumptions!$I$13 | M7: ='Sales Forecast'!M18*Assumptions!$C$13+'Sales Forecast'!L18*Assumptions!$D$13+'Sales Forecast'!K18*Assumptions!$E$13+'Sales Forecast'!J18*Assumptions!$F$13+'Sales Forecast'!I18*Assumptions!$G$13+'Sales Forecast'!H18*Assumptions!$H$13+'Sales Forecast'!G18*Assumptions!$I$13 | N7: ='Sales Forecast'!N18*Assumptions!$C$13+'Sales Forecast'!M18*Assumptions!$D$13+'Sales Forecast'!L18*Assumptions!$E$13+'Sales Forecast'!K18*Assumptions!$F$13+'Sales Forecast'!J18*Assumptions!$G$13+'Sales Forecast'!I18*Assumptions!$H$13+'Sales Forecast'!H18*Assumptions!$I$13 | O7: ='Sales Forecast'!O18*Assumptions!$C$13+'Sales Forecast'!N18*Assumptions!$D$13+'Sales Forecast'!M18*Assumptions!$E$13+'Sales Forecast'!L18*Assumptions!$F$13+'Sales Forecast'!K18*Assumptions!$G$13+'Sales Forecast'!J18*Assumptions!$H$13+'Sales Forecast'!I18*Assumptions!$I$13 | P7: ='Sales Forecast'!P18*Assumptions!$C$13+'Sales Forecast'!O18*Assumptions!$D$13+'Sales Forecast'!N18*Assumptions!$E$13+'Sales Forecast'!M18*Assumptions!$F$13+'Sales Forecast'!L18*Assumptions!$G$13+'Sales Forecast'!K18*Assumptions!$H$13+'Sales Forecast'!J18*Assumptions!$I$13 | Q7: ='Sales Forecast'!Q18*Assumptions!$C$13+'Sales Forecast'!P18*Assumptions!$D$13+'Sales Forecast'!O18*Assumptions!$E$13+'Sales Forecast'!N18*Assumptions!$F$13+'Sales Forecast'!M18*Assumptions!$G$13+'Sales Forecast'!L18*Assumptions!$H$13+'Sales Forecast'!K18*Assumptions!$I$13 | ... AM7: ='Sales Forecast'!AM18*Assumptions!$C$13+'Sales Forecast'!AL18*Assumptions!$D$13+'Sales Forecast'!AK18*Assumptions!$E$13+'Sales Forecast'!AJ18*Assumptions!$F$13+'Sales Forecast'!AI18*Assumptions!$G$13+'Sales Forecast'!AH18*Assumptions!$H$13+'Sales Forecast'!AG18*Assumptions!$I$13
B8: Retail Sales | D8: 23308 | E8: 19847 | F8: 17655 | G8: 18479 | H8: 13825.81 | I8: 16653.27 | J8: 16653.27 | K8: 16653.27 | L8: 16653.27 | M8: 16653.27 | N8: 16653.27 | O8: 16653.27 | P8: 16653.27 | Q8: 16653.27 | R8: 16653.27 | S8: 16653.27 | T8: 16653.27 | U8: 16653.27 | V8: 16653.27 | W8: 16653.27 | X8: 16653.27 | Y8: 16653.27 | Z8: 16653.27 | AA8: 16653.27 | AB8: 16653.27 | AC8: 16653.27 | AD8: 16653.27 | AE8: 16653.27 | AF8: 16653.27 | AG8: 16653.27 | AH8: 16653.27 | AI8: 16653.27 | AJ8: 16653.27 | AK8: 16653.27 | AL8: 16653.27 | AM8: 16653.27
B9: Refunds | D9: -20830.24 | E9: -15645.66 | F9: -16880.65 | G9: -12793.11 | H9: -9390.21 | I9: =(I6+I7)*Assumptions!$C$17 | J9: =(J6+J7)*Assumptions!$C$17 | K9: =(K6+K7)*Assumptions!$C$17 | L9: =(L6+L7)*Assumptions!$C$17 | M9: =(M6+M7)*Assumptions!$C$17 | N9: =(N6+N7)*Assumptions!$C$17 | O9: =(O6+O7)*Assumptions!$C$17 | P9: =(P6+P7)*Assumptions!$C$17 | ... AM9: =(AM6+AM7)*Assumptions!$C$17
B10: Discounts | D10: -59600.85 | E10: -56707.91 | F10: -53962.12 | G10: -51310.18 | H10: -35101.57 | I10: =(I6+I7)*Assumptions!$C$18 | J10: =(J6+J7)*Assumptions!$C$18 | K10: =(K6+K7)*Assumptions!$C$18 | L10: =(L6+L7)*Assumptions!$C$18 | M10: =(M6+M7)*Assumptions!$C$18 | N10: =(N6+N7)*Assumptions!$C$18 | O10: =(O6+O7)*Assumptions!$C$18 | P10: =(P6+P7)*Assumptions!$C$18 | ... AM10: =(AM6+AM7)*Assumptions!$C$18
B11: Total Revenue | D11: 1082861.8 | E11: 969453.09 | F11: 946910.64 | G11: 887877.7 | H11: 918006.51 | I11: =I6+I7+I8+I9+I10 | J11: =J6+J7+J8+J9+J10 | K11: =K6+K7+K8+K9+K10 | L11: =L6+L7+L8+L9+L10 | M11: =M6+M7+M8+M9+M10 | N11: =N6+N7+N8+N9+N10 | O11: =O6+O7+O8+O9+O10 | P11: =P6+P7+P8+P9+P10 | ... AM11: =AM6+AM7+AM8+AM9+AM10
B12: COGS & Merchant Fees | D12: 38009.85 | E12: 38497.03 | F12: 34960.53 | G12: 36936.49 | H12: 27088.66 | I12: =I11*(Assumptions!$C$19+Assumptions!$C$20) | J12: =J11*(Assumptions!$C$19+Assumptions!$C$20) | K12: =K11*(Assumptions!$C$19+Assumptions!$C$20) | L12: =L11*(Assumptions!$C$19+Assumptions!$C$20) | M12: =M11*(Assumptions!$C$19+Assumptions!$C$20) | N12: =N11*(Assumptions!$C$19+Assumptions!$C$20) | O12: =O11*(Assumptions!$C$19+Assumptions!$C$20) | P12: =P11*(Assumptions!$C$19+Assumptions!$C$20) | ... AM12: =AM11*(Assumptions!$C$19+Assumptions!$C$20)
B13: Gross Profit | D13: 1044852 | E13: 930956.06 | F13: 911950.11 | G13: 850941.21 | H13: 890917.85 | I13: =I11-I12 | J13: =J11-J12 | K13: =K11-K12 | L13: =L11-L12 | M13: =M11-M12 | N13: =N11-N12 | O13: =O11-O12 | P13: =P11-P12 | ... AM13: =AM11-AM12
B14: Marketing | D14: 27740.18 | E14: 27007.49 | F14: 16681.8 | G14: 5975.58 | H14: 5982.17 | I14: ='BK P&L'!I33+'CC P&L'!I33+'DN P&L'!I33+'LF P&L'!I33+'MR P&L'!I33+'OP P&L'!I33+'PH P&L'!I33+'RH P&L'!I33+'SB P&L'!I33+'SM P&L'!I33+'WP P&L'!I33+'WW P&L'!I33+'HO P&L'!I12 | J14: ='BK P&L'!J33+'CC P&L'!J33+'DN P&L'!J33+'LF P&L'!J33+'MR P&L'!J33+'OP P&L'!J33+'PH P&L'!J33+'RH P&L'!J33+'SB P&L'!J33+'SM P&L'!J33+'WP P&L'!J33+'WW P&L'!J33+'HO P&L'!J12 | K14: ='BK P&L'!K33+'CC P&L'!K33+'DN P&L'!K33+'LF P&L'!K33+'MR P&L'!K33+'OP P&L'!K33+'PH P&L'!K33+'RH P&L'!K33+'SB P&L'!K33+'SM P&L'!K33+'WP P&L'!K33+'WW P&L'!K33+'HO P&L'!K12 | L14: ='BK P&L'!L33+'CC P&L'!L33+'DN P&L'!L33+'LF P&L'!L33+'MR P&L'!L33+'OP P&L'!L33+'PH P&L'!L33+'RH P&L'!L33+'SB P&L'!L33+'SM P&L'!L33+'WP P&L'!L33+'WW P&L'!L33+'HO P&L'!L12 | M14: ='BK P&L'!M33+'CC P&L'!M33+'DN P&L'!M33+'LF P&L'!M33+'MR P&L'!M33+'OP P&L'!M33+'PH P&L'!M33+'RH P&L'!M33+'SB P&L'!M33+'SM P&L'!M33+'WP P&L'!M33+'WW P&L'!M33+'HO P&L'!M12 | N14: ='BK P&L'!N33+'CC P&L'!N33+'DN P&L'!N33+'LF P&L'!N33+'MR P&L'!N33+'OP P&L'!N33+'PH P&L'!N33+'RH P&L'!N33+'SB P&L'!N33+'SM P&L'!N33+'WP P&L'!N33+'WW P&L'!N33+'HO P&L'!N12 | O14: ='BK P&L'!O33+'CC P&L'!O33+'DN P&L'!O33+'LF P&L'!O33+'MR P&L'!O33+'OP P&L'!O33+'PH P&L'!O33+'RH P&L'!O33+'SB P&L'!O33+'SM P&L'!O33+'WP P&L'!O33+'WW P&L'!O33+'HO P&L'!O12 | P14: ='BK P&L'!P33+'CC P&L'!P33+'DN P&L'!P33+'LF P&L'!P33+'MR P&L'!P33+'OP P&L'!P33+'PH P&L'!P33+'RH P&L'!P33+'SB P&L'!P33+'SM P&L'!P33+'WP P&L'!P33+'WW P&L'!P33+'HO P&L'!P12 | ... AM14: ='BK P&L'!AM33+'CC P&L'!AM33+'DN P&L'!AM33+'LF P&L'!AM33+'MR P&L'!AM33+'OP P&L'!AM33+'PH P&L'!AM33+'RH P&L'!AM33+'SB P&L'!AM33+'SM P&L'!AM33+'WP P&L'!AM33+'WW P&L'!AM33+'HO P&L'!AM12
B15: Payroll | D15: 681232.98 | E15: 590412.06 | F15: 628953.81 | G15: 576480.98 | H15: 589210.62 | I15: ='BK P&L'!I38+'CC P&L'!I38+'DN P&L'!I38+'LF P&L'!I38+'MR P&L'!I38+'OP P&L'!I38+'PH P&L'!I38+'RH P&L'!I38+'SB P&L'!I38+'SM P&L'!I38+'WP P&L'!I38+'WW P&L'!I38+'HO P&L'!I17 | J15: ='BK P&L'!J38+'CC P&L'!J38+'DN P&L'!J38+'LF P&L'!J38+'MR P&L'!J38+'OP P&L'!J38+'PH P&L'!J38+'RH P&L'!J38+'SB P&L'!J38+'SM P&L'!J38+'WP P&L'!J38+'WW P&L'!J38+'HO P&L'!J17 | K15: ='BK P&L'!K38+'CC P&L'!K38+'DN P&L'!K38+'LF P&L'!K38+'MR P&L'!K38+'OP P&L'!K38+'PH P&L'!K38+'RH P&L'!K38+'SB P&L'!K38+'SM P&L'!K38+'WP P&L'!K38+'WW P&L'!K38+'HO P&L'!K17 | L15: ='BK P&L'!L38+'CC P&L'!L38+'DN P&L'!L38+'LF P&L'!L38+'MR P&L'!L38+'OP P&L'!L38+'PH P&L'!L38+'RH P&L'!L38+'SB P&L'!L38+'SM P&L'!L38+'WP P&L'!L38+'WW P&L'!L38+'HO P&L'!L17 | M15: ='BK P&L'!M38+'CC P&L'!M38+'DN P&L'!M38+'LF P&L'!M38+'MR P&L'!M38+'OP P&L'!M38+'PH P&L'!M38+'RH P&L'!M38+'SB P&L'!M38+'SM P&L'!M38+'WP P&L'!M38+'WW P&L'!M38+'HO P&L'!M17 | N15: ='BK P&L'!N38+'CC P&L'!N38+'DN P&L'!N38+'LF P&L'!N38+'MR P&L'!N38+'OP P&L'!N38+'PH P&L'!N38+'RH P&L'!N38+'SB P&L'!N38+'SM P&L'!N38+'WP P&L'!N38+'WW P&L'!N38+'HO P&L'!N17 | O15: ='BK P&L'!O38+'CC P&L'!O38+'DN P&L'!O38+'LF P&L'!O38+'MR P&L'!O38+'OP P&L'!O38+'PH P&L'!O38+'RH P&L'!O38+'SB P&L'!O38+'SM P&L'!O38+'WP P&L'!O38+'WW P&L'!O38+'HO P&L'!O17 | P15: ='BK P&L'!P38+'CC P&L'!P38+'DN P&L'!P38+'LF P&L'!P38+'MR P&L'!P38+'OP P&L'!P38+'PH P&L'!P38+'RH P&L'!P38+'SB P&L'!P38+'SM P&L'!P38+'WP P&L'!P38+'WW P&L'!P38+'HO P&L'!P17 | ... AM15: ='BK P&L'!AM38+'CC P&L'!AM38+'DN P&L'!AM38+'LF P&L'!AM38+'MR P&L'!AM38+'OP P&L'!AM38+'PH P&L'!AM38+'RH P&L'!AM38+'SB P&L'!AM38+'SM P&L'!AM38+'WP P&L'!AM38+'WW P&L'!AM38+'HO P&L'!AM17
B16: Software | D16: 14854.43 | E16: 23709.03 | F16: 10924.01 | G16: 13421.72 | H16: 14118.08 | I16: ='BK P&L'!I42+'CC P&L'!I42+'DN P&L'!I42+'LF P&L'!I42+'MR P&L'!I42+'OP P&L'!I42+'PH P&L'!I42+'RH P&L'!I42+'SB P&L'!I42+'SM P&L'!I42+'WP P&L'!I42+'WW P&L'!I42+'HO P&L'!I22 | J16: ='BK P&L'!J42+'CC P&L'!J42+'DN P&L'!J42+'LF P&L'!J42+'MR P&L'!J42+'OP P&L'!J42+'PH P&L'!J42+'RH P&L'!J42+'SB P&L'!J42+'SM P&L'!J42+'WP P&L'!J42+'WW P&L'!J42+'HO P&L'!J22 | K16: ='BK P&L'!K42+'CC P&L'!K42+'DN P&L'!K42+'LF P&L'!K42+'MR P&L'!K42+'OP P&L'!K42+'PH P&L'!K42+'RH P&L'!K42+'SB P&L'!K42+'SM P&L'!K42+'WP P&L'!K42+'WW P&L'!K42+'HO P&L'!K22 | L16: ='BK P&L'!L42+'CC P&L'!L42+'DN P&L'!L42+'LF P&L'!L42+'MR P&L'!L42+'OP P&L'!L42+'PH P&L'!L42+'RH P&L'!L42+'SB P&L'!L42+'SM P&L'!L42+'WP P&L'!L42+'WW P&L'!L42+'HO P&L'!L22 | M16: ='BK P&L'!M42+'CC P&L'!M42+'DN P&L'!M42+'LF P&L'!M42+'MR P&L'!M42+'OP P&L'!M42+'PH P&L'!M42+'RH P&L'!M42+'SB P&L'!M42+'SM P&L'!M42+'WP P&L'!M42+'WW P&L'!M42+'HO P&L'!M22 | N16: ='BK P&L'!N42+'CC P&L'!N42+'DN P&L'!N42+'LF P&L'!N42+'MR P&L'!N42+'OP P&L'!N42+'PH P&L'!N42+'RH P&L'!N42+'SB P&L'!N42+'SM P&L'!N42+'WP P&L'!N42+'WW P&L'!N42+'HO P&L'!N22 | O16: ='BK P&L'!O42+'CC P&L'!O42+'DN P&L'!O42+'LF P&L'!O42+'MR P&L'!O42+'OP P&L'!O42+'PH P&L'!O42+'RH P&L'!O42+'SB P&L'!O42+'SM P&L'!O42+'WP P&L'!O42+'WW P&L'!O42+'HO P&L'!O22 | P16: ='BK P&L'!P42+'CC P&L'!P42+'DN P&L'!P42+'LF P&L'!P42+'MR P&L'!P42+'OP P&L'!P42+'PH P&L'!P42+'RH P&L'!P42+'SB P&L'!P42+'SM P&L'!P42+'WP P&L'!P42+'WW P&L'!P42+'HO P&L'!P22 | ... AM16: ='BK P&L'!AM42+'CC P&L'!AM42+'DN P&L'!AM42+'LF P&L'!AM42+'MR P&L'!AM42+'OP P&L'!AM42+'PH P&L'!AM42+'RH P&L'!AM42+'SB P&L'!AM42+'SM P&L'!AM42+'WP P&L'!AM42+'WW P&L'!AM42+'HO P&L'!AM22
B17: Professional Fees | D17: 42733.79 | E17: 24202.3 | F17: 22556.84 | G17: 25366 | H17: 30273 | I17: ='BK P&L'!I47+'CC P&L'!I47+'DN P&L'!I47+'LF P&L'!I47+'MR P&L'!I47+'OP P&L'!I47+'PH P&L'!I47+'RH P&L'!I47+'SB P&L'!I47+'SM P&L'!I47+'WP P&L'!I47+'WW P&L'!I47+'HO P&L'!I27 | J17: ='BK P&L'!J47+'CC P&L'!J47+'DN P&L'!J47+'LF P&L'!J47+'MR P&L'!J47+'OP P&L'!J47+'PH P&L'!J47+'RH P&L'!J47+'SB P&L'!J47+'SM P&L'!J47+'WP P&L'!J47+'WW P&L'!J47+'HO P&L'!J27 | K17: ='BK P&L'!K47+'CC P&L'!K47+'DN P&L'!K47+'LF P&L'!K47+'MR P&L'!K47+'OP P&L'!K47+'PH P&L'!K47+'RH P&L'!K47+'SB P&L'!K47+'SM P&L'!K47+'WP P&L'!K47+'WW P&L'!K47+'HO P&L'!K27 | L17: ='BK P&L'!L47+'CC P&L'!L47+'DN P&L'!L47+'LF P&L'!L47+'MR P&L'!L47+'OP P&L'!L47+'PH P&L'!L47+'RH P&L'!L47+'SB P&L'!L47+'SM P&L'!L47+'WP P&L'!L47+'WW P&L'!L47+'HO P&L'!L27 | M17: ='BK P&L'!M47+'CC P&L'!M47+'DN P&L'!M47+'LF P&L'!M47+'MR P&L'!M47+'OP P&L'!M47+'PH P&L'!M47+'RH P&L'!M47+'SB P&L'!M47+'SM P&L'!M47+'WP P&L'!M47+'WW P&L'!M47+'HO P&L'!M27 | N17: ='BK P&L'!N47+'CC P&L'!N47+'DN P&L'!N47+'LF P&L'!N47+'MR P&L'!N47+'OP P&L'!N47+'PH P&L'!N47+'RH P&L'!N47+'SB P&L'!N47+'SM P&L'!N47+'WP P&L'!N47+'WW P&L'!N47+'HO P&L'!N27 | O17: ='BK P&L'!O47+'CC P&L'!O47+'DN P&L'!O47+'LF P&L'!O47+'MR P&L'!O47+'OP P&L'!O47+'PH P&L'!O47+'RH P&L'!O47+'SB P&L'!O47+'SM P&L'!O47+'WP P&L'!O47+'WW P&L'!O47+'HO P&L'!O27 | P17: ='BK P&L'!P47+'CC P&L'!P47+'DN P&L'!P47+'LF P&L'!P47+'MR P&L'!P47+'OP P&L'!P47+'PH P&L'!P47+'RH P&L'!P47+'SB P&L'!P47+'SM P&L'!P47+'WP P&L'!P47+'WW P&L'!P47+'HO P&L'!P27 | ... AM17: ='BK P&L'!AM47+'CC P&L'!AM47+'DN P&L'!AM47+'LF P&L'!AM47+'MR P&L'!AM47+'OP P&L'!AM47+'PH P&L'!AM47+'RH P&L'!AM47+'SB P&L'!AM47+'SM P&L'!AM47+'WP P&L'!AM47+'WW P&L'!AM47+'HO P&L'!AM27
