Workbook

Sheet Cover
B2: Mighty Pilates
B3: Financial Model
B5: Last refreshed: June 23, 2026
B7: Tab Guide
B9: Summary & Controls | C9: Top-level KPIs, studio sales & EBITDA tables, charts
B10: Assumptions | C10: All model inputs: OpEx, sales forecast, rev rec curves, loan terms
B11: Cash Flow Forecast | C11: Monthly cash flow from operations + investing + financing
B12: P&L Summary | C12: Consolidated monthly P&L (Revenue → EBITDA)
B13: P&L Detail | C13: Account-level P&L matching accountant chart of accounts
B14: All Studios Summary | C14: Side-by-side studio comparison
B15: [Studio] FCST (×12) | C15: Per-studio P&L forecast (BK, CC, DN, LF, MR, OP, PH, RH, SB, SM, WP, WW)
B16: Cash, Debt & Equity | C16: Balance sheet, loan amortization schedules, equity tracking
B17: Sales Forecast | C17: Studio × month editable sales grid
B18: CapEx | C18: Capital expenditure project schedule
B19: QBO Actuals | C19: Historical accountant-booked P&L, BS, SCF (read-only)
B22: Conventions
B24: Yellow cells = inputs (edit these)
B25: Light green cells = actuals (closed months, do not edit)

Sheet Read Me
B2: Read Me — Model Architecture
B3: Last refreshed: June 23, 2026
B5: Tab Roles
B6: Summary & Controls | C6: Top-level dashboard. Sales + EBITDA by studio. Total EBITDA references P&L NOI directly.
B7: Assumptions | C7: Editable global parameters: rev rec curves, refund/discount/COGS rates, escalations, loan terms.
B8: Sales Forecast | C8: Per-studio × month sales grid. EDITABLE for forecast months (yellow). Drives revenue formulas. Hidden rows 101-113 hold 2025 history for lag formulas — do not delete.
B9: Cash, Debt & Equity | C9: Loan amortization schedule + debt service forecast.
B10: Cash Flow Forecast | C10: Monthly CF with operating/investing/financing.
B11: P&L (Consolidated) | C11: Consolidated monthly P&L. Revenue/COGS use direct lag formulas (with 2025 history). OpEx rows = SUM(per-studio) + HO + HO Other.
B12: All Studios Summary | C12: Side-by-side studio comparison.
B13: [Code] P&L (×12) | C13: Per-studio P&L: BK, CC, DN, LF, MR, OP, PH, RH, SB, SM, WP, WW. OpEx leaves are HARDCODED values (editable) summing to per-studio override. Revenue formulas use per-studio lag (2026+ from Sales Forecast, 2025 from hidden helper rows 102-113).
B14: HO P&L | C14: Head Office overhead (no revenue). Same leaf-summing structure. NOI is negative (= -Total OpEx).
B15: CapEx | C15: Project schedule (empty — add projects to populate Investing rows on CF).
B16: QBO Actuals | C16: Raw accountant-booked P&L/BS/SCF data. Read-only reference.
B18: Cell Conventions
B19: Yellow fill (FFFF99) | C19: EDITABLE input cell. Cat can change these.
B20: Light green fill | C20: Hardcoded actual from QBO/accountant. Do not edit (would diverge from source data).
B21: White/no fill | C21: Formula cell. Computed from other cells.
B22: Light blue fill | C22: Subtotal or total row.
B23: Bold green fill | C23: Key KPI (EBITDA, ending cash).
B25: Value Flow
B26: Sales edit | C26: Edit Sales Forecast cell → flows to: Studio P&L Sessions/Breakage (via lag formula) → Studio NOI → Summary & Controls studio row → Sales Forecast TOTAL row → Consolidated P&L revenue → Consolidated NOI → Summary & Controls Total EBITDA.
B27: OpEx leaf edit | C27: Edit per-studio OpEx leaf (e.g., BK Paid Ads) → Studio Marketing subtotal (=SUM leaves) → Studio Total OpEx → Studio NOI → Summary & Controls studio row → Consolidated P&L Marketing (=SUM studios + HO) → Consolidated Total OpEx → Consolidated NOI → Summary & Controls Total EBITDA. Full propagation works.
B28: Assumption edit | C28: Edit rate on Assumptions tab (refund %, discount %, escalation, etc.) → flows through all formulas referencing that cell.
B30: Hidden Helpers — DO NOT DELETE
B31: Sales Forecast rows 100-113 | C31: Hidden helper rows holding 2025 monthly sales (consolidated row 101 and per-studio rows 102-113). Required for 7-month lag formulas on Session/Breakage Revenue forecasts for May 2026 and Jun 2026.
B32: Sales Forecast row ~50+ | C32: Helper for chart data references on Summary & Controls. Removing breaks charts.
B34: Monthly Update Procedure (when QBO closes new month)
B35: Step 1 | C35: Upload new QBO export to Streamlit dashboard. Streamlit's committed_actuals.json gets updated.
B36: Step 2 | C36: Run refresh_from_streamlit.py (in /Users/chandlerclemons/financial-modeling/models/mighty/).
B37: Step 3 | C37: Refresh script will: (a) extend actuals columns by 1 month, (b) shift forecast forward, (c) refresh trailing-3-month avg lines (Taxes Paid, Property Taxes, Retail, Depreciation), (d) update 2025 helper row values if Streamlit data changed historicals.
B38: Step 4 | C38: Open the Excel and spot-check the new actuals column vs Streamlit. Save & share with stakeholders.
B40: Streamlit Source Repo
B41: GitHub | C41: github.com/c-clemons/mighty-pilates (private)
B42: Live app | C42: mighty-pilates-financial-model.streamlit.app
B43: Local files | C43: /Users/chandlerclemons/mighty-pilates/dashboard/data/

Sheet Summary
B2: Summary & Controls
B3: Top-level dashboard. Studio sales, EBITDA, YoY summary, charts.
B4: Monthly Total Session Sales by Studio
B5: Metric | C5: Studio | D5: Jan 2025 (A) | E5: Feb 2025 (A) | F5: Mar 2025 (A) | G5: Apr 2025 (A) | H5: May 2025 (A) | I5: Jun 2025 (A) | J5: Jul 2025 (A) | K5: Aug 2025 (A) | L5: Sep 2025 (A) | M5: Oct 2025 (A) | N5: Nov 2025 (A) | O5: Dec 2025 (A) | P5: Jan 2026 (A) | Q5: Feb 2026 (A) | R5: Mar 2026 (A) | S5: Apr 2026 (A) | T5: May 2026 (A) | U5: Jun 2026 | V5: Jul 2026 | W5: Aug 2026 | X5: Sep 2026 | Y5: Oct 2026 | Z5: Nov 2026 | AA5: Dec 2026 | AB5: Jan 2027 | AC5: Feb 2027 | AD5: Mar 2027 | AE5: Apr 2027 | AF5: May 2027 | AG5: Jun 2027 | AH5: Jul 2027 | AI5: Aug 2027 | AJ5: Sep 2027 | AK5: Oct 2027 | AL5: Nov 2027 | AM5: Dec 2027 | AN5: Jan 2028 | AO5: Feb 2028 | AP5: Mar 2028 | AQ5: Apr 2028 | AR5: May 2028 | AS5: Jun 2028 | AT5: Jul 2028 | AU5: Aug 2028 | AV5: Sep 2028 | AW5: Oct 2028 | AX5: Nov 2028 | AY5: Dec 2028
B6: Total Sales | P6: =SUM(P7:P19) | Q6: =SUM(Q7:Q19) | R6: =SUM(R7:R19) | S6: =SUM(S7:S19) | T6: =SUM(T7:T19) | U6: =SUM(U7:U19) | V6: =SUM(V7:V19) | W6: =SUM(W7:W19) | ... AY6: =SUM(AY7:AY19)
C7: Berkeley | P7: ='Sales Forecast'!P6 | Q7: ='Sales Forecast'!Q6 | R7: ='Sales Forecast'!R6 | S7: ='Sales Forecast'!S6 | T7: ='Sales Forecast'!T6 | U7: ='Sales Forecast'!U6 | V7: ='Sales Forecast'!V6 | W7: ='Sales Forecast'!W6 | ... AY7: ='Sales Forecast'!AY6
C8: Culver City | P8: ='Sales Forecast'!P7 | Q8: ='Sales Forecast'!Q7 | R8: ='Sales Forecast'!R7 | S8: ='Sales Forecast'!S7 | T8: ='Sales Forecast'!T7 | U8: ='Sales Forecast'!U7 | V8: ='Sales Forecast'!V7 | W8: ='Sales Forecast'!W7 | ... AY8: ='Sales Forecast'!AY7
C9: Danville | P9: ='Sales Forecast'!P8 | Q9: ='Sales Forecast'!Q8 | R9: ='Sales Forecast'!R8 | S9: ='Sales Forecast'!S8 | T9: ='Sales Forecast'!T8 | U9: ='Sales Forecast'!U8 | V9: ='Sales Forecast'!V8 | W9: ='Sales Forecast'!W8 | ... AY9: ='Sales Forecast'!AY8
C10: Lafayette | P10: ='Sales Forecast'!P9 | Q10: ='Sales Forecast'!Q9 | R10: ='Sales Forecast'!R9 | S10: ='Sales Forecast'!S9 | T10: ='Sales Forecast'!T9 | U10: ='Sales Forecast'!U9 | V10: ='Sales Forecast'!V9 | W10: ='Sales Forecast'!W9 | ... AY10: ='Sales Forecast'!AY9
C11: Marin | P11: ='Sales Forecast'!P10 | Q11: ='Sales Forecast'!Q10 | R11: ='Sales Forecast'!R10 | S11: ='Sales Forecast'!S10 | T11: ='Sales Forecast'!T10 | U11: ='Sales Forecast'!U10 | V11: ='Sales Forecast'!V10 | W11: ='Sales Forecast'!W10 | ... AY11: ='Sales Forecast'!AY10
C12: Ocean Park | P12: ='Sales Forecast'!P11 | Q12: ='Sales Forecast'!Q11 | R12: ='Sales Forecast'!R11 | S12: ='Sales Forecast'!S11 | T12: ='Sales Forecast'!T11 | U12: ='Sales Forecast'!U11 | V12: ='Sales Forecast'!V11 | W12: ='Sales Forecast'!W11 | ... AY12: ='Sales Forecast'!AY11
C13: Presidio Heights | P13: ='Sales Forecast'!P12 | Q13: ='Sales Forecast'!Q12 | R13: ='Sales Forecast'!R12 | S13: ='Sales Forecast'!S12 | T13: ='Sales Forecast'!T12 | U13: ='Sales Forecast'!U12 | V13: ='Sales Forecast'!V12 | W13: ='Sales Forecast'!W12 | ... AY13: ='Sales Forecast'!AY12
C14: Russian Hill | P14: ='Sales Forecast'!P13 | Q14: ='Sales Forecast'!Q13 | R14: ='Sales Forecast'!R13 | S14: ='Sales Forecast'!S13 | T14: ='Sales Forecast'!T13 | U14: ='Sales Forecast'!U13 | V14: ='Sales Forecast'!V13 | W14: ='Sales Forecast'!W13 | ... AY14: ='Sales Forecast'!AY13
C15: Santa Barbara | P15: ='Sales Forecast'!P14 | Q15: ='Sales Forecast'!Q14 | R15: ='Sales Forecast'!R14 | S15: ='Sales Forecast'!S14 | T15: ='Sales Forecast'!T14 | U15: ='Sales Forecast'!U14 | V15: ='Sales Forecast'!V14 | W15: ='Sales Forecast'!W14 | ... AY15: ='Sales Forecast'!AY14
C16: Santa Monica | P16: ='Sales Forecast'!P15 | Q16: ='Sales Forecast'!Q15 | R16: ='Sales Forecast'!R15 | S16: ='Sales Forecast'!S15 | T16: ='Sales Forecast'!T15 | U16: ='Sales Forecast'!U15 | V16: ='Sales Forecast'!V15 | W16: ='Sales Forecast'!W15 | ... AY16: ='Sales Forecast'!AY15
C17: West Portal | P17: ='Sales Forecast'!P16 | Q17: ='Sales Forecast'!Q16 | R17: ='Sales Forecast'!R16 | S17: ='Sales Forecast'!S16 | T17: ='Sales Forecast'!T16 | U17: ='Sales Forecast'!U16 | V17: ='Sales Forecast'!V16 | W17: ='Sales Forecast'!W16 | ... AY17: ='Sales Forecast'!AY16
C18: Westwood | P18: ='Sales Forecast'!P17 | Q18: ='Sales Forecast'!Q17 | R18: ='Sales Forecast'!R17 | S18: ='Sales Forecast'!S17 | T18: ='Sales Forecast'!T17 | U18: ='Sales Forecast'!U17 | V18: ='Sales Forecast'!V17 | W18: ='Sales Forecast'!W17 | ... AY18: ='Sales Forecast'!AY17
C19: Head Office | P19: 0 | Q19: 0 | R19: 0 | S19: 0 | T19: 0 | U19: 0 | V19: 0 | W19: 0 | X19: 0 | Y19: 0 | Z19: 0 | AA19: 0 | AB19: 0 | AC19: 0 | AD19: 0 | AE19: 0 | AF19: 0 | AG19: 0 | AH19: 0 | AI19: 0 | AJ19: 0 | AK19: 0 | AL19: 0 | AM19: 0 | AN19: 0 | AO19: 0 | AP19: 0 | AQ19: 0 | AR19: 0 | AS19: 0 | AT19: 0 | AU19: 0 | AV19: 0 | AW19: 0 | AX19: 0 | AY19: 0
B21: Monthly EBITDA by Studio
B22: Total EBITDA | P22: =SUM(P23:P35) | Q22: =SUM(Q23:Q35) | R22: =SUM(R23:R35) | S22: =SUM(S23:S35) | T22: =SUM(T23:T35) | U22: =SUM(U23:U35) | V22: =SUM(V23:V35) | W22: =SUM(W23:W35) | ... AY22: =SUM(AY23:AY35)
C23: Berkeley | P23: ='BK P&L'!P63 | Q23: ='BK P&L'!Q63 | R23: ='BK P&L'!R63 | S23: ='BK P&L'!S63 | T23: ='BK P&L'!T63 | U23: ='BK P&L'!U63 | V23: ='BK P&L'!V63 | W23: ='BK P&L'!W63 | ... AY23: ='BK P&L'!AY63
C24: Culver City | P24: ='CC P&L'!P63 | Q24: ='CC P&L'!Q63 | R24: ='CC P&L'!R63 | S24: ='CC P&L'!S63 | T24: ='CC P&L'!T63 | U24: ='CC P&L'!U63 | V24: ='CC P&L'!V63 | W24: ='CC P&L'!W63 | ... AY24: ='CC P&L'!AY63
C25: Danville | P25: ='DN P&L'!P63 | Q25: ='DN P&L'!Q63 | R25: ='DN P&L'!R63 | S25: ='DN P&L'!S63 | T25: ='DN P&L'!T63 | U25: ='DN P&L'!U63 | V25: ='DN P&L'!V63 | W25: ='DN P&L'!W63 | ... AY25: ='DN P&L'!AY63
C26: Lafayette | P26: ='LF P&L'!P63 | Q26: ='LF P&L'!Q63 | R26: ='LF P&L'!R63 | S26: ='LF P&L'!S63 | T26: ='LF P&L'!T63 | U26: ='LF P&L'!U63 | V26: ='LF P&L'!V63 | W26: ='LF P&L'!W63 | ... AY26: ='LF P&L'!AY63
C27: Marin | P27: ='MR P&L'!P63 | Q27: ='MR P&L'!Q63 | R27: ='MR P&L'!R63 | S27: ='MR P&L'!S63 | T27: ='MR P&L'!T63 | U27: ='MR P&L'!U63 | V27: ='MR P&L'!V63 | W27: ='MR P&L'!W63 | ... AY27: ='MR P&L'!AY63
C28: Ocean Park | P28: ='OP P&L'!P63 | Q28: ='OP P&L'!Q63 | R28: ='OP P&L'!R63 | S28: ='OP P&L'!S63 | T28: ='OP P&L'!T63 | U28: ='OP P&L'!U63 | V28: ='OP P&L'!V63 | W28: ='OP P&L'!W63 | ... AY28: ='OP P&L'!AY63
C29: Presidio Heights | P29: ='PH P&L'!P63 | Q29: ='PH P&L'!Q63 | R29: ='PH P&L'!R63 | S29: ='PH P&L'!S63 | T29: ='PH P&L'!T63 | U29: ='PH P&L'!U63 | V29: ='PH P&L'!V63 | W29: ='PH P&L'!W63 | ... AY29: ='PH P&L'!AY63
C30: Russian Hill | P30: ='RH P&L'!P63 | Q30: ='RH P&L'!Q63 | R30: ='RH P&L'!R63 | S30: ='RH P&L'!S63 | T30: ='RH P&L'!T63 | U30: ='RH P&L'!U63 | V30: ='RH P&L'!V63 | W30: ='RH P&L'!W63 | ... AY30: ='RH P&L'!AY63
C31: Santa Barbara | P31: ='SB P&L'!P63 | Q31: ='SB P&L'!Q63 | R31: ='SB P&L'!R63 | S31: ='SB P&L'!S63 | T31: ='SB P&L'!T63 | U31: ='SB P&L'!U63 | V31: ='SB P&L'!V63 | W31: ='SB P&L'!W63 | ... AY31: ='SB P&L'!AY63
C32: Santa Monica | P32: ='SM P&L'!P63 | Q32: ='SM P&L'!Q63 | R32: ='SM P&L'!R63 | S32: ='SM P&L'!S63 | T32: ='SM P&L'!T63 | U32: ='SM P&L'!U63 | V32: ='SM P&L'!V63 | W32: ='SM P&L'!W63 | ... AY32: ='SM P&L'!AY63
C33: West Portal | P33: ='WP P&L'!P63 | Q33: ='WP P&L'!Q63 | R33: ='WP P&L'!R63 | S33: ='WP P&L'!S63 | T33: ='WP P&L'!T63 | U33: ='WP P&L'!U63 | V33: ='WP P&L'!V63 | W33: ='WP P&L'!W63 | ... AY33: ='WP P&L'!AY63
C34: Westwood | P34: ='WW P&L'!P63 | Q34: ='WW P&L'!Q63 | R34: ='WW P&L'!R63 | S34: ='WW P&L'!S63 | T34: ='WW P&L'!T63 | U34: ='WW P&L'!U63 | V34: ='WW P&L'!V63 | W34: ='WW P&L'!W63 | ... AY34: ='WW P&L'!AY63
C35: Head Office | P35: ='HO P&L'!P36 | Q35: ='HO P&L'!Q36 | R35: ='HO P&L'!R36 | S35: ='HO P&L'!S36 | T35: ='HO P&L'!T36 | U35: ='HO P&L'!U36 | V35: ='HO P&L'!V36 | W35: ='HO P&L'!W36 | ... AY35: ='HO P&L'!AY36
B37: Total Add Backs | P37: ='P&L'!P38 | Q37: ='P&L'!Q38 | R37: ='P&L'!R38 | S37: ='P&L'!S38 | T37: 16815.41 | U37: ='P&L'!U38 | V37: ='P&L'!V38 | W37: ='P&L'!W38 | X37: ='P&L'!X38 | Y37: ='P&L'!Y38 | Z37: ='P&L'!Z38 | AA37: ='P&L'!AA38 | AB37: ='P&L'!AB38 | ... AY37: ='P&L'!AY38
B38: Total Adj-EBITDA | P38: ='P&L'!P39 | Q38: ='P&L'!Q39 | R38: ='P&L'!R39 | S38: ='P&L'!S39 | T38: ='P&L'!T39 | U38: ='P&L'!U39 | V38: ='P&L'!V39 | W38: ='P&L'!W39 | ... AY38: ='P&L'!AY39
B40: Annual Summary
B41: Metric | C41: Studio | P41: 2026 | Q41: 2027 | R41: 2028 | S41: 2027 YoY | T41: 2028 YoY
B42: Total Sales | P42: =SUM(P43:P55) | Q42: =SUM(Q43:Q55) | R42: =SUM(R43:R55) | S42: =IFERROR((Q42-P42)/P42,0) | T42: =IFERROR((R42-Q42)/Q42,0)
C43: Berkeley | P43: =SUM('Sales Forecast'!P6:AA6) | Q43: =SUM('Sales Forecast'!AB6:AM6) | R43: =SUM('Sales Forecast'!AN6:AY6) | S43: =IFERROR((Q41-P41)/P41,0) | T43: =IFERROR((R41-Q41)/Q41,0)
C44: Culver City | P44: =SUM('Sales Forecast'!P7:AA7) | Q44: =SUM('Sales Forecast'!AB7:AM7) | R44: =SUM('Sales Forecast'!AN7:AY7) | S44: =IFERROR((Q42-P42)/P42,0) | T44: =IFERROR((R42-Q42)/Q42,0)
...

Sheet Assumptions
B2: Assumptions
B3: Yellow cells are editable inputs. All other tabs reference these values.
B5: 1. Model Control
B6: Last Actuals Month | C6: May 2026
B7: Forecast Horizon (months) | C7: 32
B8: Forecast End Month | C8: Dec 2028
B10: 2. Revenue Recognition Curves
B11: Lag Month (0 = sale month) | C11: 0 | D11: 1 | E11: 2 | F11: 3 | G11: 4 | H11: 5 | I11: 6 | J11: Sum
B12: Earned % | C12: 0.3868 | D12: 0.2997 | E12: 0.0855 | F12: 0.0482 | G12: 0.0261 | H12: 0.0193 | I12: 0.0144 | J12: =SUM(C12:I12)
B13: Breakage % | C13: 0.0017 | D13: 0.0602 | E13: 0.0053 | F13: 0.0003 | G13: 0.0001 | H13: 0.0008 | I13: 0.0516 | J13: =SUM(C13:I13)
B14: Total (Earned + Breakage) | C14: =C12+C13 | D14: =D12+D13 | E14: =E12+E13 | F14: =F12+F13 | G14: =G12+G13 | H14: =H12+H13 | I14: =I12+I13 | J14: =SUM(C14:I14)
B16: 3. Rates (% of Gross Revenue)
B17: Refund Rate | C17: -0.0158 | D17: Refunds as % of gross revenue. Negative reduces net revenue.
B18: Discount Rate | C18: -0.0531 | D18: Discounts as % of gross revenue. Negative reduces net revenue.
B19: Merchant Fee % | C19: 0.0286 | D19: Payment processor fees as % of revenue.
B20: COGS % | C20: 0.0096 | D20: Cost of goods sold as % of revenue (retail).
B22: 4. Annual Escalation Rates
B23: Rent / Property Escalation | C23: 0.03 | D23: 3% annual rent step-up applied to forecast months
B24: Other OpEx Escalation | C24: 0.04 | D24: 4% annual escalation for all non-rent OpEx categories
B25: Sales YoY Growth | C25: 0.05 | D25: 5% YoY assumed for 2028 (applied to 2027 seasonal pattern)
B27: 5. Loan Terms (as of Apr 2026)
B28: Loan | C28: Original Amt | D28: Current Balance | E28: Rate (Annual) | F28: Avg Monthly Pmt | G28: Start Date | H28: Type
B29: MindBody Loan - SM | C29: 193706.66 | D29: 99348.21 | E29: 0 | F29: 18871.69 | G29: 2025-09 | H29: Amortizing
B30: MindBody Loan - PH | C30: 130000 | D30: 46989.79 | E30: 0 | F30: 16602.04 | G30: 2025-09 | H30: Amortizing
B31: MindBody Loan - LF | C31: 69249.28 | D31: 20599.85 | E31: 0 | F31: 12162.36 | G31: 2025-10 | H31: Amortizing
B32: MindBody Loan - MR | C32: 67443.81 | D32: 14815.18 | E32: 0 | F32: 13157.16 | G32: 2025-10 | H32: Amortizing
B33: Samson Loan | C33: 265414.78 | D33: 189034.12 | E33: 0 | F33: 25460.22 | G33: 2025-11 | H33: Amortizing
B34: Specialty Capital Loan | C34: 217184.21 | D34: 165407.89 | E34: 0 | F34: 25888.16 | G34: 2025-12 | H34: Amortizing
B35: Norbrook Inc Loan | C35: 162318 | D35: 162318 | E35: 0.08 | F35: 0 | G35: 2025-10 | H35: Interest-Only
B36: TOTAL DEBT | D36: =SUM(D29:D35) | F36: =SUM(F29:F35)
B38: 6. Active Studios
B39: Code | C39: Name
B40: BK | C40: Berkeley
B41: CC | C41: Culver City
B42: DN | C42: Danville
B43: LF | C43: Lafayette
B44: MR | C44: Marin
B45: OP | C45: Ocean Park
B46: PH | C46: Presidio Heights
B47: RH | C47: Russian Hill
...

Sheet Sales Forecast
B2: Sales Forecast (Gross)
B3: Jan-May 2026 actuals (locked, Cat-authoritative). Jun 2026 onwards forecast (editable).
B4: Per-Studio Monthly Sales
B5: Code | C5: Studio | D5: Jan 2025 | E5: Feb 2025 | F5: Mar 2025 | G5: Apr 2025 | H5: May 2025 | I5: Jun 2025 | J5: Jul 2025 | K5: Aug 2025 | L5: Sep 2025 | M5: Oct 2025 | N5: Nov 2025 | O5: Dec 2025 | P5: Jan 2026 | Q5: Feb 2026 | R5: Mar 2026 | S5: Apr 2026 | T5: 46143 | U5: Jun 2026 | V5: Jul 2026 | W5: Aug 2026 | X5: Sep 2026 | Y5: Oct 2026 | Z5: Nov 2026 | AA5: Dec 2026 | AB5: Jan 2027 | AC5: Feb 2027 | AD5: Mar 2027 | AE5: Apr 2027 | AF5: May 2027 | AG5: Jun 2027 | AH5: Jul 2027 | AI5: Aug 2027 | AJ5: Sep 2027 | AK5: Oct 2027 | AL5: Nov 2027 | AM5: Dec 2027 | AN5: Jan 2028 | AO5: Feb 2028 | AP5: Mar 2028 | AQ5: Apr 2028 | AR5: May 2028 | AS5: Jun 2028 | AT5: Jul 2028 | AU5: Aug 2028 | AV5: Sep 2028 | AW5: Oct 2028 | AX5: Nov 2028 | AY5: Dec 2028
B6: BK | C6: Berkeley | D6: 102263.72 | E6: 108290.08 | F6: 118514.77 | G6: 113589.27 | H6: 119796.34 | I6: 114548.96 | J6: 115924.45 | K6: 121824.66 | L6: 127769.46 | M6: 112372.51 | N6: 125447.68 | O6: 122215.2 | P6: 124393 | Q6: 129377 | R6: 103159 | S6: 136117 | T6: 83273 | U6: 110000 | V6: 105000 | W6: 120000 | X6: 120000 | Y6: 130000 | Z6: 130000 | AA6: 149000 | AB6: 130612.65 | AC6: 135845.85 | AD6: 108316.95 | AE6: 142922.85 | AF6: 87649.8 | AG6: 115500 | AH6: 110250 | AI6: 126000 | AJ6: 126000 | AK6: 136500 | AL6: 136500 | AM6: 156450 | AN6: 137143.28 | AO6: 142638.14 | AP6: 113732.8 | AQ6: 150068.99 | AR6: 92032.29 | AS6: 121275 | AT6: 115762.5 | AU6: 132300 | AV6: 132300 | AW6: 143325 | AX6: 143325 | AY6: 164272.5
B7: CC | C7: Culver City | D7: 0 | E7: 0 | F7: 0 | G7: 0 | H7: 0 | I7: 0 | J7: 0 | K7: -593 | L7: 5189.14 | M7: 27904.72 | N7: 26313.91 | O7: 31865.36 | P7: 43840 | Q7: 38704 | R7: 42619 | S7: 39690 | T7: 43327 | U7: 52000 | V7: 59000 | W7: 50000 | X7: 53000 | Y7: 60000 | Z7: 64000 | AA7: 60000 | AB7: 61000 | AC7: 73307 | AD7: 69238 | AE7: 75096 | AF7: 70949 | AG7: 64231 | AH7: 95489 | AI7: 107456 | AJ7: 102425 | AK7: 95000 | AL7: 95000 | AM7: 95000 | AN7: 64050 | AO7: 76972.35 | AP7: 72699.9 | AQ7: 78850.8 | AR7: 74496.45 | AS7: 67442.55 | AT7: 100263.45 | AU7: 112828.8 | AV7: 107546.25 | AW7: 99750 | AX7: 99750 | AY7: 99750
B8: DN | C8: Danville | D8: 0 | E8: 0 | F8: 0 | G8: -41 | H8: -1587.55 | I8: 6400.96 | J8: 10873.68 | K8: 16910.99 | L8: 12236.8 | M8: 13862.23 | N8: 16979.5 | O8: 17774.24 | P8: 24286 | Q8: 23358 | R8: 20289 | S8: 20363 | T8: 15337 | U8: 20000 | V8: 20000 | W8: 25000 | X8: 25000 | Y8: 30000 | Z8: 25000 | AA8: 32000 | AB8: 32000 | AC8: 40000 | AD8: 40000 | AE8: 45000 | AF8: 45000 | AG8: 50000 | AH8: 50000 | AI8: 50000 | AJ8: 55000 | AK8: 55000 | AL8: 55000 | AM8: 55000 | AN8: 33600 | AO8: 42000 | AP8: 42000 | AQ8: 47250 | AR8: 47250 | AS8: 52500 | AT8: 52500 | AU8: 52500 | AV8: 57750 | AW8: 57750 | AX8: 57750 | AY8: 57750
B9: LF | C9: Lafayette | D9: 84917.64 | E9: 87714.89 | F9: 95273.07 | G9: 83842.65 | H9: 102916.12 | I9: 90516.06 | J9: 81871.4 | K9: 86069.17 | L9: 86278.31 | M9: 82816.69 | N9: 88360.34 | O9: 97868.23 | P9: 92365 | Q9: 126186 | R9: 78385 | S9: 106542 | T9: 71444 | U9: 80000 | V9: 80250 | W9: 80000 | X9: 80250 | Y9: 85000 | Z9: 95000 | AA9: 110000 | AB9: 96983.25 | AC9: 132495.3 | AD9: 82304.25 | AE9: 111869.1 | AF9: 75832.05 | AG9: 84000 | AH9: 84262.5 | AI9: 84000 | AJ9: 84262.5 | AK9: 89250 | AL9: 99750 | AM9: 115500 | AN9: 101832.41 | AO9: 139120.07 | AP9: 86419.46 | AQ9: 117462.56 | AR9: 79623.65 | AS9: 88200 | AT9: 88475.62 | AU9: 88200 | AV9: 88475.62 | AW9: 93712.5 | AX9: 104737.5 | AY9: 121275
B10: MR | C10: Marin | D10: 15363.68 | E10: 13623.89 | F10: 17561.05 | G10: 17301.51 | H10: 50403.35 | I10: 77670.01 | J10: 81210.12 | K10: 87074.57 | L10: 106901.68 | M10: 94929.2 | N10: 113680.3 | O10: 113277.53 | P10: 100589 | Q10: 114193 | R10: 90196 | S10: 140256 | T10: 74382 | U10: 96300 | V10: 95000 | W10: 120000 | X10: 98000 | Y10: 110000 | Z10: 120000 | AA10: 115000 | AB10: 105618.45 | AC10: 119902.65 | AD10: 94705.8 | AE10: 147268.8 | AF10: 78685.95 | AG10: 101115 | AH10: 99750 | AI10: 126000 | AJ10: 102900 | AK10: 115500 | AL10: 126000 | AM10: 120750 | AN10: 110899.37 | AO10: 125897.78 | AP10: 99441.09 | AQ10: 154632.24 | AR10: 82620.25 | AS10: 106170.75 | AT10: 104737.5 | AU10: 132300 | AV10: 108045 | AW10: 121275 | AX10: 132300 | AY10: 126787.5
B11: OP | C11: Ocean Park | D11: 0 | E11: 75 | F11: -770 | G11: 12609.02 | H11: 40940.41 | I11: 48387 | J11: 57029.27 | K11: 61238.17 | L11: 56299.57 | M11: 55206.21 | N11: 55795.78 | O11: 60611.86 | P11: 60583 | Q11: 59614 | R11: 62052 | S11: 73815 | T11: 63770 | U11: 64200 | V11: 75000 | W11: 60000 | X11: 63000 | Y11: 70000 | Z11: 75000 | AA11: 60000 | AB11: 63612.15 | AC11: 62594.7 | AD11: 65154.6 | AE11: 77505.75 | AF11: 67045.65 | AG11: 67410 | AH11: 78750 | AI11: 63000 | AJ11: 66150 | AK11: 73500 | AL11: 78750 | AM11: 63000 | AN11: 66792.76 | AO11: 65724.43 | AP11: 68412.33 | AQ11: 81381.04 | AR11: 70397.93 | AS11: 70780.5 | AT11: 82687.5 | AU11: 66150 | AV11: 69457.5 | AW11: 77175 | AX11: 82687.5 | AY11: 66150
B12: PH | C12: Presidio Heights | D12: 213465.61 | E12: 214391.55 | F12: 250059.09 | G12: 225172.86 | H12: 217319.45 | I12: 168863.04 | J12: 141383.59 | K12: 159578.75 | L12: 158576.93 | M12: 140949.38 | N12: 156577.57 | O12: 135509.79 | P12: 124927 | Q12: 180839 | R12: 115051 | S12: 179323 | T12: 93511 | U12: 115000 | V12: 110000 | W12: 155000 | X12: 120000 | Y12: 125000 | Z12: 140000 | AA12: 150000 | AB12: 131173.35 | AC12: 189880.95 | AD12: 120803.55 | AE12: 188289.15 | AF12: 100401 | AG12: 120750 | AH12: 115500 | AI12: 162750 | AJ12: 126000 | AK12: 131250 | AL12: 147000 | AM12: 157500 | AN12: 137732.02 | AO12: 199375 | AP12: 126843.73 | AQ12: 197703.61 | AR12: 105421.05 | AS12: 126787.5 | AT12: 121275 | AU12: 170887.5 | AV12: 132300 | AW12: 137812.5 | AX12: 154350 | AY12: 165375
B13: RH | C13: Russian Hill | D13: 570.7 | E13: 15527.63 | F13: 52352.26 | G13: 60194.73 | H13: 72190.72 | I13: 76768.03 | J13: 68332.76 | K13: 70395.32 | L13: 81266.29 | M13: 79286.4 | N13: 76953.29 | O13: 80511.05 | P13: 96145 | Q13: 94253 | R13: 85589 | S13: 108129 | T13: 66857 | U13: 77000 | V13: 75000 | W13: 95000 | X13: 80000 | Y13: 82000 | Z13: 80000 | AA13: 88000 | AB13: 100952.25 | AC13: 98965.65 | AD13: 89868.45 | AE13: 113535.45 | AF13: 71700.3 | AG13: 80850 | AH13: 78750 | AI13: 99750 | AJ13: 84000 | AK13: 86100 | AL13: 84000 | AM13: 92400 | AN13: 105999.86 | AO13: 103913.93 | AP13: 94361.87 | AQ13: 119212.22 | AR13: 75285.32 | AS13: 84892.5 | AT13: 82687.5 | AU13: 104737.5 | AV13: 88200 | AW13: 90405 | AX13: 88200 | AY13: 97020
B14: SB | C14: Santa Barbara | D14: 0 | E14: 0 | F14: 0 | G14: 0 | H14: 0 | I14: 0 | J14: 0 | K14: 0 | L14: 0 | M14: 0 | N14: 3292.97 | O14: 9928.33 | P14: 32747 | Q14: 27799 | R14: 25898 | S14: 23393 | T14: 20133 | U14: 25000 | V14: 25000 | W14: 30000 | X14: 30000 | Y14: 33000 | Z14: 35000 | AA14: 35000 | AB14: 59231 | AC14: 60132 | AD14: 52754 | AE14: 51670 | AF14: 60236 | AG14: 51621 | AH14: 62000 | AI14: 63000 | AJ14: 73000 | AK14: 65000 | AL14: 64200 | AM14: 64200 | AN14: 62192.55 | AO14: 63138.6 | AP14: 55391.7 | AQ14: 54253.5 | AR14: 63247.8 | AS14: 54202.05 | AT14: 65100 | AU14: 66150 | AV14: 76650 | AW14: 68250 | AX14: 67410 | AY14: 67410
B15: SM | C15: Santa Monica | D15: 148311.18 | E15: 176032.84 | F15: 214257.96 | G15: 206935.56 | H15: 197266.94 | I15: 195239.45 | J15: 199014.62 | K15: 210396.36 | L15: 181180.69 | M15: 181590.51 | N15: 176158.72 | O15: 200819.21 | P15: 184491 | Q15: 161597 | R15: 192258 | S15: 157521 | T15: 206632 | U15: 200000 | V15: 200000 | W15: 200000 | X15: 190000 | Y15: 220000 | Z15: 251450 | AA15: 190000 | AB15: 193715.55 | AC15: 169676.85 | AD15: 201870.9 | AE15: 165397.05 | AF15: 217676.55 | AG15: 210000 | AH15: 210000 | AI15: 210000 | AJ15: 199500 | AK15: 231000 | AL15: 264022.5 | AM15: 199500 | AN15: 203401.33 | AO15: 178160.69 | AP15: 211964.45 | AQ15: 173666.9 | AR15: 228560.38 | AS15: 220500 | AT15: 220500 | AU15: 220500 | AV15: 209475 | AW15: 242550 | AX15: 277223.62 | AY15: 209475
B16: WP | C16: West Portal | D16: 0 | E16: 0 | F16: 0 | G16: 0 | H16: 0 | I16: 0 | J16: 0 | K16: 0 | L16: 0 | M16: 0 | N16: 0 | O16: 0 | P16: 1573 | Q16: 1513 | R16: 784 | S16: 370 | T16: 26 | U16: 40000 | V16: 70000 | W16: 78000 | X16: 75000 | Y16: 80000 | Z16: 80000 | AA16: 80000 | AB16: 90025 | AC16: 86822 | AD16: 85300 | AE16: 127703 | AF16: 79689 | AG16: 76768 | AH16: 70767 | AI16: 102739 | AJ16: 68837 | AK16: 83777 | AL16: 79979 | AM16: 79880 | AN16: 94526.25 | AO16: 91163.1 | AP16: 89565 | AQ16: 134088.15 | AR16: 83673.45 | AS16: 80606.4 | AT16: 74305.35 | AU16: 107875.95 | AV16: 72278.85 | AW16: 87965.85 | AX16: 83977.95 | AY16: 83874
B17: WW | C17: Westwood | D17: 64463.03 | E17: 79792.51 | F17: 97840.41 | G17: 83903.77 | H17: 78473.75 | I17: 74619.28 | J17: 89249.84 | K17: 69295.19 | L17: 61491.32 | M17: 72451.08 | N17: 63966.4 | O17: 73183.51 | P17: 71360 | Q17: 69405 | R17: 62992 | S17: 49441 | T17: 60750 | U17: 65000 | V17: 62000 | W17: 64000 | X17: 72000 | Y17: 80000 | Z17: 85600 | AA17: 74900 | AB17: 74928 | AC17: 72875.25 | AD17: 66141.6 | AE17: 51913.05 | AF17: 63897.75 | AG17: 68250 | AH17: 65100 | AI17: 67200 | AJ17: 75600 | AK17: 84000 | AL17: 89880 | AM17: 78645 | AN17: 78674.4 | AO17: 76519.01 | AP17: 69448.68 | AQ17: 54508.7 | AR17: 67092.64 | AS17: 71662.5 | AT17: 68355 | AU17: 70560 | AV17: 79380 | AW17: 88200 | AX17: 94374 | AY17: 82577.25
B18: TOTAL | C18: All Studios | D18: =SUM(D6:D17) | E18: =SUM(E6:E17) | F18: =SUM(F6:F17) | G18: =SUM(G6:G17) | H18: =SUM(H6:H17) | I18: =SUM(I6:I17) | J18: =SUM(J6:J17) | K18: =SUM(K6:K17) | ... AY18: =SUM(AY6:AY17)
B20: Annual Summary
B21: Code | C21: Studio | P21: 2026 | Q21: 2027 | R21: 2028 | S21: 2027 YoY | T21: 2028 YoY
B22: BK | C22: Berkeley | P22: =SUM(P6:AA6) | Q22: =SUM(AB6:AM6) | R22: =SUM(AN6:AY6) | S22: =IFERROR((Q22-P22)/P22,0) | T22: =IFERROR((R22-Q22)/Q22,0)
B23: CC | C23: Culver City | P23: =SUM(P7:AA7) | Q23: =SUM(AB7:AM7) | R23: =SUM(AN7:AY7) | S23: =IFERROR((Q23-P23)/P23,0) | T23: =IFERROR((R23-Q23)/Q23,0)
B24: DN | C24: Danville | P24: =SUM(P8:AA8) | Q24: =SUM(AB8:AM8) | R24: =SUM(AN8:AY8) | S24: =IFERROR((Q24-P24)/P24,0) | T24: =IFERROR((R24-Q24)/Q24,0)
B25: LF | C25: Lafayette | P25: =SUM(P9:AA9) | Q25: =SUM(AB9:AM9) | R25: =SUM(AN9:AY9) | S25: =IFERROR((Q25-P25)/P25,0) | T25: =IFERROR((R25-Q25)/Q25,0)
B26: MR | C26: Marin | P26: =SUM(P10:AA10) | Q26: =SUM(AB10:AM10) | R26: =SUM(AN10:AY10) | S26: =IFERROR((Q26-P26)/P26,0) | T26: =IFERROR((R26-Q26)/Q26,0)
B27: OP | C27: Ocean Park | P27: =SUM(P11:AA11) | Q27: =SUM(AB11:AM11) | R27: =SUM(AN11:AY11) | S27: =IFERROR((Q27-P27)/P27,0) | T27: =IFERROR((R27-Q27)/Q27,0)
B28: PH | C28: Presidio Heights | P28: =SUM(P12:AA12) | Q28: =SUM(AB12:AM12) | R28: =SUM(AN12:AY12) | S28: =IFERROR((Q28-P28)/P28,0) | T28: =IFERROR((R28-Q28)/Q28,0)
B29: RH | C29: Russian Hill | P29: =SUM(P13:AA13) | Q29: =SUM(AB13:AM13) | R29: =SUM(AN13:AY13) | S29: =IFERROR((Q29-P29)/P29,0) | T29: =IFERROR((R29-Q29)/Q29,0)
B30: SB | C30: Santa Barbara | P30: =SUM(P14:AA14) | Q30: =SUM(AB14:AM14) | R30: =SUM(AN14:AY14) | S30: =IFERROR((Q30-P30)/P30,0) | T30: =IFERROR((R30-Q30)/Q30,0)
B31: SM | C31: Santa Monica | P31: =SUM(P15:AA15) | Q31: =SUM(AB15:AM15) | R31: =SUM(AN15:AY15) | S31: =IFERROR((Q31-P31)/P31,0) | T31: =IFERROR((R31-Q31)/Q31,0)
B32: WP | C32: West Portal | P32: =SUM(P16:AA16) | Q32: =SUM(AB16:AM16) | R32: =SUM(AN16:AY16) | S32: =IFERROR((Q32-P32)/P32,0) | T32: =IFERROR((R32-Q32)/Q32,0)
B33: WW | C33: Westwood | P33: =SUM(P17:AA17) | Q33: =SUM(AB17:AM17) | R33: =SUM(AN17:AY17) | S33: =IFERROR((Q33-P33)/P33,0) | T33: =IFERROR((R33-Q33)/Q33,0)
B34: TOTAL | C34: All Studios | P34: =SUM(P22:P33) | Q34: =SUM(Q22:Q33) | R34: =SUM(R22:R33) | S34: =IFERROR((Q34-P34)/P34,0) | T34: =IFERROR((R34-Q34)/Q34,0)
B100: 2025 SALES HISTORY (hidden helper for lag formulas) | P100: 2025-07 | Q100: 2025-08 | R100: 2025-09 | S100: 2025-10 | T100: 2025-11 | U100: 2025-12
P101: 808077 | Q101: 930709 | R101: 758432 | S101: 830044 | T101: 833160 | U101: 847328
B102: 2025 helper: BK (Berkeley) | T102: 102111.01 | U102: 103847.42
B103: 2025 helper: CC (Culver City) | T103: 36886.61 | U103: 37513.88
B104: 2025 helper: DN (Danville) | T104: 18359.97 | U104: 18672.19
B105: 2025 helper: LF (Lafayette) | T105: 84253.69 | U105: 85686.43
B106: 2025 helper: MR (Marin) | T106: 92130.72 | U106: 93697.42
B107: 2025 helper: OP (Ocean Park) | T107: 56662.27 | U107: 57625.82
...

Sheet Cash, Debt & Equity
B2: Cash, Debt & Equity
B4: Item | P4: Jan 2026 | Q4: Feb 2026 | R4: Mar 2026 | S4: Apr 2026 | T4: May 2026 | U4: Jun 2026 | V4: Jul 2026 | W4: Aug 2026 | X4: Sep 2026 | Y4: Oct 2026 | Z4: Nov 2026 | AA4: Dec 2026 | AB4: Jan 2027 | AC4: Feb 2027 | AD4: Mar 2027 | AE4: Apr 2027 | AF4: May 2027 | AG4: Jun 2027 | AH4: Jul 2027 | AI4: Aug 2027 | AJ4: Sep 2027 | AK4: Oct 2027 | AL4: Nov 2027 | AM4: Dec 2027 | AN4: Jan 2028 | AO4: Feb 2028 | AP4: Mar 2028 | AQ4: Apr 2028 | AR4: May 2028 | AS4: Jun 2028 | AT4: Jul 2028 | AU4: Aug 2028 | AV4: Sep 2028 | AW4: Oct 2028 | AX4: Nov 2028 | AY4: Dec 2028
B5: CASH POSITION | D5: Jan 2025 | E5: Feb 2025 | F5: Mar 2025 | G5: Apr 2025 | H5: May 2025 | I5: Jun 2025 | J5: Jul 2025 | K5: Aug 2025 | L5: Sep 2025 | M5: Oct 2025 | N5: Nov 2025 | O5: Dec 2025
B6: Ending Cash Balance (from CF) | P6: ='Cash Flow Forecast'!P38 | Q6: ='Cash Flow Forecast'!Q38 | R6: ='Cash Flow Forecast'!R38 | S6: ='Cash Flow Forecast'!S38 | T6: ='Cash Flow Forecast'!T38 | U6: ='Cash Flow Forecast'!U38 | V6: ='Cash Flow Forecast'!V38 | W6: ='Cash Flow Forecast'!W38 | ... AY6: ='Cash Flow Forecast'!AY38
B8: DEBT SCHEDULE — Loan Balances by Month
B9: MindBody Loan - SM | P9: 0 | Q9: 0 | R9: 0 | S9: 99348.21 | T9: 0 | U9: =MAX(T9-18871.69,0) | V9: =MAX(U9-18871.69,0) | W9: =MAX(V9-18871.69,0) | X9: =MAX(W9-18871.69,0) | Y9: =MAX(X9-18871.69,0) | Z9: =MAX(Y9-18871.69,0) | AA9: =MAX(Z9-18871.69,0) | AB9: =MAX(AA9-18871.69,0) | ... AY9: =MAX(AX9-18871.69,0)
B10: MindBody Loan - PH | P10: 0 | Q10: 0 | R10: 0 | S10: 46989.79 | T10: 0 | U10: =MAX(T10-16602.04,0) | V10: =MAX(U10-16602.04,0) | W10: =MAX(V10-16602.04,0) | X10: =MAX(W10-16602.04,0) | Y10: =MAX(X10-16602.04,0) | Z10: =MAX(Y10-16602.04,0) | AA10: =MAX(Z10-16602.04,0) | AB10: =MAX(AA10-16602.04,0) | ... AY10: =MAX(AX10-16602.04,0)
B11: MindBody Loan - LF | P11: 0 | Q11: 0 | R11: 0 | S11: 20599.85 | T11: 0 | U11: =MAX(T11-12162.36,0) | V11: =MAX(U11-12162.36,0) | W11: =MAX(V11-12162.36,0) | X11: =MAX(W11-12162.36,0) | Y11: =MAX(X11-12162.36,0) | Z11: =MAX(Y11-12162.36,0) | AA11: =MAX(Z11-12162.36,0) | AB11: =MAX(AA11-12162.36,0) | ... AY11: =MAX(AX11-12162.36,0)
B12: MindBody Loan - MR | P12: 0 | Q12: 0 | R12: 0 | S12: 14815.18 | T12: 0 | U12: =MAX(T12-13157.16,0) | V12: =MAX(U12-13157.16,0) | W12: =MAX(V12-13157.16,0) | X12: =MAX(W12-13157.16,0) | Y12: =MAX(X12-13157.16,0) | Z12: =MAX(Y12-13157.16,0) | AA12: =MAX(Z12-13157.16,0) | AB12: =MAX(AA12-13157.16,0) | ... AY12: =MAX(AX12-13157.16,0)
B13: Samson Loan | P13: 205426.16 | Q13: 189034.12 | R13: 154505.72 | S13: 129045.5 | T13: 94517.1 | U13: =MAX(T13-25460.22,0) | V13: =MAX(U13-25460.22,0) | W13: =MAX(V13-25460.22,0) | X13: =MAX(W13-25460.22,0) | Y13: =MAX(X13-25460.22,0) | Z13: =MAX(Y13-25460.22,0) | AA13: =MAX(Z13-25460.22,0) | AB13: =MAX(AA13-25460.22,0) | ... AY13: =MAX(AX13-25460.22,0)
B14: Specialty Capital Loan | P14: 187921.05 | Q14: 165407.89 | R14: 135078.94 | S14: 112565.78 | T14: 90052.62 | U14: =MAX(T14-25888.16,0) | V14: =MAX(U14-25888.16,0) | W14: =MAX(V14-25888.16,0) | X14: =MAX(W14-25888.16,0) | Y14: =MAX(X14-25888.16,0) | Z14: =MAX(Y14-25888.16,0) | AA14: =MAX(Z14-25888.16,0) | AB14: =MAX(AA14-25888.16,0) | ... AY14: =MAX(AX14-25888.16,0)
B15: Norbrook Inc Loan | P15: 0 | Q15: 0 | R15: 0 | S15: 162318 | T15: 0 | U15: =T15 | V15: =U15 | W15: =V15 | X15: =W15 | Y15: =X15 | Z15: =Y15 | AA15: =Z15 | AB15: =AA15 | ... AY15: =AX15
B16: TOTAL DEBT | P16: =SUM(P9:P15) | Q16: =SUM(Q9:Q15) | R16: =SUM(R9:R15) | S16: =SUM(S9:S15) | T16: =SUM(T9:T15) | U16: =SUM(U9:U15) | V16: =SUM(V9:V15) | W16: =SUM(W9:W15) | ... AY16: =SUM(AY9:AY15)
B18: MONTHLY DEBT SERVICE
B19: MindBody Loan - SM | P19: 0 | Q19: 0 | R19: 0 | S19: 0 | T19: 0 | U19: =IF(U9>0,18871.69,0) | V19: =IF(V9>0,18871.69,0) | W19: =IF(W9>0,18871.69,0) | X19: =IF(X9>0,18871.69,0) | Y19: =IF(Y9>0,18871.69,0) | Z19: =IF(Z9>0,18871.69,0) | AA19: =IF(AA9>0,18871.69,0) | AB19: =IF(AB9>0,18871.69,0) | ... AY19: =IF(AY9>0,18871.69,0)
B20: MindBody Loan - PH | P20: 0 | Q20: 0 | R20: 0 | S20: 0 | T20: 0 | U20: =IF(U10>0,16602.04,0) | V20: =IF(V10>0,16602.04,0) | W20: =IF(W10>0,16602.04,0) | X20: =IF(X10>0,16602.04,0) | Y20: =IF(Y10>0,16602.04,0) | Z20: =IF(Z10>0,16602.04,0) | AA20: =IF(AA10>0,16602.04,0) | AB20: =IF(AB10>0,16602.04,0) | ... AY20: =IF(AY10>0,16602.04,0)
B21: MindBody Loan - LF | P21: 0 | Q21: 0 | R21: 0 | S21: 0 | T21: 0 | U21: =IF(U11>0,12162.36,0) | V21: =IF(V11>0,12162.36,0) | W21: =IF(W11>0,12162.36,0) | X21: =IF(X11>0,12162.36,0) | Y21: =IF(Y11>0,12162.36,0) | Z21: =IF(Z11>0,12162.36,0) | AA21: =IF(AA11>0,12162.36,0) | AB21: =IF(AB11>0,12162.36,0) | ... AY21: =IF(AY11>0,12162.36,0)
B22: MindBody Loan - MR | P22: 0 | Q22: 0 | R22: 0 | S22: 0 | T22: 0 | U22: =IF(U12>0,13157.16,0) | V22: =IF(V12>0,13157.16,0) | W22: =IF(W12>0,13157.16,0) | X22: =IF(X12>0,13157.16,0) | Y22: =IF(Y12>0,13157.16,0) | Z22: =IF(Z12>0,13157.16,0) | AA22: =IF(AA12>0,13157.16,0) | AB22: =IF(AB12>0,13157.16,0) | ... AY22: =IF(AY12>0,13157.16,0)
B23: Samson Loan | P23: 0 | Q23: 0 | R23: 0 | S23: 0 | T23: 94517.1 | U23: =IF(U13>0,25460.22,0) | V23: =IF(V13>0,25460.22,0) | W23: =IF(W13>0,25460.22,0) | X23: =IF(X13>0,25460.22,0) | Y23: =IF(Y13>0,25460.22,0) | Z23: =IF(Z13>0,25460.22,0) | AA23: =IF(AA13>0,25460.22,0) | AB23: =IF(AB13>0,25460.22,0) | ... AY23: =IF(AY13>0,25460.22,0)
B24: Specialty Capital Loan | P24: 0 | Q24: 0 | R24: 0 | S24: 0 | T24: 90052.62 | U24: =IF(U14>0,25888.16,0) | V24: =IF(V14>0,25888.16,0) | W24: =IF(W14>0,25888.16,0) | X24: =IF(X14>0,25888.16,0) | Y24: =IF(Y14>0,25888.16,0) | Z24: =IF(Z14>0,25888.16,0) | AA24: =IF(AA14>0,25888.16,0) | AB24: =IF(AB14>0,25888.16,0) | ... AY24: =IF(AY14>0,25888.16,0)
B25: Norbrook Inc Loan | P25: 0 | Q25: 0 | R25: 0 | S25: 0 | T25: 0 | U25: =U15*0.08/12 | V25: =V15*0.08/12 | W25: =W15*0.08/12 | X25: =X15*0.08/12 | Y25: =Y15*0.08/12 | Z25: =Z15*0.08/12 | AA25: =AA15*0.08/12 | AB25: =AB15*0.08/12 | ... AY25: =AY15*0.08/12
B26: TOTAL DEBT SERVICE | P26: =SUM(P19:P25) | Q26: =SUM(Q19:Q25) | R26: =SUM(R19:R25) | S26: =SUM(S19:S25) | T26: =SUM(T19:T25) | U26: =SUM(U19:U25) | V26: =SUM(V19:V25) | W26: =SUM(W19:W25) | ... AY26: =SUM(AY19:AY25)
B28: OWNER EQUITY / INTERCOMPANY
B29: Intercompany Net Position | P29: 224773.04 | Q29: 224773.04 | R29: 358106.37 | S29: 436439.7 | T29: 0 | U29: 0 | V29: 0 | W29: 0 | X29: 0 | Y29: 0 | Z29: 0 | AA29: 0 | AB29: 0 | AC29: 0 | AD29: 0 | AE29: 0 | AF29: 0 | AG29: 0 | AH29: 0 | AI29: 0 | AJ29: 0 | AK29: 0 | AL29: 0 | AM29: 0 | AN29: 0 | AO29: 0 | AP29: 0 | AQ29: 0 | AR29: 0 | AS29: 0 | AT29: 0 | AU29: 0 | AV29: 0 | AW29: 0 | AX29: 0 | AY29: 0

Sheet Cash Flow Forecast
B2: Cash Flow Forecast
B3: Actuals: Jan-Apr 2026 (light green). Forecast: May 2026 onwards. Net Change formulas sum operations + investing + financing.
B4: Monthly Cash Flow
B5: Line Item | C5: Annual Total | D5: Jan 2025 | E5: Feb 2025 | F5: Mar 2025 | G5: Apr 2025 | H5: May 2025 | I5: Jun 2025 | J5: Jul 2025 | K5: Aug 2025 | L5: Sep 2025 | M5: Oct 2025 | N5: Nov 2025 | O5: Dec 2025 | P5: Jan 2026 | Q5: Feb 2026 | R5: Mar 2026 | S5: Apr 2026 | T5: May 2026 | U5: Jun 2026 | V5: Jul 2026 | W5: Aug 2026 | X5: Sep 2026 | Y5: Oct 2026 | Z5: Nov 2026 | AA5: Dec 2026 | AB5: Jan 2027 | AC5: Feb 2027 | AD5: Mar 2027 | AE5: Apr 2027 | AF5: May 2027 | AG5: Jun 2027 | AH5: Jul 2027 | AI5: Aug 2027 | AJ5: Sep 2027 | AK5: Oct 2027 | AL5: Nov 2027 | AM5: Dec 2027 | AN5: Jan 2028 | AO5: Feb 2028 | AP5: Mar 2028 | AQ5: Apr 2028 | AR5: May 2028 | AS5: Jun 2028 | AT5: Jul 2028 | AU5: Aug 2028 | AV5: Sep 2028 | AW5: Oct 2028 | AX5: Nov 2028 | AY5: Dec 2028
B6: CASH INFLOWS
B7: Total Cash Sales | P7: ='Sales Forecast'!P18 | Q7: ='Sales Forecast'!Q18 | R7: ='Sales Forecast'!R18 | S7: ='Sales Forecast'!S18 | T7: ='Sales Forecast'!T18 | U7: ='Sales Forecast'!U18 | V7: ='Sales Forecast'!V18 | W7: ='Sales Forecast'!W18 | ... AY7: ='Sales Forecast'!AY18
B9: OPERATING OUTFLOWS
B10: Property Costs | P10: 147113.46 | Q10: 146344.65 | R10: 147382.66 | S10: 148059.43 | T10: 147112.25 | U10: 147112.25 | V10: 147112.25 | W10: 147112.25 | X10: 147112.25 | Y10: 147112.25 | Z10: 147112.25 | AA10: 147112.25 | AB10: 151525.62 | AC10: 151525.62 | AD10: 151525.62 | AE10: 151525.62 | AF10: 151525.62 | AG10: 151525.62 | AH10: 151525.62 | AI10: 151525.62 | AJ10: 151525.62 | AK10: 151525.62 | AL10: 151525.62 | AM10: 151525.62 | AN10: 156071.4 | AO10: 156071.4 | AP10: 156071.4 | AQ10: 156071.4 | AR10: 156071.4 | AS10: 156071.4 | AT10: 156071.4 | AU10: 156071.4 | AV10: 156071.4 | AW10: 156071.4 | AX10: 156071.4 | AY10: 156071.4
B11: Staff Costs | P11: 681232.98 | Q11: 590412.06 | R11: 628953.81 | S11: 576480.98 | T11: 598615.61 | U11: 598615.61 | V11: 598615.61 | W11: 598615.61 | X11: 598615.61 | Y11: 598615.61 | Z11: 598615.61 | AA11: 598615.61 | AB11: 622560.23 | AC11: 622560.23 | AD11: 622560.23 | AE11: 622560.23 | AF11: 622560.23 | AG11: 622560.23 | AH11: 622560.23 | AI11: 622560.23 | AJ11: 622560.23 | AK11: 622560.23 | AL11: 622560.23 | AM11: 622560.23 | AN11: 647462.64 | AO11: 647462.64 | AP11: 647462.64 | AQ11: 647462.64 | AR11: 647462.64 | AS11: 647462.64 | AT11: 647462.64 | AU11: 647462.64 | AV11: 647462.64 | AW11: 647462.64 | AX11: 647462.64 | AY11: 647462.64
B12: Utilities | P12: 7087.42 | Q12: 9973.09 | R12: 7034.72 | S12: 7270.22 | T12: 8720.11 | U12: 8720.11 | V12: 8720.11 | W12: 8720.11 | X12: 8720.11 | Y12: 8720.11 | Z12: 8720.11 | AA12: 8720.11 | AB12: 9043.82 | AC12: 9043.82 | AD12: 9043.82 | AE12: 9043.82 | AF12: 9043.82 | AG12: 9043.82 | AH12: 9043.82 | AI12: 9043.82 | AJ12: 9043.82 | AK12: 9043.82 | AL12: 9043.82 | AM12: 9043.82 | AN12: 9380.48 | AO12: 9380.48 | AP12: 8753.05 | AQ12: 8753.05 | AR12: 8753.05 | AS12: 8753.05 | AT12: 8753.05 | AU12: 8753.05 | AV12: 8753.05 | AW12: 8753.05 | AX12: 8753.05 | AY12: 8753.05
B13: Marketing & Promotion | P13: 27740.18 | Q13: 27007.49 | R13: 16681.8 | S13: 5975.58 | T13: 16948.9 | U13: 16948.9 | V13: 16948.9 | W13: 16948.9 | X13: 16948.9 | Y13: 16948.9 | Z13: 16948.9 | AA13: 16948.9 | AB13: 17626.86 | AC13: 17626.86 | AD13: 17626.86 | AE13: 17626.86 | AF13: 17626.86 | AG13: 17626.86 | AH13: 17626.86 | AI13: 17626.86 | AJ13: 17626.86 | AK13: 17626.86 | AL13: 17626.86 | AM13: 17626.86 | AN13: 18331.93 | AO13: 18331.93 | AP13: 18331.93 | AQ13: 18331.93 | AR13: 18331.93 | AS13: 18331.93 | AT13: 18331.93 | AU13: 18331.93 | AV13: 18331.93 | AW13: 18331.93 | AX13: 18331.93 | AY13: 18331.93
B14: Administrative & G&A | P14: 32760.81 | Q14: 38409.23 | R14: 33297.16 | S14: 28817.49 | T14: 37431.59 | U14: 37431.59 | V14: 37431.59 | W14: 37431.59 | X14: 37431.59 | Y14: 37431.59 | Z14: 37431.59 | AA14: 37431.59 | AB14: 38928.85 | AC14: 38928.85 | AD14: 38928.85 | AE14: 38928.85 | AF14: 38928.85 | AG14: 38928.85 | AH14: 38928.85 | AI14: 38928.85 | AJ14: 38928.85 | AK14: 38928.85 | AL14: 38928.85 | AM14: 38928.85 | AN14: 40486.01 | AO14: 40486.01 | AP14: 40486.01 | AQ14: 40486.01 | AR14: 40486.01 | AS14: 40486.01 | AT14: 40486.01 | AU14: 40486.01 | AV14: 40486.01 | AW14: 40486.01 | AX14: 40486.01 | AY14: 40486.01
B15: Professional Fees | P15: 42733.79 | Q15: 24202.3 | R15: 22556.84 | S15: 25366 | T15: 24041.72 | U15: 24041.72 | V15: 24041.72 | W15: 24041.72 | X15: 24041.72 | Y15: 24041.72 | Z15: 24041.72 | AA15: 24041.72 | AB15: 25003.37 | AC15: 25003.37 | AD15: 25003.37 | AE15: 25003.37 | AF15: 25003.37 | AG15: 25003.37 | AH15: 25003.37 | AI15: 25003.37 | AJ15: 25003.37 | AK15: 25003.37 | AL15: 25003.37 | AM15: 25003.37 | AN15: 26003.5 | AO15: 26003.5 | AP15: 26003.5 | AQ15: 26003.5 | AR15: 26003.5 | AS15: 26003.5 | AT15: 26003.5 | AU15: 26003.5 | AV15: 26003.5 | AW15: 26003.5 | AX15: 26003.5 | AY15: 26003.5
B16: Travel & Meals | P16: 6819.03 | Q16: 3543.33 | R16: 6002.36 | S16: 2789.61 | T16: 4111.78 | U16: 4111.78 | V16: 4111.78 | W16: 4111.78 | X16: 4111.78 | Y16: 4111.78 | Z16: 4111.78 | AA16: 4111.78 | AB16: 4276.25 | AC16: 4276.25 | AD16: 4276.25 | AE16: 4276.25 | AF16: 4276.25 | AG16: 4276.25 | AH16: 4276.25 | AI16: 4276.25 | AJ16: 4276.25 | AK16: 4276.25 | AL16: 4276.25 | AM16: 4276.25 | AN16: 4447.31 | AO16: 4447.31 | AP16: 4447.31 | AQ16: 4447.31 | AR16: 4447.31 | AS16: 4447.31 | AT16: 4447.31 | AU16: 4447.31 | AV16: 4447.31 | AW16: 4447.31 | AX16: 4447.31 | AY16: 4447.31
B17: Merchant Fees & COGS | P17: 65117.3 | Q17: 67419.26 | R17: 61727.36 | S17: 65364.98 | T17: =T7*(Assumptions!$C$19+Assumptions!$C$20) | U17: =U7*(Assumptions!$C$19+Assumptions!$C$20) | V17: =V7*(Assumptions!$C$19+Assumptions!$C$20) | W17: =W7*(Assumptions!$C$19+Assumptions!$C$20) | X17: =X7*(Assumptions!$C$19+Assumptions!$C$20) | Y17: =Y7*(Assumptions!$C$19+Assumptions!$C$20) | Z17: =Z7*(Assumptions!$C$19+Assumptions!$C$20) | AA17: =AA7*(Assumptions!$C$19+Assumptions!$C$20) | ... AY17: =AY7*(Assumptions!$C$19+Assumptions!$C$20)
B18: Studio Start Up Costs | P18: 0 | Q18: 0 | R18: 0 | S18: 0 | T18: 0 | U18: 0 | V18: 0 | W18: 0 | X18: 0 | Y18: 0 | Z18: 0 | AA18: 0 | AB18: 0 | AC18: 0 | AD18: 0 | AE18: 0 | AF18: 0 | AG18: 0 | AH18: 0 | AI18: 0 | AJ18: 0 | AK18: 0 | AL18: 0 | AM18: 0 | AN18: 0 | AO18: 0 | AP18: 0 | AQ18: 0 | AR18: 0 | AS18: 0 | AT18: 0 | AU18: 0 | AV18: 0 | AW18: 0 | AX18: 0 | AY18: 0
B19: Taxes | P19: 3673 | Q19: 8816 | R19: 3673 | S19: 3673 | T19: 5387.33 | U19: 5387.33 | V19: 5387.33 | W19: 5387.33 | X19: 5387.33 | Y19: 5387.33 | Z19: 5387.33 | AA19: 5387.33 | AB19: 5602.82 | AC19: 5602.82 | AD19: 5602.82 | AE19: 5602.82 | AF19: 5602.82 | AG19: 5602.82 | AH19: 5602.82 | AI19: 5602.82 | AJ19: 5602.82 | AK19: 5602.82 | AL19: 5602.82 | AM19: 5602.82 | AN19: 5826.93 | AO19: 5826.93 | AP19: 5826.93 | AQ19: 5826.93 | AR19: 5826.93 | AS19: 5826.93 | AT19: 5826.93 | AU19: 5826.93 | AV19: 5826.93 | AW19: 5826.93 | AX19: 5826.93 | AY19: 5826.93
B20: Total Operating Expenses | P20: =SUM(P10:P19) | Q20: =SUM(Q10:Q19) | R20: =SUM(R10:R19) | S20: =SUM(S10:S19) | T20: =SUM(T10:T19) | U20: =SUM(U10:U19) | V20: =SUM(V10:V19) | W20: =SUM(W10:W19) | ... AY20: =SUM(AY10:AY19)
B21: Net Cash from Operations | P21: =P7-P20 | Q21: =Q7-Q20 | R21: =R7-R20 | S21: =S7-S20 | T21: =T7-T20 | U21: =U7-U20 | V21: =V7-V20 | W21: =W7-W20 | ... AY21: =AY7-AY20
B23: INVESTING ACTIVITIES
B24: Equipment & Furniture | P24: 0 | Q24: 2497.4 | R24: 0 | S24: 0 | T24: 0 | U24: 0 | V24: 0 | W24: 0 | X24: 0 | Y24: 0 | Z24: 0 | AA24: 0 | AB24: 0 | AC24: 0 | AD24: 0 | AE24: 0 | AF24: 0 | AG24: 0 | AH24: 0 | AI24: 0 | AJ24: 0 | AK24: 0 | AL24: 0 | AM24: 0 | AN24: 0 | AO24: 0 | AP24: 0 | AQ24: 0 | AR24: 0 | AS24: 0 | AT24: 0 | AU24: 0 | AV24: 0 | AW24: 0 | AX24: 0 | AY24: 0
B25: Leasehold Improvements | P25: -17810.67 | Q25: -7094.5 | R25: -24075 | S25: -1035.5 | T25: 0 | U25: 0 | V25: -275000 | W25: -160000 | X25: 0 | Y25: 0 | Z25: 0 | AA25: 0 | AB25: 0 | AC25: 0 | AD25: 0 | AE25: 0 | AF25: 0 | AG25: 0 | AH25: 0 | AI25: 0 | AJ25: 0 | AK25: 0 | AL25: 0 | AM25: 0 | AN25: 0 | AO25: 0 | AP25: 0 | AQ25: 0 | AR25: 0 | AS25: 0 | AT25: 0 | AU25: 0 | AV25: 0 | AW25: 0 | AX25: 0 | AY25: 0
B26: Deposits | P26: 0 | Q26: 0 | R26: 0 | S26: 0 | T26: 0 | U26: 0 | V26: 0 | W26: 0 | X26: 0 | Y26: 0 | Z26: 0 | AA26: 0 | AB26: 0 | AC26: 0 | AD26: 0 | AE26: 0 | AF26: 0 | AG26: 0 | AH26: 0 | AI26: 0 | AJ26: 0 | AK26: 0 | AL26: 0 | AM26: 0 | AN26: 0 | AO26: 0 | AP26: 0 | AQ26: 0 | AR26: 0 | AS26: 0 | AT26: 0 | AU26: 0 | AV26: 0 | AW26: 0 | AX26: 0 | AY26: 0
B27: Net Investing | P27: =SUM(P24:P26) | Q27: =SUM(Q24:Q26) | R27: =SUM(R24:R26) | S27: =SUM(S24:S26) | T27: =SUM(T24:T26) | U27: =SUM(U24:U26) | V27: =SUM(V24:V26) | W27: =SUM(W24:W26) | ... AY27: =SUM(AY24:AY26)
B29: FINANCING ACTIVITIES
B30: Loan Proceeds | P30: 9059.38 | Q30: 9059.38 | R30: 9059.38 | S30: 12507.09 | T30: 0 | U30: 0 | V30: 0 | W30: 0 | X30: 0 | Y30: 0 | Z30: 0 | AA30: 0 | AB30: 0 | AC30: 0 | AD30: 0 | AE30: 0 | AF30: 0 | AG30: 0 | AH30: 0 | AI30: 0 | AJ30: 0 | AK30: 0 | AL30: 0 | AM30: 0 | AN30: 0 | AO30: 0 | AP30: 0 | AQ30: 0 | AR30: 0 | AS30: 0 | AT30: 0 | AU30: 0 | AV30: 0 | AW30: 0 | AX30: 0 | AY30: 0
B31: Loan Repayments | P31: -132128.24 | Q31: -122128.76 | R31: -132834.5 | S31: -114793.66 | T31: =-'Cash, Debt & Equity'!T26 | U31: =-'Cash, Debt & Equity'!U26 | V31: =-'Cash, Debt & Equity'!V26 | W31: =-'Cash, Debt & Equity'!W26 | X31: =-'Cash, Debt & Equity'!X26 | Y31: =-'Cash, Debt & Equity'!Y26 | Z31: =-'Cash, Debt & Equity'!Z26 | AA31: =-'Cash, Debt & Equity'!AA26 | ... AY31: =-'Cash, Debt & Equity'!AY26
B32: Intercompany / Owner Contributions | P32: 0 | Q32: 0 | R32: 133333.33 | S32: 78333.33 | T32: 0 | U32: 0 | V32: 0 | W32: 0 | X32: 0 | Y32: 0 | Z32: -100000 | AA32: 0 | AB32: 0 | AC32: 0 | AD32: 0 | AE32: 0 | AF32: 0 | AG32: 0 | AH32: 0 | AI32: 0 | AJ32: 0 | AK32: 0 | AL32: 0 | AM32: 0 | AN32: 0 | AO32: 0 | AP32: 0 | AQ32: 0 | AR32: 0 | AS32: 0 | AT32: 0 | AU32: 0 | AV32: 0 | AW32: 0 | AX32: 0 | AY32: 0
B33: Net Financing | P33: =SUM(P30:P32) | Q33: =SUM(Q30:Q32) | R33: =SUM(R30:R32) | S33: =SUM(S30:S32) | T33: =SUM(T30:T32) | U33: =SUM(U30:U32) | V33: =SUM(V30:V32) | W33: =SUM(W30:W32) | ... AY33: =SUM(AY30:AY32)
B35: NET CHANGE IN CASH
B36: Net Change in Cash | P36: =P21+P27+P33 | Q36: =Q21+Q27+Q33 | R36: =R21+R27+R33 | S36: =S21+S27+S33 | T36: =T21+T27+T33 | U36: =U21+U27+U33 | V36: =V21+V27+V33 | W36: =W21+W27+W33 | ... AY36: =AY21+AY27+AY33
B37: Beginning Cash Balance | P37: =P38-P36 | Q37: =P38 | R37: =Q38 | S37: =R38 | T37: =S38 | U37: =T38 | V37: =U38 | W37: =V38 | X37: =W38 | ... AY37: =AX38
B38: Ending Cash Balance | P38: 187021.69 | Q38: 261314.24 | R38: 237762.6 | S38: 473976.03 | T38: =T37+T36 | U38: =U37+U36 | V38: =V37+V36 | W38: =W37+W36 | X38: =X37+X36 | Y38: =Y37+Y36 | Z38: =Z37+Z36 | AA38: =AA37+AA36 | ... AY38: =AY37+AY36

Sheet P&L
B2: Profit & Loss (Consolidated)
B3: Actuals Jan-Apr 2026. Forecast May 2026+ uses formulas from Sales Forecast and Assumptions.
B4: Monthly P&L
B5: Line Item | D5: Jan 2025 | E5: Feb 2025 | F5: Mar 2025 | G5: Apr 2025 | H5: May 2025 | I5: Jun 2025 | J5: Jul 2025 | K5: Aug 2025 | L5: Sep 2025 | M5: Oct 2025 | N5: Nov 2025 | O5: Dec 2025 | P5: Jan 2026 | Q5: Feb 2026 | R5: Mar 2026 | S5: Apr 2026 | T5: May 2026 | U5: Jun 2026 | V5: Jul 2026 | W5: Aug 2026 | X5: Sep 2026 | Y5: Oct 2026 | Z5: Nov 2026 | AA5: Dec 2026 | AB5: Jan 2027 | AC5: Feb 2027 | AD5: Mar 2027 | AE5: Apr 2027 | AF5: May 2027 | AG5: Jun 2027 | AH5: Jul 2027 | AI5: Aug 2027 | AJ5: Sep 2027 | AK5: Oct 2027 | AL5: Nov 2027 | AM5: Dec 2027 | AN5: Jan 2028 | AO5: Feb 2028 | AP5: Mar 2028 | AQ5: Apr 2028 | AR5: May 2028 | AS5: Jun 2028 | AT5: Jul 2028 | AU5: Aug 2028 | AV5: Sep 2028 | AW5: Oct 2028 | AX5: Nov 2028 | AY5: Dec 2028
B6: Session Revenue | D6: 444458.84 | E6: 541393.76 | F6: 704822.04 | G6: 684557.59 | H6: 741695.39 | I6: 732460.21 | J6: 728344.66 | K6: 718819.72 | L6: 720323.37 | M6: 736168.74 | N6: 706551.99 | O6: 690895.82 | P6: 1000204 | Q6: 866507.65 | R6: 867748.4 | S6: 790938.82 | T6: 807497.91 | U6: ='Sales Forecast'!U18*Assumptions!$C$12+'Sales Forecast'!T18*Assumptions!$D$12+'Sales Forecast'!S18*Assumptions!$E$12+'Sales Forecast'!R18*Assumptions!$F$12+'Sales Forecast'!Q18*Assumptions!$G$12+'Sales Forecast'!P18*Assumptions!$H$12+'Sales Forecast'!U101*Assumptions!$I$12 | V6: ='Sales Forecast'!V18*Assumptions!$C$12+'Sales Forecast'!U18*Assumptions!$D$12+'Sales Forecast'!T18*Assumptions!$E$12+'Sales Forecast'!S18*Assumptions!$F$12+'Sales Forecast'!R18*Assumptions!$G$12+'Sales Forecast'!Q18*Assumptions!$H$12+'Sales Forecast'!P18*Assumptions!$I$12 | W6: ='Sales Forecast'!W18*Assumptions!$C$12+'Sales Forecast'!V18*Assumptions!$D$12+'Sales Forecast'!U18*Assumptions!$E$12+'Sales Forecast'!T18*Assumptions!$F$12+'Sales Forecast'!S18*Assumptions!$G$12+'Sales Forecast'!R18*Assumptions!$H$12+'Sales Forecast'!Q18*Assumptions!$I$12 | X6: ='Sales Forecast'!X18*Assumptions!$C$12+'Sales Forecast'!W18*Assumptions!$D$12+'Sales Forecast'!V18*Assumptions!$E$12+'Sales Forecast'!U18*Assumptions!$F$12+'Sales Forecast'!T18*Assumptions!$G$12+'Sales Forecast'!S18*Assumptions!$H$12+'Sales Forecast'!R18*Assumptions!$I$12 | Y6: ='Sales Forecast'!Y18*Assumptions!$C$12+'Sales Forecast'!X18*Assumptions!$D$12+'Sales Forecast'!W18*Assumptions!$E$12+'Sales Forecast'!V18*Assumptions!$F$12+'Sales Forecast'!U18*Assumptions!$G$12+'Sales Forecast'!T18*Assumptions!$H$12+'Sales Forecast'!S18*Assumptions!$I$12 | Z6: ='Sales Forecast'!Z18*Assumptions!$C$12+'Sales Forecast'!Y18*Assumptions!$D$12+'Sales Forecast'!X18*Assumptions!$E$12+'Sales Forecast'!W18*Assumptions!$F$12+'Sales Forecast'!V18*Assumptions!$G$12+'Sales Forecast'!U18*Assumptions!$H$12+'Sales Forecast'!T18*Assumptions!$I$12 | AA6: ='Sales Forecast'!AA18*Assumptions!$C$12+'Sales Forecast'!Z18*Assumptions!$D$12+'Sales Forecast'!Y18*Assumptions!$E$12+'Sales Forecast'!X18*Assumptions!$F$12+'Sales Forecast'!W18*Assumptions!$G$12+'Sales Forecast'!V18*Assumptions!$H$12+'Sales Forecast'!U18*Assumptions!$I$12 | AB6: ='Sales Forecast'!AB18*Assumptions!$C$12+'Sales Forecast'!AA18*Assumptions!$D$12+'Sales Forecast'!Z18*Assumptions!$E$12+'Sales Forecast'!Y18*Assumptions!$F$12+'Sales Forecast'!X18*Assumptions!$G$12+'Sales Forecast'!W18*Assumptions!$H$12+'Sales Forecast'!V18*Assumptions!$I$12 | AC6: ='Sales Forecast'!AC18*Assumptions!$C$12+'Sales Forecast'!AB18*Assumptions!$D$12+'Sales Forecast'!AA18*Assumptions!$E$12+'Sales Forecast'!Z18*Assumptions!$F$12+'Sales Forecast'!Y18*Assumptions!$G$12+'Sales Forecast'!X18*Assumptions!$H$12+'Sales Forecast'!W18*Assumptions!$I$12 | ... AY6: ='Sales Forecast'!AY18*Assumptions!$C$12+'Sales Forecast'!AX18*Assumptions!$D$12+'Sales Forecast'!AW18*Assumptions!$E$12+'Sales Forecast'!AV18*Assumptions!$F$12+'Sales Forecast'!AU18*Assumptions!$G$12+'Sales Forecast'!AT18*Assumptions!$H$12+'Sales Forecast'!AS18*Assumptions!$I$12
B7: Breakage Revenue | D7: 75237.94 | E7: 109399.17 | F7: 140651.46 | G7: 149516.51 | H7: 181344.3 | I7: 149213.5 | J7: 157965.23 | K7: 206864.97 | L7: 213185.16 | M7: 179766.24 | N7: 238121.51 | O7: 304457.14 | P7: 139780.94 | Q7: 155452.01 | R7: 132350.01 | S7: 142563.17 | T7: 141174.57 | U7: ='Sales Forecast'!U18*Assumptions!$C$13+'Sales Forecast'!T18*Assumptions!$D$13+'Sales Forecast'!S18*Assumptions!$E$13+'Sales Forecast'!R18*Assumptions!$F$13+'Sales Forecast'!Q18*Assumptions!$G$13+'Sales Forecast'!P18*Assumptions!$H$13+'Sales Forecast'!U101*Assumptions!$I$13 | V7: ='Sales Forecast'!V18*Assumptions!$C$13+'Sales Forecast'!U18*Assumptions!$D$13+'Sales Forecast'!T18*Assumptions!$E$13+'Sales Forecast'!S18*Assumptions!$F$13+'Sales Forecast'!R18*Assumptions!$G$13+'Sales Forecast'!Q18*Assumptions!$H$13+'Sales Forecast'!P18*Assumptions!$I$13 | W7: ='Sales Forecast'!W18*Assumptions!$C$13+'Sales Forecast'!V18*Assumptions!$D$13+'Sales Forecast'!U18*Assumptions!$E$13+'Sales Forecast'!T18*Assumptions!$F$13+'Sales Forecast'!S18*Assumptions!$G$13+'Sales Forecast'!R18*Assumptions!$H$13+'Sales Forecast'!Q18*Assumptions!$I$13 | X7: ='Sales Forecast'!X18*Assumptions!$C$13+'Sales Forecast'!W18*Assumptions!$D$13+'Sales Forecast'!V18*Assumptions!$E$13+'Sales Forecast'!U18*Assumptions!$F$13+'Sales Forecast'!T18*Assumptions!$G$13+'Sales Forecast'!S18*Assumptions!$H$13+'Sales Forecast'!R18*Assumptions!$I$13 | Y7: ='Sales Forecast'!Y18*Assumptions!$C$13+'Sales Forecast'!X18*Assumptions!$D$13+'Sales Forecast'!W18*Assumptions!$E$13+'Sales Forecast'!V18*Assumptions!$F$13+'Sales Forecast'!U18*Assumptions!$G$13+'Sales Forecast'!T18*Assumptions!$H$13+'Sales Forecast'!S18*Assumptions!$I$13 | Z7: ='Sales Forecast'!Z18*Assumptions!$C$13+'Sales Forecast'!Y18*Assumptions!$D$13+'Sales Forecast'!X18*Assumptions!$E$13+'Sales Forecast'!W18*Assumptions!$F$13+'Sales Forecast'!V18*Assumptions!$G$13+'Sales Forecast'!U18*Assumptions!$H$13+'Sales Forecast'!T18*Assumptions!$I$13 | AA7: ='Sales Forecast'!AA18*Assumptions!$C$13+'Sales Forecast'!Z18*Assumptions!$D$13+'Sales Forecast'!Y18*Assumptions!$E$13+'Sales Forecast'!X18*Assumptions!$F$13+'Sales Forecast'!W18*Assumptions!$G$13+'Sales Forecast'!V18*Assumptions!$H$13+'Sales Forecast'!U18*Assumptions!$I$13 | AB7: ='Sales Forecast'!AB18*Assumptions!$C$13+'Sales Forecast'!AA18*Assumptions!$D$13+'Sales Forecast'!Z18*Assumptions!$E$13+'Sales Forecast'!Y18*Assumptions!$F$13+'Sales Forecast'!X18*Assumptions!$G$13+'Sales Forecast'!W18*Assumptions!$H$13+'Sales Forecast'!V18*Assumptions!$I$13 | AC7: ='Sales Forecast'!AC18*Assumptions!$C$13+'Sales Forecast'!AB18*Assumptions!$D$13+'Sales Forecast'!AA18*Assumptions!$E$13+'Sales Forecast'!Z18*Assumptions!$F$13+'Sales Forecast'!Y18*Assumptions!$G$13+'Sales Forecast'!X18*Assumptions!$H$13+'Sales Forecast'!W18*Assumptions!$I$13 | ... AY7: ='Sales Forecast'!AY18*Assumptions!$C$13+'Sales Forecast'!AX18*Assumptions!$D$13+'Sales Forecast'!AW18*Assumptions!$E$13+'Sales Forecast'!AV18*Assumptions!$F$13+'Sales Forecast'!AU18*Assumptions!$G$13+'Sales Forecast'!AT18*Assumptions!$H$13+'Sales Forecast'!AS18*Assumptions!$I$13
B8: Retail Sales | D8: 20273 | E8: 19453.92 | F8: 17164.03 | G8: 18478 | H8: 19384 | I8: 28826 | J8: 20010 | K8: 19175 | L8: 19247.98 | M8: 19640 | N8: 21643.2 | O8: 20189 | P8: 23308 | Q8: 19847 | R8: 17655 | S8: 18479 | T8: 13825.81 | U8: 16653.27 | V8: 16653.27 | W8: 16653.27 | X8: 16653.27 | Y8: 16653.27 | Z8: 16653.27 | AA8: 16653.27 | AB8: 16653.27 | AC8: 16653.27 | AD8: 16653.27 | AE8: 16653.27 | AF8: 16653.27 | AG8: 16653.27 | AH8: 16653.27 | AI8: 16653.27 | AJ8: 16653.27 | AK8: 16653.27 | AL8: 16653.27 | AM8: 16653.27 | AN8: 16653.27 | AO8: 16653.27 | AP8: 16653.27 | AQ8: 16653.27 | AR8: 16653.27 | AS8: 16653.27 | AT8: 16653.27 | AU8: 16653.27 | AV8: 16653.27 | AW8: 16653.27 | AX8: 16653.27 | AY8: 16653.27
B9: Refunds | D9: -16377.01 | E9: -10335.55 | F9: -14180.05 | G9: -17645.51 | H9: -12735.29 | I9: -10897.91 | J9: -13385.21 | K9: -12377.04 | L9: -18282.51 | M9: -22049.66 | N9: -15320.98 | O9: -18935.02 | P9: -20830.24 | Q9: -15645.66 | R9: -16880.65 | S9: -12793.11 | T9: -9390.21 | U9: =(U6+U7)*Assumptions!$C$17 | V9: =(V6+V7)*Assumptions!$C$17 | W9: =(W6+W7)*Assumptions!$C$17 | X9: =(X6+X7)*Assumptions!$C$17 | Y9: =(Y6+Y7)*Assumptions!$C$17 | Z9: =(Z6+Z7)*Assumptions!$C$17 | AA9: =(AA6+AA7)*Assumptions!$C$17 | AB9: =(AB6+AB7)*Assumptions!$C$17 | ... AY9: =(AY6+AY7)*Assumptions!$C$17
B10: Discounts | D10: -73972.55 | E10: -63470.28 | F10: -69852.24 | G10: -68577.95 | H10: -75810.5 | I10: -59569.88 | J10: -56128.38 | K10: -56204.78 | L10: -59582.4 | M10: -54374.17 | N10: -48649.06 | O10: -54144.13 | P10: -59600.85 | Q10: -56707.91 | R10: -53962.12 | S10: -51310.18 | T10: -35101.57 | U10: =(U6+U7)*Assumptions!$C$18 | V10: =(V6+V7)*Assumptions!$C$18 | W10: =(W6+W7)*Assumptions!$C$18 | X10: =(X6+X7)*Assumptions!$C$18 | Y10: =(Y6+Y7)*Assumptions!$C$18 | Z10: =(Z6+Z7)*Assumptions!$C$18 | AA10: =(AA6+AA7)*Assumptions!$C$18 | AB10: =(AB6+AB7)*Assumptions!$C$18 | ... AY10: =(AY6+AY7)*Assumptions!$C$18
B11: Total Revenue | D11: 629355.56 | E11: 695448.39 | F11: 845088.61 | G11: 803508.37 | H11: 877719.53 | I11: 853012.79 | J11: 844889.73 | K11: 882190.18 | L11: 877190.19 | M11: 861368.93 | N11: 903526.46 | O11: 943564.31 | P11: 1082861.8 | Q11: 969453.09 | R11: 946910.64 | S11: 887877.7 | T11: 918006.51 | U11: =U6+U7+U8+U9+U10 | V11: =V6+V7+V8+V9+V10 | W11: =W6+W7+W8+W9+W10 | X11: =X6+X7+X8+X9+X10 | Y11: =Y6+Y7+Y8+Y9+Y10 | Z11: =Z6+Z7+Z8+Z9+Z10 | AA11: =AA6+AA7+AA8+AA9+AA10 | AB11: =AB6+AB7+AB8+AB9+AB10 | ... AY11: =AY6+AY7+AY8+AY9+AY10
B12: COGS & Merchant Fees | P12: 38009.85 | Q12: 38497.03 | R12: 34960.53 | S12: 36936.49 | T12: 27088.66 | U12: =U11*(Assumptions!$C$19+Assumptions!$C$20) | V12: =V11*(Assumptions!$C$19+Assumptions!$C$20) | W12: =W11*(Assumptions!$C$19+Assumptions!$C$20) | X12: =X11*(Assumptions!$C$19+Assumptions!$C$20) | Y12: =Y11*(Assumptions!$C$19+Assumptions!$C$20) | Z12: =Z11*(Assumptions!$C$19+Assumptions!$C$20) | AA12: =AA11*(Assumptions!$C$19+Assumptions!$C$20) | AB12: =AB11*(Assumptions!$C$19+Assumptions!$C$20) | ... AY12: =AY11*(Assumptions!$C$19+Assumptions!$C$20)
B13: Gross Profit | D13: 587714.4 | E13: 664601.97 | F13: 810233.79 | G13: 766400.55 | H13: 846558.9 | I13: 817869.28 | J13: 811691.7 | K13: 847262.55 | L13: 844736.53 | M13: 829313.19 | N13: 869551.4 | O13: 888842.62 | P13: 1044852 | Q13: 930956.06 | R13: 911950.11 | S13: 850941.21 | T13: 890917.85 | U13: =U11-U12 | V13: =V11-V12 | W13: =W11-W12 | X13: =X11-X12 | Y13: =Y11-Y12 | Z13: =Z11-Z12 | AA13: =AA11-AA12 | AB13: =AB11-AB12 | ... AY13: =AY11-AY12
B14: Marketing | D14: 19034.32 | E14: 17063.4 | F14: 25178.17 | G14: 17943.65 | H14: 25913.01 | I14: 34869.84 | J14: 23544.8 | K14: 25878.64 | L14: 30151.1 | M14: 31586.11 | N14: 40588.79 | O14: 31249.9 | P14: 27740.18 | Q14: 27007.49 | R14: 16681.8 | S14: 5975.58 | T14: 5982.17 | U14: ='BK P&L'!U33+'CC P&L'!U33+'DN P&L'!U33+'LF P&L'!U33+'MR P&L'!U33+'OP P&L'!U33+'PH P&L'!U33+'RH P&L'!U33+'SB P&L'!U33+'SM P&L'!U33+'WP P&L'!U33+'WW P&L'!U33+'HO P&L'!U12 | V14: ='BK P&L'!V33+'CC P&L'!V33+'DN P&L'!V33+'LF P&L'!V33+'MR P&L'!V33+'OP P&L'!V33+'PH P&L'!V33+'RH P&L'!V33+'SB P&L'!V33+'SM P&L'!V33+'WP P&L'!V33+'WW P&L'!V33+'HO P&L'!V12 | W14: ='BK P&L'!W33+'CC P&L'!W33+'DN P&L'!W33+'LF P&L'!W33+'MR P&L'!W33+'OP P&L'!W33+'PH P&L'!W33+'RH P&L'!W33+'SB P&L'!W33+'SM P&L'!W33+'WP P&L'!W33+'WW P&L'!W33+'HO P&L'!W12 | X14: ='BK P&L'!X33+'CC P&L'!X33+'DN P&L'!X33+'LF P&L'!X33+'MR P&L'!X33+'OP P&L'!X33+'PH P&L'!X33+'RH P&L'!X33+'SB P&L'!X33+'SM P&L'!X33+'WP P&L'!X33+'WW P&L'!X33+'HO P&L'!X12 | Y14: ='BK P&L'!Y33+'CC P&L'!Y33+'DN P&L'!Y33+'LF P&L'!Y33+'MR P&L'!Y33+'OP P&L'!Y33+'PH P&L'!Y33+'RH P&L'!Y33+'SB P&L'!Y33+'SM P&L'!Y33+'WP P&L'!Y33+'WW P&L'!Y33+'HO P&L'!Y12 | Z14: ='BK P&L'!Z33+'CC P&L'!Z33+'DN P&L'!Z33+'LF P&L'!Z33+'MR P&L'!Z33+'OP P&L'!Z33+'PH P&L'!Z33+'RH P&L'!Z33+'SB P&L'!Z33+'SM P&L'!Z33+'WP P&L'!Z33+'WW P&L'!Z33+'HO P&L'!Z12 | AA14: ='BK P&L'!AA33+'CC P&L'!AA33+'DN P&L'!AA33+'LF P&L'!AA33+'MR P&L'!AA33+'OP P&L'!AA33+'PH P&L'!AA33+'RH P&L'!AA33+'SB P&L'!AA33+'SM P&L'!AA33+'WP P&L'!AA33+'WW P&L'!AA33+'HO P&L'!AA12 | AB14: ='BK P&L'!AB33+'CC P&L'!AB33+'DN P&L'!AB33+'LF P&L'!AB33+'MR P&L'!AB33+'OP P&L'!AB33+'PH P&L'!AB33+'RH P&L'!AB33+'SB P&L'!AB33+'SM P&L'!AB33+'WP P&L'!AB33+'WW P&L'!AB33+'HO P&L'!AB12 | ... AY14: ='BK P&L'!AY33+'CC P&L'!AY33+'DN P&L'!AY33+'LF P&L'!AY33+'MR P&L'!AY33+'OP P&L'!AY33+'PH P&L'!AY33+'RH P&L'!AY33+'SB P&L'!AY33+'SM P&L'!AY33+'WP P&L'!AY33+'WW P&L'!AY33+'HO P&L'!AY12
