Workbook

Sheet Company Prepared Model>>>

Sheet Sources and Uses
B2: NOTE: Model assumes transaction closes on Sept 1, 2026
B4: Entry Valuation
B6: EBITDA Multiple | C6: 5.5
B7: LTM May 2026 Studio Level EBITDA | C7: =SUM(Summary!BF23:BF34)
B8: Pre Money TEV | C8: =C7*C6
B10: Sources and Uses
B11: Uses
B12: Pre Money TEV | C12: =C8
B13: Existing Debt Paydown (at August 2026) | C13: ='Cash, Debt & Equity'!W26
B14: Cash on balance sheet for working capital, studio buildouts, etc. | C14: =C17-SUM(C12,C16,C15,C13)
B15: Legal Fees | C15: 50000
B16: Financing Fees (2% of raise) | C16: =D16*C20 | D16: 0.02 | E16: <<< Fee
B17: Total Uses | C17: =C22
B19: Sources
B20: New Debt (leasehold, certain amount covers losses) | C20: 1500000 | D20: 0.1 | E20: <<< Cash Interest, paid monthly
B21: Management Rollover | C21: =C12
B22: Total Uses | C22: =SUM(C20:C21)
B24: Debt Service Coverage Metrics
C25: LTM May 2026 | D25: 2026 | E25: =D25+1 | F25: =E25+1
B26: ='Cash Flow Forecast'!B55 | C26: ='Cash Flow Forecast'!BF55 | D26: ='Cash Flow Forecast'!BB55 | E26: ='Cash Flow Forecast'!BC55 | F26: ='Cash Flow Forecast'!BD55
B27: ='Cash Flow Forecast'!B56 | C27: ='Cash Flow Forecast'!BF56 | D27: ='Cash Flow Forecast'!BB56 | E27: ='Cash Flow Forecast'!BC56 | F27: ='Cash Flow Forecast'!BD56
B28: ='Cash Flow Forecast'!B57 | C28: ='Cash Flow Forecast'!BF57 | D28: ='Cash Flow Forecast'!BB57 | E28: ='Cash Flow Forecast'!BC57 | F28: ='Cash Flow Forecast'!BD57
B29: ='Cash Flow Forecast'!B58 | C29: ='Cash Flow Forecast'!BF58 | D29: =IFERROR('Cash Flow Forecast'!BB58,"NA") | E29: ='Cash Flow Forecast'!BC58 | F29: ='Cash Flow Forecast'!BD58

Sheet Cover
B2: Mighty Pilates
B3: Financial Model
B5: Last refreshed: June 23, 2026
B7: Tab Guide
B9: Summary & Controls | C9: Top-level KPIs, studio sales & EBITDA tables, charts
B10: Assumptions | C10: All model inputs: OpEx, sales forecast, rev rec curves, loan terms
B11: Cash Flow Forecast | C11: Monthly cash flow from operations + investing + financing
B12: P&L Summary | C12: Consolidated monthly P&L (Revenue → EBITDA)
B13: P&L Detail | C13: Account-level P&L matching accountant chart of accounts
B14: All Studios Summary | C14: Side-by-side studio comparison
B15: [Studio] FCST (×12) | C15: Per-studio P&L forecast (BK, CC, DN, LF, MR, OP, PH, RH, SB, SM, WP, WW)
B16: Cash, Debt & Equity | C16: Balance sheet, loan amortization schedules, equity tracking
B17: Sales Forecast | C17: Studio × month editable sales grid
B18: CapEx | C18: Capital expenditure project schedule
B19: QBO Actuals | C19: Historical accountant-booked P&L, BS, SCF (read-only)
B22: Conventions
B24: Yellow cells = inputs (edit these)
B25: Light green cells = actuals (closed months, do not edit)

Sheet Read Me
B2: Read Me — Model Architecture
B3: Last refreshed: June 23, 2026
B5: Tab Roles
B6: Summary & Controls | C6: Top-level dashboard. Sales + EBITDA by studio. Total EBITDA references P&L NOI directly.
B7: Assumptions | C7: Editable global parameters: rev rec curves, refund/discount/COGS rates, escalations, loan terms.
B8: Sales Forecast | C8: Per-studio × month sales grid. EDITABLE for forecast months (yellow). Drives revenue formulas. Hidden rows 101-113 hold 2025 history for lag formulas — do not delete.
B9: Cash, Debt & Equity | C9: Loan amortization schedule + debt service forecast.
B10: Cash Flow Forecast | C10: Monthly CF with operating/investing/financing.
B11: P&L (Consolidated) | C11: Consolidated monthly P&L. Revenue/COGS use direct lag formulas (with 2025 history). OpEx rows = SUM(per-studio) + HO + HO Other.
B12: All Studios Summary | C12: Side-by-side studio comparison.
B13: [Code] P&L (×12) | C13: Per-studio P&L: BK, CC, DN, LF, MR, OP, PH, RH, SB, SM, WP, WW. OpEx leaves are HARDCODED values (editable) summing to per-studio override. Revenue formulas use per-studio lag (2026+ from Sales Forecast, 2025 from hidden helper rows 102-113).
B14: HO P&L | C14: Head Office overhead (no revenue). Same leaf-summing structure. NOI is negative (= -Total OpEx).
B15: CapEx | C15: Project schedule (empty — add projects to populate Investing rows on CF).
B16: QBO Actuals | C16: Raw accountant-booked P&L/BS/SCF data. Read-only reference.
B18: Cell Conventions
B19: Yellow fill (FFFF99) | C19: EDITABLE input cell. Cat can change these.
B20: Light green fill | C20: Hardcoded actual from QBO/accountant. Do not edit (would diverge from source data).
B21: White/no fill | C21: Formula cell. Computed from other cells.
B22: Light blue fill | C22: Subtotal or total row.
B23: Bold green fill | C23: Key KPI (EBITDA, ending cash).
B25: Value Flow
B26: Sales edit | C26: Edit Sales Forecast cell → flows to: Studio P&L Sessions/Breakage (via lag formula) → Studio NOI → Summary & Controls studio row → Sales Forecast TOTAL row → Consolidated P&L revenue → Consolidated NOI → Summary & Controls Total EBITDA.
B27: OpEx leaf edit | C27: Edit per-studio OpEx leaf (e.g., BK Paid Ads) → Studio Marketing subtotal (=SUM leaves) → Studio Total OpEx → Studio NOI → Summary & Controls studio row → Consolidated P&L Marketing (=SUM studios + HO) → Consolidated Total OpEx → Consolidated NOI → Summary & Controls Total EBITDA. Full propagation works.
B28: Assumption edit | C28: Edit rate on Assumptions tab (refund %, discount %, escalation, etc.) → flows through all formulas referencing that cell.
B30: Hidden Helpers — DO NOT DELETE
B31: Sales Forecast rows 100-113 | C31: Hidden helper rows holding 2025 monthly sales (consolidated row 101 and per-studio rows 102-113). Required for 7-month lag formulas on Session/Breakage Revenue forecasts for May 2026 and Jun 2026.
B32: Sales Forecast row ~50+ | C32: Helper for chart data references on Summary & Controls. Removing breaks charts.
B34: Monthly Update Procedure (when QBO closes new month)
B35: Step 1 | C35: Upload new QBO export to Streamlit dashboard. Streamlit's committed_actuals.json gets updated.
B36: Step 2 | C36: Run refresh_from_streamlit.py (in /Users/chandlerclemons/financial-modeling/models/mighty/).
B37: Step 3 | C37: Refresh script will: (a) extend actuals columns by 1 month, (b) shift forecast forward, (c) refresh trailing-3-month avg lines (Taxes Paid, Property Taxes, Retail, Depreciation), (d) update 2025 helper row values if Streamlit data changed historicals.
B38: Step 4 | C38: Open the Excel and spot-check the new actuals column vs Streamlit. Save & share with stakeholders.
B40: Streamlit Source Repo
B41: GitHub | C41: github.com/c-clemons/mighty-pilates (private)
B42: Live app | C42: mighty-pilates-financial-model.streamlit.app
B43: Local files | C43: /Users/chandlerclemons/mighty-pilates/dashboard/data/
B45: Cash Sales vs Accrual Revenue
B46: Sales Forecast / Summary | C46: These tabs show CASH SALES: Total Sales captured at the MindBody point-of-sale when a member buys a class pack, membership, or workshop.
B47: Studio P&L / All Studios | C47: These tabs show ACCRUAL P&L REVENUE: Sessions recognized over the package usage window + Breakage when unused packages expire − Refunds − Discounts.
B48: Worked example | C48: Berkeley Dec 2028: Cash Sales $164K, Accrual Revenue $140K. The $24K gap = packages sold in Dec 2028 that will be USED (or breakage'd) in later months.
...

Sheet Summary
B2: Summary & Controls
B3: Top-level dashboard. Studio sales, EBITDA, YoY summary, charts.
B4: Monthly Total Session Sales by Studio
B5: Metric | C5: Studio | D5: Jan 2025 (A) | E5: Feb 2025 (A) | F5: Mar 2025 (A) | G5: Apr 2025 (A) | H5: May 2025 (A) | I5: Jun 2025 (A) | J5: Jul 2025 (A) | K5: Aug 2025 (A) | L5: Sep 2025 (A) | M5: Oct 2025 (A) | N5: Nov 2025 (A) | O5: Dec 2025 (A) | P5: Jan 2026 (A) | Q5: Feb 2026 (A) | R5: Mar 2026 (A) | S5: Apr 2026 (A) | T5: May 2026 (A) | U5: Jun 2026 | V5: Jul 2026 | W5: Aug 2026 | X5: Sep 2026 | Y5: Oct 2026 | Z5: Nov 2026 | AA5: Dec 2026 | AB5: Jan 2027 | AC5: Feb 2027 | AD5: Mar 2027 | AE5: Apr 2027 | AF5: May 2027 | AG5: Jun 2027 | AH5: Jul 2027 | AI5: Aug 2027 | AJ5: Sep 2027 | AK5: Oct 2027 | AL5: Nov 2027 | AM5: Dec 2027 | AN5: Jan 2028 | AO5: Feb 2028 | AP5: Mar 2028 | AQ5: Apr 2028 | AR5: May 2028 | AS5: Jun 2028 | AT5: Jul 2028 | AU5: Aug 2028 | AV5: Sep 2028 | AW5: Oct 2028 | AX5: Nov 2028 | AY5: Dec 2028 | BA5: 2025 | BB5: =BA5+1 | BC5: =BB5+1 | BD5: =BC5+1 | BF5: LTM May 2026
B6: Total Sales | D6: =SUM(D7:D19) | E6: =SUM(E7:E19) | F6: =SUM(F7:F19) | G6: =SUM(G7:G19) | H6: =SUM(H7:H19) | I6: =SUM(I7:I19) | J6: =SUM(J7:J19) | K6: =SUM(K7:K19) | ... AY6: =SUM(AY7:AY19) | BA6: =SUM(D6:O6) | BB6: =SUM(P6:AA6) | BC6: =SUM(AB6:AM6) | BD6: =SUM(AN6:AY6) | BF6: =SUM(I6:T6) | BH6: =SUM(BA6:BD6)-SUM(D6:AY6)
C7: Berkeley | D7: ='Sales Forecast'!D6 | E7: ='Sales Forecast'!E6 | F7: ='Sales Forecast'!F6 | G7: ='Sales Forecast'!G6 | H7: ='Sales Forecast'!H6 | I7: ='Sales Forecast'!I6 | J7: ='Sales Forecast'!J6 | K7: ='Sales Forecast'!K6 | ... AY7: ='Sales Forecast'!AY6 | BA7: =SUM(D7:O7) | BB7: =SUM(P7:AA7) | BC7: =SUM(AB7:AM7) | BD7: =SUM(AN7:AY7) | BF7: =SUM(I7:T7) | BH7: =SUM(BA7:BD7)-SUM(D7:AY7)
C8: Culver City | D8: ='Sales Forecast'!D7 | E8: ='Sales Forecast'!E7 | F8: ='Sales Forecast'!F7 | G8: ='Sales Forecast'!G7 | H8: ='Sales Forecast'!H7 | I8: ='Sales Forecast'!I7 | J8: ='Sales Forecast'!J7 | K8: ='Sales Forecast'!K7 | ... AY8: ='Sales Forecast'!AY7 | BA8: =SUM(D8:O8) | BB8: =SUM(P8:AA8) | BC8: =SUM(AB8:AM8) | BD8: =SUM(AN8:AY8) | BF8: =SUM(I8:T8) | BH8: =SUM(BA8:BD8)-SUM(D8:AY8)
C9: Danville | D9: ='Sales Forecast'!D8 | E9: ='Sales Forecast'!E8 | F9: ='Sales Forecast'!F8 | G9: ='Sales Forecast'!G8 | H9: ='Sales Forecast'!H8 | I9: ='Sales Forecast'!I8 | J9: ='Sales Forecast'!J8 | K9: ='Sales Forecast'!K8 | ... AY9: ='Sales Forecast'!AY8 | BA9: =SUM(D9:O9) | BB9: =SUM(P9:AA9) | BC9: =SUM(AB9:AM9) | BD9: =SUM(AN9:AY9) | BF9: =SUM(I9:T9) | BH9: =SUM(BA9:BD9)-SUM(D9:AY9)
C10: Lafayette | D10: ='Sales Forecast'!D9 | E10: ='Sales Forecast'!E9 | F10: ='Sales Forecast'!F9 | G10: ='Sales Forecast'!G9 | H10: ='Sales Forecast'!H9 | I10: ='Sales Forecast'!I9 | J10: ='Sales Forecast'!J9 | K10: ='Sales Forecast'!K9 | ... AY10: ='Sales Forecast'!AY9 | BA10: =SUM(D10:O10) | BB10: =SUM(P10:AA10) | BC10: =SUM(AB10:AM10) | BD10: =SUM(AN10:AY10) | BF10: =SUM(I10:T10) | BH10: =SUM(BA10:BD10)-SUM(D10:AY10)
C11: Marin | D11: ='Sales Forecast'!D10 | E11: ='Sales Forecast'!E10 | F11: ='Sales Forecast'!F10 | G11: ='Sales Forecast'!G10 | H11: ='Sales Forecast'!H10 | I11: ='Sales Forecast'!I10 | J11: ='Sales Forecast'!J10 | K11: ='Sales Forecast'!K10 | ... AY11: ='Sales Forecast'!AY10 | BA11: =SUM(D11:O11) | BB11: =SUM(P11:AA11) | BC11: =SUM(AB11:AM11) | BD11: =SUM(AN11:AY11) | BF11: =SUM(I11:T11) | BH11: =SUM(BA11:BD11)-SUM(D11:AY11)
C12: Ocean Park | D12: ='Sales Forecast'!D11 | E12: ='Sales Forecast'!E11 | F12: ='Sales Forecast'!F11 | G12: ='Sales Forecast'!G11 | H12: ='Sales Forecast'!H11 | I12: ='Sales Forecast'!I11 | J12: ='Sales Forecast'!J11 | K12: ='Sales Forecast'!K11 | ... AY12: ='Sales Forecast'!AY11 | BA12: =SUM(D12:O12) | BB12: =SUM(P12:AA12) | BC12: =SUM(AB12:AM12) | BD12: =SUM(AN12:AY12) | BF12: =SUM(I12:T12) | BH12: =SUM(BA12:BD12)-SUM(D12:AY12)
C13: Presidio Heights | D13: ='Sales Forecast'!D12 | E13: ='Sales Forecast'!E12 | F13: ='Sales Forecast'!F12 | G13: ='Sales Forecast'!G12 | H13: ='Sales Forecast'!H12 | I13: ='Sales Forecast'!I12 | J13: ='Sales Forecast'!J12 | K13: ='Sales Forecast'!K12 | ... AY13: ='Sales Forecast'!AY12 | BA13: =SUM(D13:O13) | BB13: =SUM(P13:AA13) | BC13: =SUM(AB13:AM13) | BD13: =SUM(AN13:AY13) | BF13: =SUM(I13:T13) | BH13: =SUM(BA13:BD13)-SUM(D13:AY13)
C14: Russian Hill | D14: ='Sales Forecast'!D13 | E14: ='Sales Forecast'!E13 | F14: ='Sales Forecast'!F13 | G14: ='Sales Forecast'!G13 | H14: ='Sales Forecast'!H13 | I14: ='Sales Forecast'!I13 | J14: ='Sales Forecast'!J13 | K14: ='Sales Forecast'!K13 | ... AY14: ='Sales Forecast'!AY13 | BA14: =SUM(D14:O14) | BB14: =SUM(P14:AA14) | BC14: =SUM(AB14:AM14) | BD14: =SUM(AN14:AY14) | BF14: =SUM(I14:T14) | BH14: =SUM(BA14:BD14)-SUM(D14:AY14)
C15: Santa Barbara | D15: ='Sales Forecast'!D14 | E15: ='Sales Forecast'!E14 | F15: ='Sales Forecast'!F14 | G15: ='Sales Forecast'!G14 | H15: ='Sales Forecast'!H14 | I15: ='Sales Forecast'!I14 | J15: ='Sales Forecast'!J14 | K15: ='Sales Forecast'!K14 | ... AY15: ='Sales Forecast'!AY14 | BA15: =SUM(D15:O15) | BB15: =SUM(P15:AA15) | BC15: =SUM(AB15:AM15) | BD15: =SUM(AN15:AY15) | BF15: =SUM(I15:T15) | BH15: =SUM(BA15:BD15)-SUM(D15:AY15)
C16: Santa Monica | D16: ='Sales Forecast'!D15 | E16: ='Sales Forecast'!E15 | F16: ='Sales Forecast'!F15 | G16: ='Sales Forecast'!G15 | H16: ='Sales Forecast'!H15 | I16: ='Sales Forecast'!I15 | J16: ='Sales Forecast'!J15 | K16: ='Sales Forecast'!K15 | ... AY16: ='Sales Forecast'!AY15 | BA16: =SUM(D16:O16) | BB16: =SUM(P16:AA16) | BC16: =SUM(AB16:AM16) | BD16: =SUM(AN16:AY16) | BF16: =SUM(I16:T16) | BH16: =SUM(BA16:BD16)-SUM(D16:AY16)
C17: West Portal | D17: ='Sales Forecast'!D16 | E17: ='Sales Forecast'!E16 | F17: ='Sales Forecast'!F16 | G17: ='Sales Forecast'!G16 | H17: ='Sales Forecast'!H16 | I17: ='Sales Forecast'!I16 | J17: ='Sales Forecast'!J16 | K17: ='Sales Forecast'!K16 | ... AY17: ='Sales Forecast'!AY16 | BA17: =SUM(D17:O17) | BB17: =SUM(P17:AA17) | BC17: =SUM(AB17:AM17) | BD17: =SUM(AN17:AY17) | BF17: =SUM(I17:T17) | BH17: =SUM(BA17:BD17)-SUM(D17:AY17)
C18: Westwood | D18: ='Sales Forecast'!D17 | E18: ='Sales Forecast'!E17 | F18: ='Sales Forecast'!F17 | G18: ='Sales Forecast'!G17 | H18: ='Sales Forecast'!H17 | I18: ='Sales Forecast'!I17 | J18: ='Sales Forecast'!J17 | K18: ='Sales Forecast'!K17 | ... AY18: ='Sales Forecast'!AY17 | BA18: =SUM(D18:O18) | BB18: =SUM(P18:AA18) | BC18: =SUM(AB18:AM18) | BD18: =SUM(AN18:AY18) | BF18: =SUM(I18:T18) | BH18: =SUM(BA18:BD18)-SUM(D18:AY18)
C19: Head Office | D19: 0 | E19: 0 | F19: 0 | G19: 0 | H19: 0 | I19: 0 | J19: 0 | K19: 0 | L19: 0 | M19: 0 | N19: 0 | O19: 0 | P19: 0 | Q19: 0 | R19: 0 | S19: 0 | T19: 0 | U19: 0 | V19: 0 | W19: 0 | X19: 0 | Y19: 0 | Z19: 0 | AA19: 0 | AB19: 0 | AC19: 0 | AD19: 0 | AE19: 0 | AF19: 0 | AG19: 0 | AH19: 0 | AI19: 0 | AJ19: 0 | AK19: 0 | AL19: 0 | AM19: 0 | AN19: 0 | AO19: 0 | AP19: 0 | AQ19: 0 | AR19: 0 | AS19: 0 | AT19: 0 | AU19: 0 | AV19: 0 | AW19: 0 | AX19: 0 | AY19: 0 | BA19: =SUM(D19:O19) | BB19: =SUM(P19:AA19) | BC19: =SUM(AB19:AM19) | BD19: =SUM(AN19:AY19) | BF19: =SUM(I19:T19) | BH19: =SUM(BA19:BD19)-SUM(D19:AY19)
B21: Monthly EBITDA by Studio
B22: Total EBITDA | D22: =SUM(D23:D35) | E22: =SUM(E23:E35) | F22: =SUM(F23:F35) | G22: =SUM(G23:G35) | H22: =SUM(H23:H35) | I22: =SUM(I23:I35) | J22: =SUM(J23:J35) | K22: =SUM(K23:K35) | ... AY22: =SUM(AY23:AY35) | BA22: =SUM(D22:O22) | BB22: =SUM(P22:AA22) | BC22: =SUM(AB22:AM22) | BD22: =SUM(AN22:AY22) | BF22: =SUM(I22:T22) | BH22: =SUM(BA22:BD22)-SUM(D22:AY22)
C23: Berkeley | D23: ='BK P&L'!D63 | E23: ='BK P&L'!E63 | F23: ='BK P&L'!F63 | G23: ='BK P&L'!G63 | H23: ='BK P&L'!H63 | I23: ='BK P&L'!I63 | J23: ='BK P&L'!J63 | K23: ='BK P&L'!K63 | ... AY23: ='BK P&L'!AY63 | BA23: =SUM(D23:O23) | BB23: =SUM(P23:AA23) | BC23: =SUM(AB23:AM23) | BD23: =SUM(AN23:AY23) | BF23: =SUM(I23:T23) | BH23: =SUM(BA23:BD23)-SUM(D23:AY23)
C24: Culver City | D24: ='CC P&L'!D63 | E24: ='CC P&L'!E63 | F24: ='CC P&L'!F63 | G24: ='CC P&L'!G63 | H24: ='CC P&L'!H63 | I24: ='CC P&L'!I63 | J24: ='CC P&L'!J63 | K24: ='CC P&L'!K63 | ... AY24: ='CC P&L'!AY63 | BA24: =SUM(D24:O24) | BB24: =SUM(P24:AA24) | BC24: =SUM(AB24:AM24) | BD24: =SUM(AN24:AY24) | BF24: =SUM(I24:T24) | BH24: =SUM(BA24:BD24)-SUM(D24:AY24)
C25: Danville | D25: ='DN P&L'!D63 | E25: ='DN P&L'!E63 | F25: ='DN P&L'!F63 | G25: ='DN P&L'!G63 | H25: ='DN P&L'!H63 | I25: ='DN P&L'!I63 | J25: ='DN P&L'!J63 | K25: ='DN P&L'!K63 | ... AY25: ='DN P&L'!AY63 | BA25: =SUM(D25:O25) | BB25: =SUM(P25:AA25) | BC25: =SUM(AB25:AM25) | BD25: =SUM(AN25:AY25) | BF25: =SUM(I25:T25) | BH25: =SUM(BA25:BD25)-SUM(D25:AY25)
C26: Lafayette | D26: ='LF P&L'!D63 | E26: ='LF P&L'!E63 | F26: ='LF P&L'!F63 | G26: ='LF P&L'!G63 | H26: ='LF P&L'!H63 | I26: ='LF P&L'!I63 | J26: ='LF P&L'!J63 | K26: ='LF P&L'!K63 | ... AY26: ='LF P&L'!AY63 | BA26: =SUM(D26:O26) | BB26: =SUM(P26:AA26) | BC26: =SUM(AB26:AM26) | BD26: =SUM(AN26:AY26) | BF26: =SUM(I26:T26) | BH26: =SUM(BA26:BD26)-SUM(D26:AY26)
C27: Marin | D27: ='MR P&L'!D63 | E27: ='MR P&L'!E63 | F27: ='MR P&L'!F63 | G27: ='MR P&L'!G63 | H27: ='MR P&L'!H63 | I27: ='MR P&L'!I63 | J27: ='MR P&L'!J63 | K27: ='MR P&L'!K63 | ... AY27: ='MR P&L'!AY63 | BA27: =SUM(D27:O27) | BB27: =SUM(P27:AA27) | BC27: =SUM(AB27:AM27) | BD27: =SUM(AN27:AY27) | BF27: =SUM(I27:T27) | BH27: =SUM(BA27:BD27)-SUM(D27:AY27)
C28: Ocean Park | D28: ='OP P&L'!D63 | E28: ='OP P&L'!E63 | F28: ='OP P&L'!F63 | G28: ='OP P&L'!G63 | H28: ='OP P&L'!H63 | I28: ='OP P&L'!I63 | J28: ='OP P&L'!J63 | K28: ='OP P&L'!K63 | ... AY28: ='OP P&L'!AY63 | BA28: =SUM(D28:O28) | BB28: =SUM(P28:AA28) | BC28: =SUM(AB28:AM28) | BD28: =SUM(AN28:AY28) | BF28: =SUM(I28:T28) | BH28: =SUM(BA28:BD28)-SUM(D28:AY28)
C29: Presidio Heights | D29: ='PH P&L'!D63 | E29: ='PH P&L'!E63 | F29: ='PH P&L'!F63 | G29: ='PH P&L'!G63 | H29: ='PH P&L'!H63 | I29: ='PH P&L'!I63 | J29: ='PH P&L'!J63 | K29: ='PH P&L'!K63 | ... AY29: ='PH P&L'!AY63 | BA29: =SUM(D29:O29) | BB29: =SUM(P29:AA29) | BC29: =SUM(AB29:AM29) | BD29: =SUM(AN29:AY29) | BF29: =SUM(I29:T29) | BH29: =SUM(BA29:BD29)-SUM(D29:AY29)
C30: Russian Hill | D30: ='RH P&L'!D63 | E30: ='RH P&L'!E63 | F30: ='RH P&L'!F63 | G30: ='RH P&L'!G63 | H30: ='RH P&L'!H63 | I30: ='RH P&L'!I63 | J30: ='RH P&L'!J63 | K30: ='RH P&L'!K63 | ... AY30: ='RH P&L'!AY63 | BA30: =SUM(D30:O30) | BB30: =SUM(P30:AA30) | BC30: =SUM(AB30:AM30) | BD30: =SUM(AN30:AY30) | BF30: =SUM(I30:T30) | BH30: =SUM(BA30:BD30)-SUM(D30:AY30)
C31: Santa Barbara | D31: ='SB P&L'!D63 | E31: ='SB P&L'!E63 | F31: ='SB P&L'!F63 | G31: ='SB P&L'!G63 | H31: ='SB P&L'!H63 | I31: ='SB P&L'!I63 | J31: ='SB P&L'!J63 | K31: ='SB P&L'!K63 | ... AY31: ='SB P&L'!AY63 | BA31: =SUM(D31:O31) | BB31: =SUM(P31:AA31) | BC31: =SUM(AB31:AM31) | BD31: =SUM(AN31:AY31) | BF31: =SUM(I31:T31) | BH31: =SUM(BA31:BD31)-SUM(D31:AY31)
C32: Santa Monica | D32: ='SM P&L'!D63 | E32: ='SM P&L'!E63 | F32: ='SM P&L'!F63 | G32: ='SM P&L'!G63 | H32: ='SM P&L'!H63 | I32: ='SM P&L'!I63 | J32: ='SM P&L'!J63 | K32: ='SM P&L'!K63 | ... AY32: ='SM P&L'!AY63 | BA32: =SUM(D32:O32) | BB32: =SUM(P32:AA32) | BC32: =SUM(AB32:AM32) | BD32: =SUM(AN32:AY32) | BF32: =SUM(I32:T32) | BH32: =SUM(BA32:BD32)-SUM(D32:AY32)
C33: West Portal | D33: ='WP P&L'!D63 | E33: ='WP P&L'!E63 | F33: ='WP P&L'!F63 | G33: ='WP P&L'!G63 | H33: ='WP P&L'!H63 | I33: ='WP P&L'!I63 | J33: ='WP P&L'!J63 | K33: ='WP P&L'!K63 | ... AY33: ='WP P&L'!AY63 | BA33: =SUM(D33:O33) | BB33: =SUM(P33:AA33) | BC33: =SUM(AB33:AM33) | BD33: =SUM(AN33:AY33) | BF33: =SUM(I33:T33) | BH33: =SUM(BA33:BD33)-SUM(D33:AY33)
C34: Westwood | D34: ='WW P&L'!D63 | E34: ='WW P&L'!E63 | F34: ='WW P&L'!F63 | G34: ='WW P&L'!G63 | H34: ='WW P&L'!H63 | I34: ='WW P&L'!I63 | J34: ='WW P&L'!J63 | K34: ='WW P&L'!K63 | ... AY34: ='WW P&L'!AY63 | BA34: =SUM(D34:O34) | BB34: =SUM(P34:AA34) | BC34: =SUM(AB34:AM34) | BD34: =SUM(AN34:AY34) | BF34: =SUM(I34:T34) | BH34: =SUM(BA34:BD34)-SUM(D34:AY34)
C35: Head Office | D35: ='HO P&L'!D36 | E35: ='HO P&L'!E36 | F35: ='HO P&L'!F36 | G35: ='HO P&L'!G36 | H35: ='HO P&L'!H36 | I35: ='HO P&L'!I36 | J35: ='HO P&L'!J36 | K35: ='HO P&L'!K36 | ... AY35: ='HO P&L'!AY36 | BA35: =SUM(D35:O35) | BB35: =SUM(P35:AA35) | BC35: =SUM(AB35:AM35) | BD35: =SUM(AN35:AY35) | BF35: =SUM(I35:T35) | BH35: =SUM(BA35:BD35)-SUM(D35:AY35)
B37: Studio Level EBITDA | D37: =SUM(D23:D34) | E37: =SUM(E23:E34) | F37: =SUM(F23:F34) | G37: =SUM(G23:G34) | H37: =SUM(H23:H34) | I37: =SUM(I23:I34) | J37: =SUM(J23:J34) | K37: =SUM(K23:K34) | ... AY37: =SUM(AY23:AY34) | BA37: =SUM(D37:O37) | BB37: =SUM(P37:AA37) | BC37: =SUM(AB37:AM37) | BD37: =SUM(AN37:AY37) | BF37: =SUM(I37:T37)
B38: Total Add Backs | D38: 28398.84 | E38: 52184.59 | F38: 34406.02 | G38: 20335.04 | H38: 25137.94 | I38: 86480.66 | J38: 13252.8 | K38: 38505.24 | L38: 73265.17 | M38: 67217.42 | N38: 91181.16 | O38: 46220.52 | P38: ='P&L'!P38 | Q38: ='P&L'!Q38 | R38: ='P&L'!R38 | S38: ='P&L'!S38 | T38: 16815.41 | U38: 25000 | V38: 25000 | W38: 25000 | X38: 70000 | Y38: 50000 | Z38: 20000 | AA38: 15000 | AB38: 15000 | AC38: 15000 | AD38: 15000 | AE38: 15000 | AF38: 15000 | AG38: 15000 | AH38: 15000 | AI38: 15000 | AJ38: 15000 | AK38: 15000 | AL38: 15000 | AM38: 15000 | AN38: 15000 | AO38: 15000 | AP38: 15000 | AQ38: 15000 | AR38: 15000 | AS38: 15000 | AT38: 15000 | AU38: 15000 | AV38: 15000 | AW38: 15000 | AX38: 15000 | AY38: 15000 | BA38: =SUM(D38:O38) | BB38: =SUM(P38:AA38) | BC38: =SUM(AB38:AM38) | BD38: =SUM(AN38:AY38) | BF38: =SUM(I38:T38) | BH38: =SUM(BA38:BD38)-SUM(D38:AY38)
B39: Total Adj-EBITDA | D39: =D22+D38 | E39: =E22+E38 | F39: =F22+F38 | G39: =G22+G38 | H39: =H22+H38 | I39: =I22+I38 | J39: =J22+J38 | K39: =K22+K38 | ... P39: =P22+P38 | Q39: ='P&L'!Q39 | R39: ='P&L'!R39 | S39: ='P&L'!S39 | T39: ='P&L'!T39 | U39: =U22+U38 | V39: =V22+V38 | W39: =W22+W38 | X39: =X22+X38 | Y39: =Y22+Y38 | Z39: =Z22+Z38 | AA39: =AA22+AA38 | AB39: =AB22+AB38 | ... AY39: =AY22+AY38 | BA39: =SUM(D39:O39) | BB39: =SUM(P39:AA39) | BC39: =SUM(AB39:AM39) | BD39: =SUM(AN39:AY39) | BF39: =SUM(I39:T39) | BH39: =SUM(BA39:BD39)-SUM(D39:AY39)
B41: Annual Summary
B42: Metric | C42: Studio | D42: 2025 | E42: 2026 | F42: 2027 | G42: 2028 | H42: 2026 YoY | I42: 2027 YoY | J42: 2028 YoY
B43: Total Sales | D43: =SUM(D44:D56) | E43: =SUM(E44:E56) | F43: =SUM(F44:F56) | G43: =SUM(G44:G56) | H43: =IFERROR((E43-D43)/D43,0) | I43: =IFERROR((F43-E43)/E43,0) | J43: =IFERROR((G43-F43)/F43,0)
C44: Berkeley | D44: =SUM('Sales Forecast'!D6:O6) | E44: =SUM('Sales Forecast'!P6:AA6) | F44: =SUM('Sales Forecast'!AB6:AM6) | G44: =SUM('Sales Forecast'!AN6:AY6) | H44: =IFERROR((E42-D42)/D42,0) | I44: =IFERROR((F42-E42)/E42,0) | J44: =IFERROR((G42-F42)/F42,0)
...

Sheet Assumptions
B2: Assumptions
B3: Yellow cells are editable inputs. All other tabs reference these values.
B5: 1. Model Control
B6: Last Actuals Month | C6: May 2026
B7: Forecast Horizon (months) | C7: 32
B8: Forecast End Month | C8: Dec 2028
B10: 2. Revenue Recognition Curves
B11: Lag Month (0 = sale month) | C11: 0 | D11: 1 | E11: 2 | F11: 3 | G11: 4 | H11: 5 | I11: 6 | J11: Sum
B12: Earned % | C12: 0.3868 | D12: 0.2997 | E12: 0.0855 | F12: 0.0482 | G12: 0.0261 | H12: 0.0193 | I12: 0.0144 | J12: =SUM(C12:I12)
B13: Breakage % | C13: 0.0017 | D13: 0.0602 | E13: 0.0053 | F13: 0.0003 | G13: 0.0001 | H13: 0.0008 | I13: 0.0516 | J13: =SUM(C13:I13)
B14: Total (Earned + Breakage) | C14: =C12+C13 | D14: =D12+D13 | E14: =E12+E13 | F14: =F12+F13 | G14: =G12+G13 | H14: =H12+H13 | I14: =I12+I13 | J14: =SUM(C14:I14)
B16: 3. Rates (% of Gross Revenue)
B17: Refund Rate | C17: -0.0158 | D17: Refunds as % of gross revenue. Negative reduces net revenue.
B18: Discount Rate | C18: -0.0531 | D18: Discounts as % of gross revenue. Negative reduces net revenue.
B19: Merchant Fee % | C19: 0.0286 | D19: Payment processor fees as % of revenue.
B20: COGS % | C20: 0.0096 | D20: Cost of goods sold as % of revenue (retail).
B22: 4. Annual Escalation Rates
B23: Rent / Property Escalation | C23: 0.03 | D23: 3% annual rent step-up applied to forecast months
B24: Other OpEx Escalation | C24: 0.04 | D24: 4% annual escalation for all non-rent OpEx categories
B25: Sales YoY Growth | C25: 0.05 | D25: 5% YoY assumed for 2028 (applied to 2027 seasonal pattern)
B27: 5. Loan Terms (as of Apr 2026)
B28: Loan | C28: Original Amt | D28: Current Balance | E28: Rate (Annual) | F28: Avg Monthly Pmt | G28: Start Date | H28: Type
B29: MindBody Loan - SM | C29: 193706.66 | D29: 99348.21 | E29: 0 | F29: 18871.69 | G29: 2025-09 | H29: Amortizing
B30: MindBody Loan - PH | C30: 130000 | D30: 46989.79 | E30: 0 | F30: 16602.04 | G30: 2025-09 | H30: Amortizing
B31: MindBody Loan - LF | C31: 69249.28 | D31: 20599.85 | E31: 0 | F31: 12162.36 | G31: 2025-10 | H31: Amortizing
B32: MindBody Loan - MR | C32: 67443.81 | D32: 14815.18 | E32: 0 | F32: 13157.16 | G32: 2025-10 | H32: Amortizing
B33: Samson Loan | C33: 265414.78 | D33: 189034.12 | E33: 0 | F33: 25460.22 | G33: 2025-11 | H33: Amortizing
B34: Specialty Capital Loan | C34: 217184.21 | D34: 165407.89 | E34: 0 | F34: 25888.16 | G34: 2025-12 | H34: Amortizing
B35: Norbrook Inc Loan | C35: 162318 | D35: 162318 | E35: 0.08 | F35: 0 | G35: 2025-10 | H35: Interest-Only
B36: TOTAL DEBT | D36: =SUM(D29:D35) | F36: =SUM(F29:F35)
B38: 6. Active Studios
B39: Code | C39: Name
B40: BK | C40: Berkeley
B41: CC | C41: Culver City
B42: DN | C42: Danville
B43: LF | C43: Lafayette
B44: MR | C44: Marin
B45: OP | C45: Ocean Park
B46: PH | C46: Presidio Heights
B47: RH | C47: Russian Hill
...

Sheet Sales Forecast
B2: Sales Forecast (Gross)
B3: Jan-May 2026 actuals (locked, Cat-authoritative). Jun 2026 onwards forecast (editable).
B4: Per-Studio Monthly Sales
B5: Code | C5: Studio | D5: Jan 2025 | E5: Feb 2025 | F5: Mar 2025 | G5: Apr 2025 | H5: May 2025 | I5: Jun 2025 | J5: Jul 2025 | K5: Aug 2025 | L5: Sep 2025 | M5: Oct 2025 | N5: Nov 2025 | O5: Dec 2025 | P5: Jan 2026 | Q5: Feb 2026 | R5: Mar 2026 | S5: Apr 2026 | T5: 46143 | U5: Jun 2026 | V5: Jul 2026 | W5: Aug 2026 | X5: Sep 2026 | Y5: Oct 2026 | Z5: Nov 2026 | AA5: Dec 2026 | AB5: Jan 2027 | AC5: Feb 2027 | AD5: Mar 2027 | AE5: Apr 2027 | AF5: May 2027 | AG5: Jun 2027 | AH5: Jul 2027 | AI5: Aug 2027 | AJ5: Sep 2027 | AK5: Oct 2027 | AL5: Nov 2027 | AM5: Dec 2027 | AN5: Jan 2028 | AO5: Feb 2028 | AP5: Mar 2028 | AQ5: Apr 2028 | AR5: May 2028 | AS5: Jun 2028 | AT5: Jul 2028 | AU5: Aug 2028 | AV5: Sep 2028 | AW5: Oct 2028 | AX5: Nov 2028 | AY5: Dec 2028
B6: BK | C6: Berkeley | D6: 122672 | E6: 124750 | F6: 112908 | G6: 140814 | H6: 111061 | I6: 107458 | J6: 101618 | K6: 142373 | L6: 101097 | M6: 115965 | N6: 101860 | O6: 99707 | P6: 124393 | Q6: 129377 | R6: 103159 | S6: 136117 | T6: 83273 | U6: 110000 | V6: 105000 | W6: 120000 | X6: 120000 | Y6: 130000 | Z6: 130000 | AA6: 149000 | AB6: 130612.65 | AC6: 135845.85 | AD6: 108316.95 | AE6: 142922.85 | AF6: 87649.8 | AG6: 115500 | AH6: 110250 | AI6: 126000 | AJ6: 126000 | AK6: 136500 | AL6: 136500 | AM6: 156450 | AN6: 137143.28 | AO6: 142638.14 | AP6: 113732.8 | AQ6: 150068.99 | AR6: 92032.29 | AS6: 121275 | AT6: 115762.5 | AU6: 132300 | AV6: 132300 | AW6: 143325 | AX6: 143325 | AY6: 164272.5
B7: CC | C7: Culver City | D7: 0 | E7: 0 | F7: 0 | G7: 0 | H7: 0 | I7: 0 | J7: 0 | K7: 0 | L7: 16118 | M7: 31030 | N7: 31622 | O7: 31310 | P7: 43840 | Q7: 38704 | R7: 42619 | S7: 39690 | T7: 43327 | U7: 52000 | V7: 59000 | W7: 50000 | X7: 53000 | Y7: 60000 | Z7: 64000 | AA7: 60000 | AB7: 61000 | AC7: 73307 | AD7: 69238 | AE7: 75096 | AF7: 70949 | AG7: 64231 | AH7: 95489 | AI7: 107456 | AJ7: 102425 | AK7: 95000 | AL7: 95000 | AM7: 95000 | AN7: 64050 | AO7: 76972.35 | AP7: 72699.9 | AQ7: 78850.8 | AR7: 74496.45 | AS7: 67442.55 | AT7: 100263.45 | AU7: 112828.8 | AV7: 107546.25 | AW7: 99750 | AX7: 99750 | AY7: 99750
B8: DN | C8: Danville | D8: 0 | E8: 0 | F8: 0 | G8: 0 | H8: 0 | I8: 8385 | J8: 14789 | K8: 16531 | L8: 16660 | M8: 14843 | N8: 15819 | O8: 17950 | P8: 24286 | Q8: 23358 | R8: 20289 | S8: 20363 | T8: 15337 | U8: 20000 | V8: 20000 | W8: 25000 | X8: 25000 | Y8: 30000 | Z8: 25000 | AA8: 32000 | AB8: 32000 | AC8: 40000 | AD8: 40000 | AE8: 45000 | AF8: 45000 | AG8: 50000 | AH8: 50000 | AI8: 50000 | AJ8: 55000 | AK8: 55000 | AL8: 55000 | AM8: 55000 | AN8: 33600 | AO8: 42000 | AP8: 42000 | AQ8: 47250 | AR8: 47250 | AS8: 52500 | AT8: 52500 | AU8: 52500 | AV8: 57750 | AW8: 57750 | AX8: 57750 | AY8: 57750
B9: LF | C9: Lafayette | D9: 90025 | E9: 86822 | F9: 85300 | G9: 127703 | H9: 79380 | I9: 76768 | J9: 70767 | K9: 102739 | L9: 68837 | M9: 83777 | N9: 79979 | O9: 79880 | P9: 92365 | Q9: 126186 | R9: 78385 | S9: 106542 | T9: 71444 | U9: 80000 | V9: 80250 | W9: 80000 | X9: 80250 | Y9: 85000 | Z9: 95000 | AA9: 110000 | AB9: 96983.25 | AC9: 132495.3 | AD9: 82304.25 | AE9: 111869.1 | AF9: 75832.05 | AG9: 84000 | AH9: 84262.5 | AI9: 84000 | AJ9: 84262.5 | AK9: 89250 | AL9: 99750 | AM9: 115500 | AN9: 101832.41 | AO9: 139120.07 | AP9: 86419.46 | AQ9: 117462.56 | AR9: 79623.65 | AS9: 88200 | AT9: 88475.62 | AU9: 88200 | AV9: 88475.62 | AW9: 93712.5 | AX9: 104737.5 | AY9: 121275
B10: MR | C10: Marin | D10: 16838.6 | E10: 13867.046 | F10: 14508.233 | G10: 36538 | H10: 90956 | I10: 87668 | J10: 91349 | K10: 113973 | L10: 81190 | M10: 98516 | N10: 90001 | O10: 104919 | P10: 100589 | Q10: 114193 | R10: 90196 | S10: 140256 | T10: 74382 | U10: 96300 | V10: 95000 | W10: 120000 | X10: 98000 | Y10: 110000 | Z10: 120000 | AA10: 115000 | AB10: 105618.45 | AC10: 119902.65 | AD10: 94705.8 | AE10: 147268.8 | AF10: 78685.95 | AG10: 101115 | AH10: 99750 | AI10: 126000 | AJ10: 102900 | AK10: 115500 | AL10: 126000 | AM10: 120750 | AN10: 110899.37 | AO10: 125897.78 | AP10: 99441.09 | AQ10: 154632.24 | AR10: 82620.25 | AS10: 106170.75 | AT10: 104737.5 | AU10: 132300 | AV10: 108045 | AW10: 121275 | AX10: 132300 | AY10: 126787.5
B11: OP | C11: Ocean Park | D11: 0 | E11: 0 | F11: 0 | G11: 30025 | H11: 45379 | I11: 50782 | J11: 59231 | K11: 60132 | L11: 52754 | M11: 51670 | N11: 60236 | O11: 51621 | P11: 60583 | Q11: 59614 | R11: 62052 | S11: 73815 | T11: 63770 | U11: 64200 | V11: 75000 | W11: 60000 | X11: 63000 | Y11: 70000 | Z11: 75000 | AA11: 60000 | AB11: 63612.15 | AC11: 62594.7 | AD11: 65154.6 | AE11: 77505.75 | AF11: 67045.65 | AG11: 67410 | AH11: 78750 | AI11: 63000 | AJ11: 66150 | AK11: 73500 | AL11: 78750 | AM11: 63000 | AN11: 66792.76 | AO11: 65724.43 | AP11: 68412.33 | AQ11: 81381.04 | AR11: 70397.93 | AS11: 70780.5 | AT11: 82687.5 | AU11: 66150 | AV11: 69457.5 | AW11: 77175 | AX11: 82687.5 | AY11: 66150
B12: PH | C12: Presidio Heights | D12: 233958.4 | E12: 218217.95 | F12: 206588.77 | G12: 189694 | H12: 117239 | I12: 109486 | J12: 91214 | K12: 179728 | L12: 107500 | M12: 134780 | N12: 113334 | O12: 128126 | P12: 124927 | Q12: 180839 | R12: 115051 | S12: 179323 | T12: 93511 | U12: 115000 | V12: 110000 | W12: 155000 | X12: 120000 | Y12: 125000 | Z12: 140000 | AA12: 150000 | AB12: 131173.35 | AC12: 189880.95 | AD12: 120803.55 | AE12: 188289.15 | AF12: 100401 | AG12: 120750 | AH12: 115500 | AI12: 162750 | AJ12: 126000 | AK12: 131250 | AL12: 147000 | AM12: 157500 | AN12: 137732.02 | AO12: 199375 | AP12: 126843.73 | AQ12: 197703.61 | AR12: 105421.05 | AS12: 126787.5 | AT12: 121275 | AU12: 170887.5 | AV12: 132300 | AW12: 137812.5 | AX12: 154350 | AY12: 165375
B13: RH | C13: Russian Hill | D13: 0 | E13: 31933 | F13: 55412 | G13: 81989 | H13: 70953 | I13: 67470 | J13: 72141 | K13: 93312 | L13: 69913 | M13: 80685 | N13: 76340 | O13: 72252 | P13: 96145 | Q13: 94253 | R13: 85589 | S13: 108129 | T13: 66857 | U13: 77000 | V13: 75000 | W13: 95000 | X13: 80000 | Y13: 82000 | Z13: 80000 | AA13: 88000 | AB13: 100952.25 | AC13: 98965.65 | AD13: 89868.45 | AE13: 113535.45 | AF13: 71700.3 | AG13: 80850 | AH13: 78750 | AI13: 99750 | AJ13: 84000 | AK13: 86100 | AL13: 84000 | AM13: 92400 | AN13: 105999.86 | AO13: 103913.93 | AP13: 94361.87 | AQ13: 119212.22 | AR13: 75285.32 | AS13: 84892.5 | AT13: 82687.5 | AU13: 104737.5 | AV13: 88200 | AW13: 90405 | AX13: 88200 | AY13: 97020
B14: SB | C14: Santa Barbara | D14: 0 | E14: 0 | F14: 0 | G14: 0 | H14: 0 | I14: 0 | J14: 0 | K14: 0 | L14: 0 | M14: 0 | N14: 8231 | O14: 17514 | P14: 32747 | Q14: 27799 | R14: 25898 | S14: 23393 | T14: 20133 | U14: 25000 | V14: 25000 | W14: 30000 | X14: 30000 | Y14: 33000 | Z14: 35000 | AA14: 35000 | AB14: 59231 | AC14: 60132 | AD14: 52754 | AE14: 51670 | AF14: 60236 | AG14: 51621 | AH14: 62000 | AI14: 63000 | AJ14: 73000 | AK14: 65000 | AL14: 64200 | AM14: 64200 | AN14: 62192.55 | AO14: 63138.6 | AP14: 55391.7 | AQ14: 54253.5 | AR14: 63247.8 | AS14: 54202.05 | AT14: 65100 | AU14: 66150 | AV14: 76650 | AW14: 68250 | AX14: 67410 | AY14: 67410
B15: SM | C15: Santa Monica | D15: 143755 | E15: 203570 | F15: 268747 | G15: 164726 | H15: 193168 | I15: 169753 | J15: 231840 | K15: 162408 | L15: 176867 | M15: 154064 | N15: 188610 | O15: 178478 | P15: 184491 | Q15: 161597 | R15: 192258 | S15: 157521 | T15: 206632 | U15: 200000 | V15: 200000 | W15: 200000 | X15: 190000 | Y15: 220000 | Z15: 251450 | AA15: 190000 | AB15: 193715.55 | AC15: 169676.85 | AD15: 201870.9 | AE15: 165397.05 | AF15: 217676.55 | AG15: 210000 | AH15: 210000 | AI15: 210000 | AJ15: 199500 | AK15: 231000 | AL15: 264022.5 | AM15: 199500 | AN15: 203401.33 | AO15: 178160.69 | AP15: 211964.45 | AQ15: 173666.9 | AR15: 228560.38 | AS15: 220500 | AT15: 220500 | AU15: 220500 | AV15: 209475 | AW15: 242550 | AX15: 277223.62 | AY15: 209475
B16: WP | C16: West Portal | D16: 0 | E16: 0 | F16: 0 | G16: 0 | H16: 0 | I16: 0 | J16: 0 | K16: 0 | L16: 0 | M16: 0 | N16: 470 | O16: 4114 | P16: 1573 | Q16: 1513 | R16: 784 | S16: 370 | T16: 26 | U16: 40000 | V16: 70000 | W16: 78000 | X16: 75000 | Y16: 80000 | Z16: 80000 | AA16: 80000 | AB16: 90025 | AC16: 86822 | AD16: 85300 | AE16: 127703 | AF16: 79689 | AG16: 76768 | AH16: 70767 | AI16: 102739 | AJ16: 68837 | AK16: 83777 | AL16: 79979 | AM16: 79880 | AN16: 94526.25 | AO16: 91163.1 | AP16: 89565 | AQ16: 134088.15 | AR16: 83673.45 | AS16: 80606.4 | AT16: 74305.35 | AU16: 107875.95 | AV16: 72278.85 | AW16: 87965.85 | AX16: 83977.95 | AY16: 83874
B17: WW | C17: Westwood | D17: 71187 | E17: 96307 | F17: 93607 | G17: 77241 | H17: 90103 | I17: 75890 | J17: 75128 | K17: 59513 | L17: 67496 | M17: 64714 | N17: 67128 | O17: 61457 | P17: 71360 | Q17: 69405 | R17: 62992 | S17: 49441 | T17: 60750 | U17: 65000 | V17: 62000 | W17: 64000 | X17: 72000 | Y17: 80000 | Z17: 85600 | AA17: 74900 | AB17: 74928 | AC17: 72875.25 | AD17: 66141.6 | AE17: 51913.05 | AF17: 63897.75 | AG17: 68250 | AH17: 65100 | AI17: 67200 | AJ17: 75600 | AK17: 84000 | AL17: 89880 | AM17: 78645 | AN17: 78674.4 | AO17: 76519.01 | AP17: 69448.68 | AQ17: 54508.7 | AR17: 67092.64 | AS17: 71662.5 | AT17: 68355 | AU17: 70560 | AV17: 79380 | AW17: 88200 | AX17: 94374 | AY17: 82577.25
B18: TOTAL | C18: All Studios | D18: =SUM(D6:D17) | E18: =SUM(E6:E17) | F18: =SUM(F6:F17) | G18: =SUM(G6:G17) | H18: =SUM(H6:H17) | I18: =SUM(I6:I17) | J18: =SUM(J6:J17) | K18: =SUM(K6:K17) | ... AY18: =SUM(AY6:AY17)
B20: Annual Summary
B21: Code | C21: Studio | D21: 2025 | E21: 2026 | F21: 2027 | G21: 2028
B22: BK | C22: Berkeley | D22: =SUM(D6:O6) | E22: =SUM(P6:AA6) | F22: =SUM(AB6:AM6) | G22: =SUM(AN6:AY6)
B23: CC | C23: Culver City | D23: =SUM(D7:O7) | E23: =SUM(P7:AA7) | F23: =SUM(AB7:AM7) | G23: =SUM(AN7:AY7)
B24: DN | C24: Danville | D24: =SUM(D8:O8) | E24: =SUM(P8:AA8) | F24: =SUM(AB8:AM8) | G24: =SUM(AN8:AY8)
B25: LF | C25: Lafayette | D25: =SUM(D9:O9) | E25: =SUM(P9:AA9) | F25: =SUM(AB9:AM9) | G25: =SUM(AN9:AY9)
B26: MR | C26: Marin | D26: =SUM(D10:O10) | E26: =SUM(P10:AA10) | F26: =SUM(AB10:AM10) | G26: =SUM(AN10:AY10)
B27: OP | C27: Ocean Park | D27: =SUM(D11:O11) | E27: =SUM(P11:AA11) | F27: =SUM(AB11:AM11) | G27: =SUM(AN11:AY11)
B28: PH | C28: Presidio Heights | D28: =SUM(D12:O12) | E28: =SUM(P12:AA12) | F28: =SUM(AB12:AM12) | G28: =SUM(AN12:AY12)
B29: RH | C29: Russian Hill | D29: =SUM(D13:O13) | E29: =SUM(P13:AA13) | F29: =SUM(AB13:AM13) | G29: =SUM(AN13:AY13)
B30: SB | C30: Santa Barbara | D30: =SUM(D14:O14) | E30: =SUM(P14:AA14) | F30: =SUM(AB14:AM14) | G30: =SUM(AN14:AY14)
B31: SM | C31: Santa Monica | D31: =SUM(D15:O15) | E31: =SUM(P15:AA15) | F31: =SUM(AB15:AM15) | G31: =SUM(AN15:AY15)
B32: WP | C32: West Portal | D32: =SUM(D16:O16) | E32: =SUM(P16:AA16) | F32: =SUM(AB16:AM16) | G32: =SUM(AN16:AY16)
B33: WW | C33: Westwood | D33: =SUM(D17:O17) | E33: =SUM(P17:AA17) | F33: =SUM(AB17:AM17) | G33: =SUM(AN17:AY17)
B34: TOTAL | C34: All Studios | D34: =SUM(D22:D33) | E34: =SUM(E22:E33) | F34: =SUM(F22:F33) | G34: =SUM(G22:G33)
B100: 2025 SALES HISTORY (hidden helper for lag formulas) | P100: 2025-07 | Q100: 2025-08 | R100: 2025-09 | S100: 2025-10 | T100: 2025-11 | U100: 2025-12
P101: 808077 | Q101: 930709 | R101: 758432 | S101: 830044 | T101: 833160 | U101: 847328
B102: 2025 helper: BK (Berkeley) | T102: 102111.01 | U102: 103847.42
B103: 2025 helper: CC (Culver City) | T103: 36886.61 | U103: 37513.88
B104: 2025 helper: DN (Danville) | T104: 18359.97 | U104: 18672.19
B105: 2025 helper: LF (Lafayette) | T105: 84253.69 | U105: 85686.43
B106: 2025 helper: MR (Marin) | T106: 92130.72 | U106: 93697.42
B107: 2025 helper: OP (Ocean Park) | T107: 56662.27 | U107: 57625.82
...

Sheet Cash, Debt & Equity
B2: Cash, Debt & Equity
B4: Item | P4: Jan 2026 | Q4: Feb 2026 | R4: Mar 2026 | S4: Apr 2026 | T4: May 2026 | U4: Jun 2026 | V4: Jul 2026 | W4: Aug 2026 | X4: Sep 2026 | Y4: Oct 2026 | Z4: Nov 2026 | AA4: Dec 2026 | AB4: Jan 2027 | AC4: Feb 2027 | AD4: Mar 2027 | AE4: Apr 2027 | AF4: May 2027 | AG4: Jun 2027 | AH4: Jul 2027 | AI4: Aug 2027 | AJ4: Sep 2027 | AK4: Oct 2027 | AL4: Nov 2027 | AM4: Dec 2027 | AN4: Jan 2028 | AO4: Feb 2028 | AP4: Mar 2028 | AQ4: Apr 2028 | AR4: May 2028 | AS4: Jun 2028 | AT4: Jul 2028 | AU4: Aug 2028 | AV4: Sep 2028 | AW4: Oct 2028 | AX4: Nov 2028 | AY4: Dec 2028
B5: CASH POSITION | D5: Jan 2025 | E5: Feb 2025 | F5: Mar 2025 | G5: Apr 2025 | H5: May 2025 | I5: Jun 2025 | J5: Jul 2025 | K5: Aug 2025 | L5: Sep 2025 | M5: Oct 2025 | N5: Nov 2025 | O5: Dec 2025
B6: Ending Cash Balance (from CF) | P6: ='Cash Flow Forecast'!P40 | Q6: ='Cash Flow Forecast'!Q40 | R6: ='Cash Flow Forecast'!R40 | S6: ='Cash Flow Forecast'!S40 | T6: ='Cash Flow Forecast'!T40 | U6: ='Cash Flow Forecast'!U40 | V6: ='Cash Flow Forecast'!V40 | W6: ='Cash Flow Forecast'!W40 | ... AY6: ='Cash Flow Forecast'!AY40
B8: DEBT SCHEDULE — Loan Balances by Month
B9: MindBody Loan - SM | P9: 0 | Q9: 0 | R9: 0 | S9: 99348.21 | T9: 0 | U9: =MAX(T9-18871.69,0) | V9: =MAX(U9-18871.69,0) | W9: =MAX(V9-18871.69,0) | X9: =MAX(W9-18871.69,0) | Y9: =MAX(X9-18871.69,0) | Z9: =MAX(Y9-18871.69,0) | AA9: =MAX(Z9-18871.69,0) | AB9: =MAX(AA9-18871.69,0) | ... AY9: =MAX(AX9-18871.69,0)
B10: MindBody Loan - PH | P10: 0 | Q10: 0 | R10: 0 | S10: 46989.79 | T10: 0 | U10: =MAX(T10-16602.04,0) | V10: =MAX(U10-16602.04,0) | W10: =MAX(V10-16602.04,0) | X10: =MAX(W10-16602.04,0) | Y10: =MAX(X10-16602.04,0) | Z10: =MAX(Y10-16602.04,0) | AA10: =MAX(Z10-16602.04,0) | AB10: =MAX(AA10-16602.04,0) | ... AY10: =MAX(AX10-16602.04,0)
B11: MindBody Loan - LF | P11: 0 | Q11: 0 | R11: 0 | S11: 20599.85 | T11: 0 | U11: =MAX(T11-12162.36,0) | V11: =MAX(U11-12162.36,0) | W11: =MAX(V11-12162.36,0) | X11: =MAX(W11-12162.36,0) | Y11: =MAX(X11-12162.36,0) | Z11: =MAX(Y11-12162.36,0) | AA11: =MAX(Z11-12162.36,0) | AB11: =MAX(AA11-12162.36,0) | ... AY11: =MAX(AX11-12162.36,0)
B12: MindBody Loan - MR | P12: 0 | Q12: 0 | R12: 0 | S12: 14815.18 | T12: 0 | U12: =MAX(T12-13157.16,0) | V12: =MAX(U12-13157.16,0) | W12: =MAX(V12-13157.16,0) | X12: =MAX(W12-13157.16,0) | Y12: =MAX(X12-13157.16,0) | Z12: =MAX(Y12-13157.16,0) | AA12: =MAX(Z12-13157.16,0) | AB12: =MAX(AA12-13157.16,0) | ... AY12: =MAX(AX12-13157.16,0)
B13: Samson Loan | P13: 205426.16 | Q13: 189034.12 | R13: 154505.72 | S13: 129045.5 | T13: 94517.1 | U13: =MAX(T13-25460.22,0) | V13: =MAX(U13-25460.22,0) | W13: =MAX(V13-25460.22,0) | X13: =MAX(W13-25460.22,0) | Y13: =MAX(X13-25460.22,0) | Z13: =MAX(Y13-25460.22,0) | AA13: =MAX(Z13-25460.22,0) | AB13: =MAX(AA13-25460.22,0) | ... AY13: =MAX(AX13-25460.22,0)
B14: Specialty Capital Loan | P14: 187921.05 | Q14: 165407.89 | R14: 135078.94 | S14: 112565.78 | T14: 90052.62 | U14: =MAX(T14-25888.16,0) | V14: =MAX(U14-25888.16,0) | W14: =MAX(V14-25888.16,0) | X14: =MAX(W14-25888.16,0) | Y14: =MAX(X14-25888.16,0) | Z14: =MAX(Y14-25888.16,0) | AA14: =MAX(Z14-25888.16,0) | AB14: =MAX(AA14-25888.16,0) | ... AY14: =MAX(AX14-25888.16,0)
B15: Norbrook Inc Loan | P15: 0 | Q15: 0 | R15: 0 | S15: 162318 | T15: 0 | U15: =T15 | V15: =U15 | W15: =V15 | X15: =W15 | Y15: =X15 | Z15: =Y15 | AA15: =Z15 | AB15: =AA15 | ... AY15: =AX15
B16: TOTAL DEBT | P16: =SUM(P9:P15) | Q16: =SUM(Q9:Q15) | R16: =SUM(R9:R15) | S16: =SUM(S9:S15) | T16: =SUM(T9:T15) | U16: =SUM(U9:U15) | V16: =SUM(V9:V15) | W16: =SUM(W9:W15) | ... AY16: =SUM(AY9:AY15)
B18: MONTHLY DEBT SERVICE
B19: MindBody Loan - SM | P19: 0 | Q19: 0 | R19: 0 | S19: 0 | T19: 0 | U19: =IF(U9>0,18871.69,0) | V19: =IF(V9>0,18871.69,0) | W19: =IF(W9>0,18871.69,0) | X19: =IF(X9>0,18871.69,0) | Y19: =IF(Y9>0,18871.69,0) | Z19: =IF(Z9>0,18871.69,0) | AA19: =IF(AA9>0,18871.69,0) | AB19: =IF(AB9>0,18871.69,0) | ... AY19: =IF(AY9>0,18871.69,0)
B20: MindBody Loan - PH | P20: 0 | Q20: 0 | R20: 0 | S20: 0 | T20: 0 | U20: =IF(U10>0,16602.04,0) | V20: =IF(V10>0,16602.04,0) | W20: =IF(W10>0,16602.04,0) | X20: =IF(X10>0,16602.04,0) | Y20: =IF(Y10>0,16602.04,0) | Z20: =IF(Z10>0,16602.04,0) | AA20: =IF(AA10>0,16602.04,0) | AB20: =IF(AB10>0,16602.04,0) | ... AY20: =IF(AY10>0,16602.04,0)
B21: MindBody Loan - LF | P21: 0 | Q21: 0 | R21: 0 | S21: 0 | T21: 0 | U21: =IF(U11>0,12162.36,0) | V21: =IF(V11>0,12162.36,0) | W21: =IF(W11>0,12162.36,0) | X21: =IF(X11>0,12162.36,0) | Y21: =IF(Y11>0,12162.36,0) | Z21: =IF(Z11>0,12162.36,0) | AA21: =IF(AA11>0,12162.36,0) | AB21: =IF(AB11>0,12162.36,0) | ... AY21: =IF(AY11>0,12162.36,0)
B22: MindBody Loan - MR | P22: 0 | Q22: 0 | R22: 0 | S22: 0 | T22: 0 | U22: =IF(U12>0,13157.16,0) | V22: =IF(V12>0,13157.16,0) | W22: =IF(W12>0,13157.16,0) | X22: =IF(X12>0,13157.16,0) | Y22: =IF(Y12>0,13157.16,0) | Z22: =IF(Z12>0,13157.16,0) | AA22: =IF(AA12>0,13157.16,0) | AB22: =IF(AB12>0,13157.16,0) | ... AY22: =IF(AY12>0,13157.16,0)
B23: Samson Loan | P23: 0 | Q23: 0 | R23: 0 | S23: 0 | T23: 94517.1 | U23: =IF(U13>0,25460.22,0) | V23: =IF(V13>0,25460.22,0) | W23: =IF(W13>0,25460.22,0) | X23: =IF(X13>0,25460.22,0) | Y23: =IF(Y13>0,25460.22,0) | Z23: =IF(Z13>0,25460.22,0) | AA23: =IF(AA13>0,25460.22,0) | AB23: =IF(AB13>0,25460.22,0) | ... AY23: =IF(AY13>0,25460.22,0)
B24: Specialty Capital Loan | P24: 0 | Q24: 0 | R24: 0 | S24: 0 | T24: 90052.62 | U24: =IF(U14>0,25888.16,0) | V24: =IF(V14>0,25888.16,0) | W24: =IF(W14>0,25888.16,0) | X24: =IF(X14>0,25888.16,0) | Y24: =IF(Y14>0,25888.16,0) | Z24: =IF(Z14>0,25888.16,0) | AA24: =IF(AA14>0,25888.16,0) | AB24: =IF(AB14>0,25888.16,0) | ... AY24: =IF(AY14>0,25888.16,0)
B25: Norbrook Inc Loan | P25: 0 | Q25: 0 | R25: 0 | S25: 0 | T25: 0 | U25: =U15*0.08/12 | V25: =V15*0.08/12 | W25: =W15*0.08/12 | X25: =X15*0.08/12 | Y25: =Y15*0.08/12 | Z25: =Z15*0.08/12 | AA25: =AA15*0.08/12 | AB25: =AB15*0.08/12 | ... AY25: =AY15*0.08/12
B26: TOTAL DEBT SERVICE | P26: =SUM(P19:P25) | Q26: =SUM(Q19:Q25) | R26: =SUM(R19:R25) | S26: =SUM(S19:S25) | T26: =SUM(T19:T25) | U26: =SUM(U19:U25) | V26: =SUM(V19:V25) | W26: =SUM(W19:W25) | ... AY26: =SUM(AY19:AY25)
B28: OWNER EQUITY / INTERCOMPANY
B29: Intercompany Net Position | P29: 224773.04 | Q29: 224773.04 | R29: 358106.37 | S29: 436439.7 | T29: 0 | U29: 0 | V29: 0 | W29: 0 | X29: 0 | Y29: 0 | Z29: 0 | AA29: 0 | AB29: 0 | AC29: 0 | AD29: 0 | AE29: 0 | AF29: 0 | AG29: 0 | AH29: 0 | AI29: 0 | AJ29: 0 | AK29: 0 | AL29: 0 | AM29: 0 | AN29: 0 | AO29: 0 | AP29: 0 | AQ29: 0 | AR29: 0 | AS29: 0 | AT29: 0 | AU29: 0 | AV29: 0 | AW29: 0 | AX29: 0 | AY29: 0

Sheet Cash Flow Forecast
B2: Cash Flow Forecast
B3: Actuals: Jan-Apr 2026 (light green). Forecast: May 2026 onwards. Net Change formulas sum operations + investing + financing.
B4: Monthly Cash Flow
B5: Line Item | C5: Annual Total | D5: Jan 2025 | E5: Feb 2025 | F5: Mar 2025 | G5: Apr 2025 | H5: May 2025 | I5: Jun 2025 | J5: Jul 2025 | K5: Aug 2025 | L5: Sep 2025 | M5: Oct 2025 | N5: Nov 2025 | O5: Dec 2025 | P5: Jan 2026 | Q5: Feb 2026 | R5: Mar 2026 | S5: Apr 2026 | T5: May 2026 | U5: Jun 2026 | V5: Jul 2026 | W5: Aug 2026 | X5: Sep 2026 | Y5: Oct 2026 | Z5: Nov 2026 | AA5: Dec 2026 | AB5: Jan 2027 | AC5: Feb 2027 | AD5: Mar 2027 | AE5: Apr 2027 | AF5: May 2027 | AG5: Jun 2027 | AH5: Jul 2027 | AI5: Aug 2027 | AJ5: Sep 2027 | AK5: Oct 2027 | AL5: Nov 2027 | AM5: Dec 2027 | AN5: Jan 2028 | AO5: Feb 2028 | AP5: Mar 2028 | AQ5: Apr 2028 | AR5: May 2028 | AS5: Jun 2028 | AT5: Jul 2028 | AU5: Aug 2028 | AV5: Sep 2028 | AW5: Oct 2028 | AX5: Nov 2028 | AY5: Dec 2028 | BA5: 2025 | BB5: =BA5+1 | BC5: =BB5+1 | BD5: =BC5+1 | BF5: LTM May 2026
B6: CASH INFLOWS
B7: Total Cash Sales | P7: ='Sales Forecast'!P18 | Q7: ='Sales Forecast'!Q18 | R7: ='Sales Forecast'!R18 | S7: ='Sales Forecast'!S18 | T7: ='Sales Forecast'!T18 | U7: ='Sales Forecast'!U18 | V7: ='Sales Forecast'!V18 | W7: ='Sales Forecast'!W18 | ... AY7: ='Sales Forecast'!AY18
B9: OPERATING OUTFLOWS
B10: Property Costs | P10: ='P&L'!P19 | Q10: ='P&L'!Q19 | R10: ='P&L'!R19 | S10: ='P&L'!S19 | T10: ='P&L'!T19 | U10: ='P&L'!U19 | V10: ='P&L'!V19 | W10: ='P&L'!W19 | ... AM10: ='P&L'!AM19 | AN10: 156071.4 | AO10: 156071.4 | AP10: 156071.4 | AQ10: 156071.4 | AR10: 156071.4 | AS10: 156071.4 | AT10: 156071.4 | AU10: 156071.4 | AV10: 156071.4 | AW10: 156071.4 | AX10: 156071.4 | AY10: 156071.4
B11: Staff Costs | P11: ='P&L'!P15 | Q11: ='P&L'!Q15 | R11: ='P&L'!R15 | S11: ='P&L'!S15 | T11: ='P&L'!T15 | U11: ='P&L'!U15 | V11: ='P&L'!V15 | W11: ='P&L'!W15 | ... AM11: ='P&L'!AM15 | AN11: 647462.64 | AO11: 647462.64 | AP11: 647462.64 | AQ11: 647462.64 | AR11: 647462.64 | AS11: 647462.64 | AT11: 647462.64 | AU11: 647462.64 | AV11: 647462.64 | AW11: 647462.64 | AX11: 647462.64 | AY11: 647462.64
B12: Utilities | P12: ='P&L'!P18 | Q12: ='P&L'!Q18 | R12: ='P&L'!R18 | S12: ='P&L'!S18 | T12: ='P&L'!T18 | U12: ='P&L'!U18 | V12: ='P&L'!V18 | W12: ='P&L'!W18 | ... AM12: ='P&L'!AM18 | AN12: 9380.48 | AO12: 9380.48 | AP12: 8753.05 | AQ12: 8753.05 | AR12: 8753.05 | AS12: 8753.05 | AT12: 8753.05 | AU12: 8753.05 | AV12: 8753.05 | AW12: 8753.05 | AX12: 8753.05 | AY12: 8753.05
B13: Marketing & Promotion | P13: ='P&L'!P14 | Q13: ='P&L'!Q14 | R13: ='P&L'!R14 | S13: ='P&L'!S14 | T13: ='P&L'!T14 | U13: ='P&L'!U14 | V13: ='P&L'!V14 | W13: ='P&L'!W14 | ... AM13: ='P&L'!AM14 | AN13: 18331.93 | AO13: 18331.93 | AP13: 18331.93 | AQ13: 18331.93 | AR13: 18331.93 | AS13: 18331.93 | AT13: 18331.93 | AU13: 18331.93 | AV13: 18331.93 | AW13: 18331.93 | AX13: 18331.93 | AY13: 18331.93
B14: Administrative & G&A | P14: ='P&L'!P16 | Q14: ='P&L'!Q16 | R14: ='P&L'!R16 | S14: ='P&L'!S16 | T14: ='P&L'!T16 | U14: ='P&L'!U16 | V14: ='P&L'!V16 | W14: ='P&L'!W16 | ... AM14: ='P&L'!AM16 | AN14: 40486.01 | AO14: 40486.01 | AP14: 40486.01 | AQ14: 40486.01 | AR14: 40486.01 | AS14: 40486.01 | AT14: 40486.01 | AU14: 40486.01 | AV14: 40486.01 | AW14: 40486.01 | AX14: 40486.01 | AY14: 40486.01
B15: Professional Fees | P15: ='P&L'!P17 | Q15: ='P&L'!Q17 | R15: ='P&L'!R17 | S15: ='P&L'!S17 | T15: ='P&L'!T17 | U15: ='P&L'!U17 | V15: ='P&L'!V17 | W15: ='P&L'!W17 | ... AM15: ='P&L'!AM17 | AN15: 26003.5 | AO15: 26003.5 | AP15: 26003.5 | AQ15: 26003.5 | AR15: 26003.5 | AS15: 26003.5 | AT15: 26003.5 | AU15: 26003.5 | AV15: 26003.5 | AW15: 26003.5 | AX15: 26003.5 | AY15: 26003.5
B16: Travel & Meals | P16: ='BK P&L'!P50+'CC P&L'!P50+'DN P&L'!P50+'LF P&L'!P50+'MR P&L'!P50+'OP P&L'!P50+'PH P&L'!P50+'RH P&L'!P50+'SB P&L'!P50+'SM P&L'!P50+'WP P&L'!P50+'WW P&L'!P50+'HO P&L'!P30 | Q16: ='BK P&L'!Q50+'CC P&L'!Q50+'DN P&L'!Q50+'LF P&L'!Q50+'MR P&L'!Q50+'OP P&L'!Q50+'PH P&L'!Q50+'RH P&L'!Q50+'SB P&L'!Q50+'SM P&L'!Q50+'WP P&L'!Q50+'WW P&L'!Q50+'HO P&L'!Q30 | R16: ='BK P&L'!R50+'CC P&L'!R50+'DN P&L'!R50+'LF P&L'!R50+'MR P&L'!R50+'OP P&L'!R50+'PH P&L'!R50+'RH P&L'!R50+'SB P&L'!R50+'SM P&L'!R50+'WP P&L'!R50+'WW P&L'!R50+'HO P&L'!R30 | S16: ='BK P&L'!S50+'CC P&L'!S50+'DN P&L'!S50+'LF P&L'!S50+'MR P&L'!S50+'OP P&L'!S50+'PH P&L'!S50+'RH P&L'!S50+'SB P&L'!S50+'SM P&L'!S50+'WP P&L'!S50+'WW P&L'!S50+'HO P&L'!S30 | T16: ='BK P&L'!T50+'CC P&L'!T50+'DN P&L'!T50+'LF P&L'!T50+'MR P&L'!T50+'OP P&L'!T50+'PH P&L'!T50+'RH P&L'!T50+'SB P&L'!T50+'SM P&L'!T50+'WP P&L'!T50+'WW P&L'!T50+'HO P&L'!T30 | U16: ='BK P&L'!U50+'CC P&L'!U50+'DN P&L'!U50+'LF P&L'!U50+'MR P&L'!U50+'OP P&L'!U50+'PH P&L'!U50+'RH P&L'!U50+'SB P&L'!U50+'SM P&L'!U50+'WP P&L'!U50+'WW P&L'!U50+'HO P&L'!U30 | V16: ='BK P&L'!V50+'CC P&L'!V50+'DN P&L'!V50+'LF P&L'!V50+'MR P&L'!V50+'OP P&L'!V50+'PH P&L'!V50+'RH P&L'!V50+'SB P&L'!V50+'SM P&L'!V50+'WP P&L'!V50+'WW P&L'!V50+'HO P&L'!V30 | W16: ='BK P&L'!W50+'CC P&L'!W50+'DN P&L'!W50+'LF P&L'!W50+'MR P&L'!W50+'OP P&L'!W50+'PH P&L'!W50+'RH P&L'!W50+'SB P&L'!W50+'SM P&L'!W50+'WP P&L'!W50+'WW P&L'!W50+'HO P&L'!W30 | ... AM16: ='BK P&L'!AM50+'CC P&L'!AM50+'DN P&L'!AM50+'LF P&L'!AM50+'MR P&L'!AM50+'OP P&L'!AM50+'PH P&L'!AM50+'RH P&L'!AM50+'SB P&L'!AM50+'SM P&L'!AM50+'WP P&L'!AM50+'WW P&L'!AM50+'HO P&L'!AM30 | AN16: 4447.31 | AO16: 4447.31 | AP16: 4447.31 | AQ16: 4447.31 | AR16: 4447.31 | AS16: 4447.31 | AT16: 4447.31 | AU16: 4447.31 | AV16: 4447.31 | AW16: 4447.31 | AX16: 4447.31 | AY16: 4447.31
B17: Merchant Fees & COGS | P17: ='P&L'!P12 | Q17: ='P&L'!Q12 | R17: ='P&L'!R12 | S17: ='P&L'!S12 | T17: ='P&L'!T12 | U17: ='P&L'!U12 | V17: ='P&L'!V12 | W17: ='P&L'!W12 | ... AM17: ='P&L'!AM12 | AN17: =AN7*(Assumptions!$C$19+Assumptions!$C$20) | AO17: =AO7*(Assumptions!$C$19+Assumptions!$C$20) | AP17: =AP7*(Assumptions!$C$19+Assumptions!$C$20) | AQ17: =AQ7*(Assumptions!$C$19+Assumptions!$C$20) | AR17: =AR7*(Assumptions!$C$19+Assumptions!$C$20) | AS17: =AS7*(Assumptions!$C$19+Assumptions!$C$20) | AT17: =AT7*(Assumptions!$C$19+Assumptions!$C$20) | AU17: =AU7*(Assumptions!$C$19+Assumptions!$C$20) | ... AY17: =AY7*(Assumptions!$C$19+Assumptions!$C$20)
B18: Studio Start Up Costs | P18: 0 | Q18: 0 | R18: 0 | S18: 0 | T18: 0 | U18: 0 | V18: 0 | W18: 0 | X18: 0 | Y18: 0 | Z18: 0 | AA18: 0 | AB18: 0 | AC18: 0 | AD18: 0 | AE18: 0 | AF18: 0 | AG18: 0 | AH18: 0 | AI18: 0 | AJ18: 0 | AK18: 0 | AL18: 0 | AM18: 0 | AN18: 0 | AO18: 0 | AP18: 0 | AQ18: 0 | AR18: 0 | AS18: 0 | AT18: 0 | AU18: 0 | AV18: 0 | AW18: 0 | AX18: 0 | AY18: 0
B19: Taxes | P19: ='P&L'!P25+'P&L'!P26 | Q19: ='P&L'!Q25+'P&L'!Q26 | R19: ='P&L'!R25+'P&L'!R26 | S19: ='P&L'!S25+'P&L'!S26 | T19: ='P&L'!T25+'P&L'!T26 | U19: ='P&L'!U25+'P&L'!U26 | V19: ='P&L'!V25+'P&L'!V26 | W19: ='P&L'!W25+'P&L'!W26 | ... AM19: ='P&L'!AM25+'P&L'!AM26 | AN19: 5826.93 | AO19: 5826.93 | AP19: 5826.93 | AQ19: 5826.93 | AR19: 5826.93 | AS19: 5826.93 | AT19: 5826.93 | AU19: 5826.93 | AV19: 5826.93 | AW19: 5826.93 | AX19: 5826.93 | AY19: 5826.93
B20: PF Interest Expense | X20: =X49 | Y20: =Y49 | Z20: =Z49 | AA20: =AA49 | AB20: =AB49 | AC20: =AC49 | AD20: =AD49 | AE20: =AE49 | ... AY20: =AY49
B21: PF Fees (Debt Fees and Legal) | X21: ='Sources and Uses'!C15+'Sources and Uses'!C16
B22: Total Operating Expenses | P22: =SUM(P10:P21) | Q22: =SUM(Q10:Q21) | R22: =SUM(R10:R21) | S22: =SUM(S10:S21) | T22: =SUM(T10:T21) | U22: =SUM(U10:U21) | V22: =SUM(V10:V21) | W22: =SUM(W10:W21) | ... AY22: =SUM(AY10:AY21)
B23: Net Cash from Operations | P23: =P7-P22 | Q23: =Q7-Q22 | R23: =R7-R22 | S23: =S7-S22 | T23: =T7-T22 | U23: =U7-U22 | V23: =V7-V22 | W23: =W7-W22 | ... AY23: =AY7-AY22
B25: INVESTING ACTIVITIES
B26: Equipment & Furniture | P26: 0 | Q26: 2497.4 | R26: 0 | S26: 0 | T26: 0 | U26: 0 | V26: 0 | W26: 0 | X26: 0 | Y26: 0 | Z26: 0 | AA26: 0 | AB26: 0 | AC26: 0 | AD26: 0 | AE26: 0 | AF26: 0 | AG26: 0 | AH26: 0 | AI26: 0 | AJ26: 0 | AK26: 0 | AL26: 0 | AM26: 0 | AN26: 0 | AO26: 0 | AP26: 0 | AQ26: 0 | AR26: 0 | AS26: 0 | AT26: 0 | AU26: 0 | AV26: 0 | AW26: 0 | AX26: 0 | AY26: 0
B27: Leasehold Improvements | P27: -17810.67 | Q27: -7094.5 | R27: -24075 | S27: -1035.5 | T27: 0 | U27: 0 | V27: -275000 | W27: -160000 | X27: 0 | Y27: 0 | Z27: 0 | AA27: 0 | AB27: 0 | AC27: 0 | AD27: 0 | AE27: 0 | AF27: 0 | AG27: 0 | AH27: 0 | AI27: 0 | AJ27: 0 | AK27: 0 | AL27: 0 | AM27: 0 | AN27: 0 | AO27: 0 | AP27: 0 | AQ27: 0 | AR27: 0 | AS27: 0 | AT27: 0 | AU27: 0 | AV27: 0 | AW27: 0 | AX27: 0 | AY27: 0
B28: Deposits | P28: 0 | Q28: 0 | R28: 0 | S28: 0 | T28: 0 | U28: 0 | V28: 0 | W28: 0 | X28: 0 | Y28: 0 | Z28: 0 | AA28: 0 | AB28: 0 | AC28: 0 | AD28: 0 | AE28: 0 | AF28: 0 | AG28: 0 | AH28: 0 | AI28: 0 | AJ28: 0 | AK28: 0 | AL28: 0 | AM28: 0 | AN28: 0 | AO28: 0 | AP28: 0 | AQ28: 0 | AR28: 0 | AS28: 0 | AT28: 0 | AU28: 0 | AV28: 0 | AW28: 0 | AX28: 0 | AY28: 0
B29: Net Investing | P29: =SUM(P26:P28) | Q29: =SUM(Q26:Q28) | R29: =SUM(R26:R28) | S29: =SUM(S26:S28) | T29: =SUM(T26:T28) | U29: =SUM(U26:U28) | V29: =SUM(V26:V28) | W29: =SUM(W26:W28) | ... AY29: =SUM(AY26:AY28)
B31: FINANCING ACTIVITIES
B32: Loan Proceeds | P32: 9059.38 | Q32: 9059.38 | R32: 9059.38 | S32: 12507.09 | T32: 0 | U32: 0 | V32: 0 | W32: 0 | X32: =X45 | Y32: 0 | Z32: 0 | AB32: 0 | AC32: 0 | AD32: 0 | AE32: 0 | AF32: 0 | AG32: 0 | AH32: 0 | AI32: 0 | AJ32: 0 | AK32: 0 | AL32: 0 | AM32: 0 | AN32: 0 | AO32: 0 | AP32: 0 | AQ32: 0 | AR32: 0 | AS32: 0 | AT32: 0 | AU32: 0 | AV32: 0 | AW32: 0 | AX32: 0 | AY32: 0
B33: Loan Repayments | P33: -132128.24 | Q33: -122128.76 | R33: -132834.5 | S33: -114793.66 | T33: =-'Cash, Debt & Equity'!T26 | U33: =-'Cash, Debt & Equity'!U26 | V33: =-'Cash, Debt & Equity'!V26 | W33: =-'Cash, Debt & Equity'!W26 | X33: =-'Cash, Debt & Equity'!X26 | Y33: =-'Cash, Debt & Equity'!Y26 | Z33: =-'Cash, Debt & Equity'!Z26 | AA33: =-'Cash, Debt & Equity'!AA26 | ... AY33: =-'Cash, Debt & Equity'!AY26
B34: Intercompany / Owner Contributions | P34: 0 | Q34: 0 | R34: 133333.33 | S34: 78333.33 | T34: 0 | U34: 0 | V34: 0 | W34: 0 | X34: 0 | Y34: 0 | Z34: -100000 | AA34: 0 | AB34: 0 | AC34: 0 | AD34: 0 | AE34: 0 | AF34: 0 | AG34: 0 | AH34: 0 | AI34: 0 | AJ34: 0 | AK34: 0 | AL34: 0 | AM34: 0 | AN34: 0 | AO34: 0 | AP34: 0 | AQ34: 0 | AR34: 0 | AS34: 0 | AT34: 0 | AU34: 0 | AV34: 0 | AW34: 0 | AX34: 0 | AY34: 0
B35: Net Financing | P35: =SUM(P32:P34) | Q35: =SUM(Q32:Q34) | R35: =SUM(R32:R34) | S35: =SUM(S32:S34) | T35: =SUM(T32:T34) | U35: =SUM(U32:U34) | V35: =SUM(V32:V34) | W35: =SUM(W32:W34) | ... AY35: =SUM(AY32:AY34)
B37: NET CHANGE IN CASH
B38: Net Change in Cash | P38: =P23+P29+P35 | Q38: =Q23+Q29+Q35 | R38: =R23+R29+R35 | S38: =S23+S29+S35 | T38: =T23+T29+T35 | U38: =U23+U29+U35 | V38: =V23+V29+V35 | W38: =W23+W29+W35 | ... AY38: =AY23+AY29+AY35
B39: Beginning Cash Balance | P39: =P40-P38 | Q39: =P40 | R39: =Q40 | S39: =R40 | T39: =S40 | U39: =T40 | V39: =U40 | W39: =V40 | X39: =W40 | ... AY39: =AX40
B40: Ending Cash Balance | P40: 187021.69 | Q40: 261314.24 | R40: 237762.6 | S40: 473976.03 | T40: =T39+T38 | U40: =U39+U38 | V40: =V39+V38 | W40: =W39+W38 | X40: =X39+X38 | Y40: =Y39+Y38 | Z40: =Z39+Z38 | AA40: =AA39+AA38 | ... AY40: =AY39+AY38
B42: PF Debt At Close
B44: New Debt, Beg of Period | X44: 0 | Y44: =X47 | Z44: =Y47 | AA44: =Z47 | AB44: =AA47 | AC44: =AB47 | AD44: =AC47 | AE44: =AD47 | AF44: =AE47 | ... AY44: =AX47
B45: Increase (+) | X45: ='Sources and Uses'!C20
B46: Paydown (-) | X46: 0 | Y46: 0 | Z46: 0 | AA46: 0 | AB46: 0 | AC46: 0 | AD46: 0 | AE46: 0 | AF46: 0 | AG46: 0 | AH46: 0 | AI46: 0 | AJ46: 0 | AK46: 0 | AL46: 0 | AM46: 0 | AN46: 0 | AO46: 0 | AP46: 0 | AQ46: 0 | AR46: 0 | AS46: 0 | AT46: 0 | AU46: 0 | AV46: 0 | AW46: 0 | AX46: 0 | AY46: 0
B47: New Debt, End of Period | X47: =SUM(X44:X46) | Y47: =SUM(Y44:Y46) | Z47: =SUM(Z44:Z46) | AA47: =SUM(AA44:AA46) | AB47: =SUM(AB44:AB46) | AC47: =SUM(AC44:AC46) | AD47: =SUM(AD44:AD46) | AE47: =SUM(AE44:AE46) | ... AY47: =SUM(AY44:AY46) | BB47: =AA47 | BC47: =AM47 | BD47: =AY47 | BF47: =BB47
...

Sheet P&L
B2: Profit & Loss (Consolidated)
B3: Actuals Jan-Apr 2026. Forecast May 2026+ uses formulas from Sales Forecast and Assumptions.
B4: Monthly P&L
B5: Line Item | D5: Jan 2025 | E5: Feb 2025 | F5: Mar 2025 | G5: Apr 2025 | H5: May 2025 | I5: Jun 2025 | J5: Jul 2025 | K5: Aug 2025 | L5: Sep 2025 | M5: Oct 2025 | N5: Nov 2025 | O5: Dec 2025 | P5: Jan 2026 | Q5: Feb 2026 | R5: Mar 2026 | S5: Apr 2026 | T5: May 2026 | U5: Jun 2026 | V5: Jul 2026 | W5: Aug 2026 | X5: Sep 2026 | Y5: Oct 2026 | Z5: Nov 2026 | AA5: Dec 2026 | AB5: Jan 2027 | AC5: Feb 2027 | AD5: Mar 2027 | AE5: Apr 2027 | AF5: May 2027 | AG5: Jun 2027 | AH5: Jul 2027 | AI5: Aug 2027 | AJ5: Sep 2027 | AK5: Oct 2027 | AL5: Nov 2027 | AM5: Dec 2027 | AN5: Jan 2028 | AO5: Feb 2028 | AP5: Mar 2028 | AQ5: Apr 2028 | AR5: May 2028 | AS5: Jun 2028 | AT5: Jul 2028 | AU5: Aug 2028 | AV5: Sep 2028 | AW5: Oct 2028 | AX5: Nov 2028 | AY5: Dec 2028
B6: Session Revenue | D6: 624194.18 | E6: 640401.13 | F6: 771305.41 | G6: 721737.32 | H6: 765537.02 | I6: 745441.08 | J6: 736428.09 | K6: 724732.03 | L6: 722621.96 | M6: 738386.52 | N6: 707731.79 | O6: 691997.32 | P6: 1000204 | Q6: 866507.65 | R6: 867748.4 | S6: 790938.82 | T6: 807497.91 | U6: ='Sales Forecast'!U18*Assumptions!$C$12+'Sales Forecast'!T18*Assumptions!$D$12+'Sales Forecast'!S18*Assumptions!$E$12+'Sales Forecast'!R18*Assumptions!$F$12+'Sales Forecast'!Q18*Assumptions!$G$12+'Sales Forecast'!P18*Assumptions!$H$12+'Sales Forecast'!U101*Assumptions!$I$12 | V6: ='Sales Forecast'!V18*Assumptions!$C$12+'Sales Forecast'!U18*Assumptions!$D$12+'Sales Forecast'!T18*Assumptions!$E$12+'Sales Forecast'!S18*Assumptions!$F$12+'Sales Forecast'!R18*Assumptions!$G$12+'Sales Forecast'!Q18*Assumptions!$H$12+'Sales Forecast'!P18*Assumptions!$I$12 | W6: ='Sales Forecast'!W18*Assumptions!$C$12+'Sales Forecast'!V18*Assumptions!$D$12+'Sales Forecast'!U18*Assumptions!$E$12+'Sales Forecast'!T18*Assumptions!$F$12+'Sales Forecast'!S18*Assumptions!$G$12+'Sales Forecast'!R18*Assumptions!$H$12+'Sales Forecast'!Q18*Assumptions!$I$12 | X6: ='Sales Forecast'!X18*Assumptions!$C$12+'Sales Forecast'!W18*Assumptions!$D$12+'Sales Forecast'!V18*Assumptions!$E$12+'Sales Forecast'!U18*Assumptions!$F$12+'Sales Forecast'!T18*Assumptions!$G$12+'Sales Forecast'!S18*Assumptions!$H$12+'Sales Forecast'!R18*Assumptions!$I$12 | Y6: ='Sales Forecast'!Y18*Assumptions!$C$12+'Sales Forecast'!X18*Assumptions!$D$12+'Sales Forecast'!W18*Assumptions!$E$12+'Sales Forecast'!V18*Assumptions!$F$12+'Sales Forecast'!U18*Assumptions!$G$12+'Sales Forecast'!T18*Assumptions!$H$12+'Sales Forecast'!S18*Assumptions!$I$12 | Z6: ='Sales Forecast'!Z18*Assumptions!$C$12+'Sales Forecast'!Y18*Assumptions!$D$12+'Sales Forecast'!X18*Assumptions!$E$12+'Sales Forecast'!W18*Assumptions!$F$12+'Sales Forecast'!V18*Assumptions!$G$12+'Sales Forecast'!U18*Assumptions!$H$12+'Sales Forecast'!T18*Assumptions!$I$12 | AA6: ='Sales Forecast'!AA18*Assumptions!$C$12+'Sales Forecast'!Z18*Assumptions!$D$12+'Sales Forecast'!Y18*Assumptions!$E$12+'Sales Forecast'!X18*Assumptions!$F$12+'Sales Forecast'!W18*Assumptions!$G$12+'Sales Forecast'!V18*Assumptions!$H$12+'Sales Forecast'!U18*Assumptions!$I$12 | AB6: ='Sales Forecast'!AB18*Assumptions!$C$12+'Sales Forecast'!AA18*Assumptions!$D$12+'Sales Forecast'!Z18*Assumptions!$E$12+'Sales Forecast'!Y18*Assumptions!$F$12+'Sales Forecast'!X18*Assumptions!$G$12+'Sales Forecast'!W18*Assumptions!$H$12+'Sales Forecast'!V18*Assumptions!$I$12 | AC6: ='Sales Forecast'!AC18*Assumptions!$C$12+'Sales Forecast'!AB18*Assumptions!$D$12+'Sales Forecast'!AA18*Assumptions!$E$12+'Sales Forecast'!Z18*Assumptions!$F$12+'Sales Forecast'!Y18*Assumptions!$G$12+'Sales Forecast'!X18*Assumptions!$H$12+'Sales Forecast'!W18*Assumptions!$I$12 | ... AY6: ='Sales Forecast'!AY18*Assumptions!$C$12+'Sales Forecast'!AX18*Assumptions!$D$12+'Sales Forecast'!AW18*Assumptions!$E$12+'Sales Forecast'!AV18*Assumptions!$F$12+'Sales Forecast'!AU18*Assumptions!$G$12+'Sales Forecast'!AT18*Assumptions!$H$12+'Sales Forecast'!AS18*Assumptions!$I$12
